<?xml version="1.0"?>
<!-- This URDF was automatically created by SolidWorks to URDF Exporter! Originally created by Stephen Brawner (brawner@gmail.com) 
     Commit Version: 1.6.0-1-g15f4949  Build Version: 1.6.7594.29634
     For more information, please see http://wiki.ros.org/sw_urdf_exporter -->
<robot name="arm" xmlns:xacro="http://www.ros.org/wiki/xacro">
 <xacro:macro name="rm_arm">
  <link
    name="arm_base_link">
    <inertial>
      <origin
        xyz="-0.080503 0.0035113 0.016265"
        rpy="0 0 0" />
      <mass
        value="0.5853" />
      <inertia
        ixx="0.00038102"
        ixy="6.0454E-06"
        ixz="-3.1755E-08"
        iyy="0.00051883"
        iyz="5.5652E-09"
        izz="0.0008751" />
    </inertial>
    <visual>
      <origin
        xyz="0 0 0"
        rpy="0 0 0" />
      <geometry>
        <mesh
          filename="package://sp_description/meshes/base_link.STL" />
      </geometry>
      <material
        name="">
        <color
          rgba="0.33333 0.33333 0.33333 1" />
      </material>
    </visual>
    <collision>
      <origin
        xyz="0 0 0"
        rpy="0 0 0" />
      <geometry>
        <mesh
          filename="package://sp_description/meshes/base_link.STL" />
      </geometry>
    </collision>
  </link>
  <link
    name="Link_1">
    <inertial>
      <origin
        xyz="2.7281E-05 0.0022326 0.092049"
        rpy="0 0 0" />
      <mass
        value="1.5075" />
      <inertia
        ixx="0.0010176"
        ixy="8.2456E-09"
        ixz="-3.7005E-07"
        iyy="0.0018978"
        iyz="7.4212E-08"
        izz="0.0012474" />
    </inertial>
    <visual>
      <origin
        xyz="0 0 0"
        rpy="0 0 0" />
      <geometry>
        <mesh
          filename="package://sp_description/meshes/Link_1.STL" />
      </geometry>
      <material
        name="">
        <color
          rgba="0.79216 0.81961 0.93333 1" />
      </material>
    </visual>
    <collision>
      <origin
        xyz="0 0 0"
        rpy="0 0 0" />
      <geometry>
        <mesh
          filename="package://sp_description/meshes/Link_1.STL" />
      </geometry>
    </collision>
  </link>
  <joint
    name="Joint_1"
    type="revolute">
    <origin
      xyz="-0.12088 0.0052779 0.0145"
      rpy="0 0 0.47036" />
    <parent
      link="arm_base_link" />
    <child
      link="Link_1" />
    <axis
      xyz="0 0 1" />
    <limit
      lower="-3.14"
      upper="3.14"
      effort="80"
      velocity="25" />
  </joint>
  <link
    name="Link_2">
    <inertial>
      <origin
        xyz="0.000292500655580858 0.180365674657187 0.0562795140433986"
        rpy="0 0 0" />
      <mass
        value="0.728670490361224" />
      <inertia
        ixx="0.000804471529449478"
        ixy="1.99485127410755E-05"
        ixz="-3.73633199110893E-08"
        iyy="0.000266076398816204"
        iyz="-8.03511541284116E-08"
        izz="0.000993614124728688" />
    </inertial>
    <visual>
      <origin
        xyz="0 0 0"
        rpy="0 0 0" />
      <geometry>
        <mesh
          filename="package://sp_description/meshes/Link_2.STL" />
      </geometry>
      <material
        name="">
        <color
          rgba="0.792156862745098 0.819607843137255 0.933333333333333 1" />
      </material>
    </visual>
    <collision>
      <origin
        xyz="0 0 0"
        rpy="0 0 0" />
      <geometry>
        <mesh
          filename="package://sp_description/meshes/Link_2.STL" />
      </geometry>
    </collision>
  </link>
  <joint
    name="Joint_2"
    type="revolute">
    <origin
      xyz="0 0.078 0.0963"
      rpy="1.5708 -0.82195 0" />
    <parent
      link="Link_1" />
    <child
      link="Link_2" />
    <axis
      xyz="0 0 1" />
    <limit
      lower="-3.14"
      upper="3.14"
      effort="80"
      velocity="25" />
  </joint>
  <link
    name="Link_3">
    <inertial>
      <origin
        xyz="-0.053132 -4.1282E-11 -0.017583"
        rpy="0 0 0" />
      <mass
        value="0.15481" />
      <inertia
        ixx="3.3921E-05"
        ixy="-2.091E-13"
        ixz="-1.5035E-18"
        iyy="0.00060814"
        iyz="2.7105E-20"
        izz="0.00064142" />
    </inertial>
    <visual>
      <origin
        xyz="0 0 0"
        rpy="0 0 0" />
      <geometry>
        <mesh
          filename="package://sp_description/meshes/Link_3.STL" />
      </geometry>
      <material
        name="">
        <color
          rgba="0.79216 0.81961 0.93333 1" />
      </material>
    </visual>
    <collision>
      <origin
        xyz="0 0 0"
        rpy="0 0 0" />
      <geometry>
        <mesh
          filename="package://sp_description/meshes/Link_3.STL" />
      </geometry>
    </collision>
  </link>
  <joint
    name="Joint_3"
    type="revolute">
    <origin
      xyz="0 0.2 0"
      rpy="0 0 -0.2083" />
    <parent
      link="Link_2" />
    <child
      link="Link_3" />
    <axis
      xyz="0 0 1" />
    <limit
      lower="-3.14"
      upper="3.14"
      effort="80"
      velocity="25" />
  </joint>
  <link
    name="Link_4">
    <inertial>
      <origin
        xyz="0.054727 9.2973E-05 -0.015197"
        rpy="0 0 0" />
      <mass
        value="0.64557" />
      <inertia
        ixx="0.00021111"
        ixy="-2.1598E-06"
        ixz="-9.7806E-09"
        iyy="0.00030955"
        iyz="-4.208E-08"
        izz="0.0004044" />
    </inertial>
    <visual>
      <origin
        xyz="0 0 0"
        rpy="0 0 0" />
      <geometry>
        <mesh
          filename="package://sp_description/meshes/Link_4.STL" />
      </geometry>
      <material
        name="">
        <color
          rgba="0.89804 0.91765 0.92941 1" />
      </material>
    </visual>
    <collision>
      <origin
        xyz="0 0 0"
        rpy="0 0 0" />
      <geometry>
        <mesh
          filename="package://sp_description/meshes/Link_4.STL" />
      </geometry>
    </collision>
  </link>
  <joint
    name="Joint_4"
    type="revolute">
    <origin
      xyz="-0.1575 0 0"
      rpy="3.1416 0 2.5279" />
    <parent
      link="Link_3" />
    <child
      link="Link_4" />
    <axis
      xyz="0 0 1" />
    <limit
      lower="-3.14"
      upper="3.14"
      effort="80"
      velocity="25" />
  </joint>
  <link
    name="Link_5">
    <inertial>
      <origin
        xyz="-0.0037794 -0.002534 -0.031782"
        rpy="0 0 0" />
      <mass
        value="0.51072" />
      <inertia
        ixx="0.00041878"
        ixy="-0.00018891"
        ixz="-2.6197E-06"
        iyy="0.0006406"
        iyz="4.537E-06"
        izz="0.000494" />
    </inertial>
    <visual>
      <origin
        xyz="0 0 0"
        rpy="0 0 0" />
      <geometry>
        <mesh
          filename="package://sp_description/meshes/Link_5.STL" />
      </geometry>
      <material
        name="">
        <color
          rgba="1 1 1 1" />
      </material>
    </visual>
    <collision>
      <origin
        xyz="0 0 0"
        rpy="0 0 0" />
      <geometry>
        <mesh
          filename="package://sp_description/meshes/Link_5.STL" />
      </geometry>
    </collision>
  </link>
  <joint
    name="Joint_5"
    type="revolute">
    <origin
      xyz="0.12802 -0.0274 -0.0015"
      rpy="1.5708 -0.7854 -2.1735" />
    <parent
      link="Link_4" />
    <child
      link="Link_5" />
    <axis
      xyz="0 0 1" />
    <limit
      lower="-3.14"
      upper="3.14"
      effort="20"
      velocity="25" />
  </joint>

 </xacro:macro>
</robot>
