<?xml version="1.0" ?>
<!-- =================================================================================== -->
<!-- |    This document was autogenerated by xacro from /home/adminpc/catkin_ws/src/sp_description/urdf/engineer/engineer.xacro | -->
<!-- |    EDITING THIS FILE BY HAND IS NOT RECOMMENDED                                 | -->
<!-- =================================================================================== -->
<robot name="engineer">
    <transmission name="trans_joint1">
        <type>transmission_interface/SimpleTransmission</type>
        <actuator name="joint1_motor">
            <mechanicalReduction>1</mechanicalReduction>
            <hardwareInterface>hardware_interface/PositionJointInterface</hardwareInterface>
        </actuator>
        <joint name="joint1">
            <hardwareInterface>hardware_interface/PositionJointInterface</hardwareInterface>
        </joint>
    </transmission>
    <transmission name="trans_joint2">
        <type>transmission_interface/SimpleTransmission</type>
        <actuator name="joint2_motor">
            <mechanicalReduction>1</mechanicalReduction>
            <hardwareInterface>hardware_interface/PositionJointInterface</hardwareInterface>
        </actuator>
        <joint name="joint2">
            <hardwareInterface>hardware_interface/PositionJointInterface</hardwareInterface>
        </joint>
    </transmission>
    <transmission name="trans_joint3">
        <type>transmission_interface/SimpleTransmission</type>
        <actuator name="joint3_motor">
            <mechanicalReduction>1</mechanicalReduction>
            <hardwareInterface>hardware_interface/PositionJointInterface</hardwareInterface>
        </actuator>
        <joint name="joint3">
            <hardwareInterface>hardware_interface/PositionJointInterface</hardwareInterface>
        </joint>
    </transmission>
    <!--base link-->
    <link name="base_link">
        <inertial>
            <origin rpy="0 0 0" xyz="-0.0113738412352606 -0.0179737884364999 0.0629667320671845" />
            <mass value="12.478309558197" />
            <inertia ixx="0.0306729834251133" ixy="2.06989089203648E-05" ixz="-4.24062281514238E-06" iyy="0.0340671825531538" iyz="-3.89196837584769E-05" izz="0.0558921594392679" />
        </inertial>
        <visual>
            <origin rpy="0 0 0" xyz="0 0 0" />
            <geometry>
                <mesh filename="package://sp_description/meshes/engineer_chassis/base_link.STL" />
            </geometry>
            <material name="">
                <color rgba="0.898039215686275 0.917647058823529 0.929411764705882 1" />
            </material>
        </visual>
        <collision>
            <origin rpy="0 0 0" xyz="0 0 0" />
            <geometry>
                <box size="0.6 0.6 0.15" />
            </geometry>
        </collision>
        <collision>
            <origin rpy="0 0 0" xyz="0.2375 0.0 0.11" />
            <geometry>
                <box size="0.125 0.6 0.07" />
            </geometry>
        </collision>
        <collision>
            <origin rpy="0 0 0" xyz="-0.205 0.0 0.11" />
            <geometry>
                <box size="0.19 0.6 0.07" />
            </geometry>
        </collision>
        <collision>
            <origin rpy="0 0 0" xyz="0.0325 0.1965 0.13" />
            <geometry>
                <box size="0.285 0.207 0.11" />
            </geometry>
        </collision>
        <collision>
            <origin rpy="0 0 0" xyz="0.0325 -0.2135 0.13" />
            <geometry>
                <box size="0.285 0.173 0.11" />
            </geometry>
        </collision>
        <collision>
            <origin rpy="0 0 0" xyz="0.0 0.2 0.21" />
            <geometry>
                <box size="0.23 0.12 0.05" />
            </geometry>
        </collision>
        <collision>
            <origin rpy="0 0 0" xyz="0.0 -0.1895 0.235" />
            <geometry>
                <box size="0.32 0.125 0.1" />
            </geometry>
        </collision>
        <collision>
            <origin rpy="0 0 0" xyz="0.0 0.098 0.25" />
            <geometry>
                <box rpy="0 0 0" size="0.19 0.01 0.13" />
            </geometry>
        </collision>
        <collision>
            <origin rpy="0 0 0" xyz="0.0 -0.132 0.3" />
            <geometry>
                <box size="0.19 0.01 0.03" />
            </geometry>
        </collision>
    </link>
    <!--  link  -->
    <link name="left_front_wheel">
        <visual>
            <geometry>
                <mesh filename="package://sp_description/meshes/common/mecanum_wheel/right_threaded_mecanum_wheel.stl" scale="0.001 0.001 0.001" />
            </geometry>
        </visual>
        <inertial>
            <mass value="0.59" />
            <inertia ixx="1.416e-3" ixy="0.0" ixz="0.0" iyy="2.749e-3" iyz="0.0" izz="1.416e-3" />
        </inertial>
    </link>
    <!--  joint  -->
    <joint name="left_front_wheel_joint" type="revolute">
        <axis xyz="0 1 0" />
        <origin rpy="0 0 0" xyz="0.19727 0.223 -0.00111" />
        <!--      limit not work while type="continuous"-->
        <limit effort="10" lower="-1e9" upper="1e9" velocity="70" />
        <dynamics damping="0.0" friction="0.05" />
        <parent link="base_link" />
        <child link="left_front_wheel" />
    </joint>
    <!--  link  -->
    <link name="left_front_roller_0">
        <collision>
            <geometry>
                <sphere radius="0.009" />
            </geometry>
        </collision>
        <inertial>
            <mass value="0.036" />
            <inertia ixx="3128e-9" ixy="0.0" ixz="0.0" iyy="3128e-9" iyz="0.0" izz="3128e-9" />
            <origin xyz="0 0 0" rpy="0 0 0" />
        </inertial>
    </link>
    <joint name="left_front_roller_0_joint" type="continuous">
        <origin rpy="0 0 0" xyz="4.117874862132975e-18 0 -0.06725" />
        <axis xyz="0.7071067811865476 -0.7071067811865476 0.0" />
        <dynamics damping="0.0" friction="0.001" />
        <parent link="left_front_wheel" />
        <child link="left_front_roller_0" />
    </joint>
    <gazebo reference="left_front_roller_0">
        <mu1 value="2000.0" />
        <mu2 value="2000.0" />
        <kp value="1000000.0" />
        <kd value="100.0" />
        <material>Gazebo/Black</material>
        <plugin name="gazebo_ros_control">
            <robotNamespace>/</robotNamespace>
        </plugin>
    </gazebo>
    <!--  link  -->
    <link name="left_front_roller_1">
        <collision>
            <geometry>
                <sphere radius="0.009" />
            </geometry>
        </collision>
        <inertial>
            <mass value="0.036" />
            <inertia ixx="3128e-9" ixy="0.0" ixz="0.0" iyy="3128e-9" iyz="0.0" izz="3128e-9" />
            <origin xyz="0 0 0" rpy="0 0 0" />
        </inertial>
    </link>
    <joint name="left_front_roller_1_joint" type="continuous">
        <origin rpy="0 0 0" xyz="0.025754155985525513 0 -0.06212315147731336" />
        <axis xyz="0.653200024955946 -0.7071067811865476 0.27079462217250855" />
        <dynamics damping="0.0" friction="0.001" />
        <parent link="left_front_wheel" />
        <child link="left_front_roller_1" />
    </joint>
    <gazebo reference="left_front_roller_1">
        <mu1 value="2000.0" />
        <mu2 value="2000.0" />
        <kp value="1000000.0" />
        <kd value="100.0" />
        <material>Gazebo/Black</material>
    </gazebo>
    <!--  link  -->
    <link name="left_front_roller_2">
        <collision>
            <geometry>
                <sphere radius="0.009" />
            </geometry>
        </collision>
        <inertial>
            <mass value="0.036" />
            <inertia ixx="3128e-9" ixy="0.0" ixz="0.0" iyy="3128e-9" iyz="0.0" izz="3128e-9" />
            <origin xyz="0 0 0" rpy="0 0 0" />
        </inertial>
    </link>
    <joint name="left_front_roller_2_joint" type="continuous">
        <origin rpy="0 0 0" xyz="0.04758154151551398 0 -0.04752430333005861" />
        <axis xyz="0.49969899116506866 -0.7071067811865476 0.5003008277312888" />
        <dynamics damping="0.0" friction="0.001" />
        <parent link="left_front_wheel" />
        <child link="left_front_roller_2" />
    </joint>
    <gazebo reference="left_front_roller_2">
        <mu1 value="2000.0" />
        <mu2 value="2000.0" />
        <kp value="1000000.0" />
        <kd value="100.0" />
        <material>Gazebo/Black</material>
    </gazebo>
    <!--  link  -->
    <link name="left_front_roller_3">
        <collision>
            <geometry>
                <sphere radius="0.009" />
            </geometry>
        </collision>
        <inertial>
            <mass value="0.036" />
            <inertia ixx="3128e-9" ixy="0.0" ixz="0.0" iyy="3128e-9" iyz="0.0" izz="3128e-9" />
            <origin xyz="0 0 0" rpy="0 0 0" />
        </inertial>
    </link>
    <joint name="left_front_roller_3_joint" type="continuous">
        <origin rpy="0 0 0" xyz="0.062154106054395655 0 -0.02567936137404779" />
        <axis xyz="0.2700081868271984 -0.7071067811865476 0.6535254999204613" />
        <dynamics damping="0.0" friction="0.001" />
        <parent link="left_front_wheel" />
        <child link="left_front_roller_3" />
    </joint>
    <gazebo reference="left_front_roller_3">
        <mu1 value="2000.0" />
        <mu2 value="2000.0" />
        <kp value="1000000.0" />
        <kd value="100.0" />
        <material>Gazebo/Black</material>
    </gazebo>
    <!--  link  -->
    <link name="left_front_roller_4">
        <collision>
            <geometry>
                <sphere radius="0.009" />
            </geometry>
        </collision>
        <inertial>
            <mass value="0.036" />
            <inertia ixx="3128e-9" ixy="0.0" ixz="0.0" iyy="3128e-9" iyz="0.0" izz="3128e-9" />
            <origin xyz="0 0 0" rpy="0 0 0" />
        </inertial>
    </link>
    <joint name="left_front_roller_4_joint" type="continuous">
        <origin rpy="0 0 0" xyz="0.06724995128312455 0 8.094700349681064e-05" />
        <axis xyz="-0.0008511252801386329 -0.7071067811865476 0.7071062689481388" />
        <dynamics damping="0.0" friction="0.001" />
        <parent link="left_front_wheel" />
        <child link="left_front_roller_4" />
    </joint>
    <gazebo reference="left_front_roller_4">
        <mu1 value="2000.0" />
        <mu2 value="2000.0" />
        <kp value="1000000.0" />
        <kd value="100.0" />
        <material>Gazebo/Black</material>
    </gazebo>
    <!--  link  -->
    <link name="left_front_roller_5">
        <collision>
            <geometry>
                <sphere radius="0.009" />
            </geometry>
        </collision>
        <inertial>
            <mass value="0.036" />
            <inertia ixx="3128e-9" ixy="0.0" ixz="0.0" iyy="3128e-9" iyz="0.0" izz="3128e-9" />
            <origin xyz="0 0 0" rpy="0 0 0" />
        </inertial>
    </link>
    <joint name="left_front_roller_5_joint" type="continuous">
        <origin rpy="0 0 0" xyz="0.06209210689440703 0 0.025828913283634913" />
        <axis xyz="-0.27158066518271434 -0.7071067811865476 0.6528736036162853" />
        <dynamics damping="0.0" friction="0.001" />
        <parent link="left_front_wheel" />
        <child link="left_front_roller_5" />
    </joint>
    <gazebo reference="left_front_roller_5">
        <mu1 value="2000.0" />
        <mu2 value="2000.0" />
        <kp value="1000000.0" />
        <kd value="100.0" />
        <material>Gazebo/Black</material>
    </gazebo>
    <!--  link  -->
    <link name="left_front_roller_6">
        <collision>
            <geometry>
                <sphere radius="0.009" />
            </geometry>
        </collision>
        <inertial>
            <mass value="0.036" />
            <inertia ixx="3128e-9" ixy="0.0" ixz="0.0" iyy="3128e-9" iyz="0.0" izz="3128e-9" />
            <origin xyz="0 0 0" rpy="0 0 0" />
        </inertial>
    </link>
    <joint name="left_front_roller_6_joint" type="continuous">
        <origin rpy="0 0 0" xyz="0.04746699629001391 0 0.04763871076345167" />
        <axis xyz="-0.5009019394471561 -0.7071067811865476 0.499096430620454" />
        <dynamics damping="0.0" friction="0.001" />
        <parent link="left_front_wheel" />
        <child link="left_front_roller_6" />
    </joint>
    <gazebo reference="left_front_roller_6">
        <mu1 value="2000.0" />
        <mu2 value="2000.0" />
        <kp value="1000000.0" />
        <kd value="100.0" />
        <material>Gazebo/Black</material>
    </gazebo>
    <!--  link  -->
    <link name="left_front_roller_7">
        <collision>
            <geometry>
                <sphere radius="0.009" />
            </geometry>
        </collision>
        <inertial>
            <mass value="0.036" />
            <inertia ixx="3128e-9" ixy="0.0" ixz="0.0" iyy="3128e-9" iyz="0.0" izz="3128e-9" />
            <origin xyz="0 0 0" rpy="0 0 0" />
        </inertial>
    </link>
    <joint name="left_front_roller_7_joint" type="continuous">
        <origin rpy="0 0 0" xyz="0.02560452955756635 0 0.06218497058080603" />
        <axis xyz="-0.6538500280382736 -0.7071067811865476 0.2692213602861942" />
        <dynamics damping="0.0" friction="0.001" />
        <parent link="left_front_wheel" />
        <child link="left_front_roller_7" />
    </joint>
    <gazebo reference="left_front_roller_7">
        <mu1 value="2000.0" />
        <mu2 value="2000.0" />
        <kp value="1000000.0" />
        <kd value="100.0" />
        <material>Gazebo/Black</material>
    </gazebo>
    <!--  link  -->
    <link name="left_front_roller_8">
        <collision>
            <geometry>
                <sphere radius="0.009" />
            </geometry>
        </collision>
        <inertial>
            <mass value="0.036" />
            <inertia ixx="3128e-9" ixy="0.0" ixz="0.0" iyy="3128e-9" iyz="0.0" izz="3128e-9" />
            <origin xyz="0 0 0" rpy="0 0 0" />
        </inertial>
    </link>
    <joint name="left_front_roller_8_joint" type="continuous">
        <origin rpy="0 0 0" xyz="-0.0001618938897152502 0 0.06724980513256877" />
        <axis xyz="-0.7071047322336546 -0.7071067811865476 -0.0017022493271422689" />
        <dynamics damping="0.0" friction="0.001" />
        <parent link="left_front_wheel" />
        <child link="left_front_roller_8" />
    </joint>
    <gazebo reference="left_front_roller_8">
        <mu1 value="2000.0" />
        <mu2 value="2000.0" />
        <kp value="1000000.0" />
        <kd value="100.0" />
        <material>Gazebo/Black</material>
    </gazebo>
    <!--  link  -->
    <link name="left_front_roller_9">
        <collision>
            <geometry>
                <sphere radius="0.009" />
            </geometry>
        </collision>
        <inertial>
            <mass value="0.036" />
            <inertia ixx="3128e-9" ixy="0.0" ixz="0.0" iyy="3128e-9" iyz="0.0" izz="3128e-9" />
            <origin xyz="0 0 0" rpy="0 0 0" />
        </inertial>
    </link>
    <joint name="left_front_roller_9_joint" type="continuous">
        <origin rpy="0 0 0" xyz="-0.025903633160065442 0 0.062060972350654955" />
        <axis xyz="-0.6525462363744081 -0.7071067811865476 -0.2723663147189738" />
        <dynamics damping="0.0" friction="0.001" />
        <parent link="left_front_wheel" />
        <child link="left_front_roller_9" />
    </joint>
    <gazebo reference="left_front_roller_9">
        <mu1 value="2000.0" />
        <mu2 value="2000.0" />
        <kp value="1000000.0" />
        <kd value="100.0" />
        <material>Gazebo/Black</material>
    </gazebo>
    <!--  link  -->
    <link name="left_front_roller_10">
        <collision>
            <geometry>
                <sphere radius="0.009" />
            </geometry>
        </collision>
        <inertial>
            <mass value="0.036" />
            <inertia ixx="3128e-9" ixy="0.0" ixz="0.0" iyy="3128e-9" iyz="0.0" izz="3128e-9" />
            <origin xyz="0 0 0" rpy="0 0 0" />
        </inertial>
    </link>
    <joint name="left_front_roller_10_joint" type="continuous">
        <origin rpy="0 0 0" xyz="-0.04769581099104322 0 0.04740962047840798" />
        <axis xyz="-0.49849314697045194 -0.7071067811865476 -0.5015023254417625" />
        <dynamics damping="0.0" friction="0.001" />
        <parent link="left_front_wheel" />
        <child link="left_front_roller_10" />
    </joint>
    <gazebo reference="left_front_roller_10">
        <mu1 value="2000.0" />
        <mu2 value="2000.0" />
        <kp value="1000000.0" />
        <kd value="100.0" />
        <material>Gazebo/Black</material>
    </gazebo>
    <!--  link  -->
    <link name="left_front_roller_11">
        <collision>
            <geometry>
                <sphere radius="0.009" />
            </geometry>
        </collision>
        <inertial>
            <mass value="0.036" />
            <inertia ixx="3128e-9" ixy="0.0" ixz="0.0" iyy="3128e-9" iyz="0.0" izz="3128e-9" />
            <origin xyz="0 0 0" rpy="0 0 0" />
        </inertial>
    </link>
    <joint name="left_front_roller_11_joint" type="continuous">
        <origin rpy="0 0 0" xyz="-0.06221574501182705 0 0.02552966064449972" />
        <axis xyz="-0.2684341436894733 -0.7071067811865476 -0.6541736088391974" />
        <dynamics damping="0.0" friction="0.001" />
        <parent link="left_front_wheel" />
        <child link="left_front_roller_11" />
    </joint>
    <gazebo reference="left_front_roller_11">
        <mu1 value="2000.0" />
        <mu2 value="2000.0" />
        <kp value="1000000.0" />
        <kd value="100.0" />
        <material>Gazebo/Black</material>
    </gazebo>
    <!--  link  -->
    <link name="left_front_roller_12">
        <collision>
            <geometry>
                <sphere radius="0.009" />
            </geometry>
        </collision>
        <inertial>
            <mass value="0.036" />
            <inertia ixx="3128e-9" ixy="0.0" ixz="0.0" iyy="3128e-9" iyz="0.0" izz="3128e-9" />
            <origin xyz="0 0 0" rpy="0 0 0" />
        </inertial>
    </link>
    <joint name="left_front_roller_12_joint" type="continuous">
        <origin rpy="0 0 0" xyz="-0.06724956154854442 0 -0.00024284054137712588" />
        <axis xyz="0.002553370907877698 -0.7071067811865476 -0.7071021710453214" />
        <dynamics damping="0.0" friction="0.001" />
        <parent link="left_front_wheel" />
        <child link="left_front_roller_12" />
    </joint>
    <gazebo reference="left_front_roller_12">
        <mu1 value="2000.0" />
        <mu2 value="2000.0" />
        <kp value="1000000.0" />
        <kd value="100.0" />
        <material>Gazebo/Black</material>
    </gazebo>
    <!--  link  -->
    <link name="left_front_roller_13">
        <collision>
            <geometry>
                <sphere radius="0.009" />
            </geometry>
        </collision>
        <inertial>
            <mass value="0.036" />
            <inertia ixx="3128e-9" ixy="0.0" ixz="0.0" iyy="3128e-9" iyz="0.0" izz="3128e-9" />
            <origin xyz="0 0 0" rpy="0 0 0" />
        </inertial>
    </link>
    <joint name="left_front_roller_13_joint" type="continuous">
        <origin rpy="0 0 0" xyz="-0.062029747891165755 0 -0.025978315506560806" />
        <axis xyz="0.2731515696430154 -0.7071067811865476 -0.6522179237046135" />
        <dynamics damping="0.0" friction="0.001" />
        <parent link="left_front_wheel" />
        <child link="left_front_roller_13" />
    </joint>
    <gazebo reference="left_front_roller_13">
        <mu1 value="2000.0" />
        <mu2 value="2000.0" />
        <kp value="1000000.0" />
        <kd value="100.0" />
        <material>Gazebo/Black</material>
    </gazebo>
    <!--  link  -->
    <link name="left_front_roller_14">
        <collision>
            <geometry>
                <sphere radius="0.009" />
            </geometry>
        </collision>
        <inertial>
            <mass value="0.036" />
            <inertia ixx="3128e-9" ixy="0.0" ixz="0.0" iyy="3128e-9" iyz="0.0" izz="3128e-9" />
            <origin xyz="0 0 0" rpy="0 0 0" />
        </inertial>
    </link>
    <joint name="left_front_roller_14_joint" type="continuous">
        <origin rpy="0 0 0" xyz="-0.047352175978368535 0 -0.04775284211556018" />
        <axis xyz="0.5021019848452515 -0.7071067811865476 -0.49788914108911725" />
        <dynamics damping="0.0" friction="0.001" />
        <parent link="left_front_wheel" />
        <child link="left_front_roller_14" />
    </joint>
    <gazebo reference="left_front_roller_14">
        <mu1 value="2000.0" />
        <mu2 value="2000.0" />
        <kp value="1000000.0" />
        <kd value="100.0" />
        <material>Gazebo/Black</material>
    </gazebo>
    <!--  link  -->
    <link name="left_front_roller_15">
        <collision>
            <geometry>
                <sphere radius="0.009" />
            </geometry>
        </collision>
        <inertial>
            <mass value="0.036" />
            <inertia ixx="3128e-9" ixy="0.0" ixz="0.0" iyy="3128e-9" iyz="0.0" izz="3128e-9" />
            <origin xyz="0 0 0" rpy="0 0 0" />
        </inertial>
    </link>
    <joint name="left_front_roller_15_joint" type="continuous">
        <origin rpy="0 0 0" xyz="-0.025454754743320145 0 -0.06224642930287183" />
        <axis xyz="0.6544962418544192 -0.7071067811865476 -0.2676465381775779" />
        <dynamics damping="0.0" friction="0.001" />
        <parent link="left_front_wheel" />
        <child link="left_front_roller_15" />
    </joint>
    <gazebo reference="left_front_roller_15">
        <mu1 value="2000.0" />
        <mu2 value="2000.0" />
        <kp value="1000000.0" />
        <kd value="100.0" />
        <material>Gazebo/Black</material>
    </gazebo>
    <!--  link  -->
    <link name="right_front_wheel">
        <visual>
            <geometry>
                <mesh filename="package://sp_description/meshes/common/mecanum_wheel/left_threaded_mecanum_wheel.stl" scale="0.001 0.001 0.001" />
            </geometry>
        </visual>
        <inertial>
            <mass value="0.59" />
            <inertia ixx="1.416e-3" ixy="0.0" ixz="0.0" iyy="2.749e-3" iyz="0.0" izz="1.416e-3" />
        </inertial>
    </link>
    <!--  joint  -->
    <joint name="right_front_wheel_joint" type="revolute">
        <axis xyz="0 1 0" />
        <origin rpy="0 0 0" xyz="0.19727 -0.223 -0.00111" />
        <!--      limit not work while type="continuous"-->
        <limit effort="10" lower="-1e9" upper="1e9" velocity="70" />
        <dynamics damping="0.0" friction="0.05" />
        <parent link="base_link" />
        <child link="right_front_wheel" />
    </joint>
    <!--  link  -->
    <link name="right_front_roller_0">
        <collision>
            <geometry>
                <sphere radius="0.009" />
            </geometry>
        </collision>
        <inertial>
            <mass value="0.036" />
            <inertia ixx="3128e-9" ixy="0.0" ixz="0.0" iyy="3128e-9" iyz="0.0" izz="3128e-9" />
            <origin xyz="0 0 0" rpy="0 0 0" />
        </inertial>
    </link>
    <joint name="right_front_roller_0_joint" type="continuous">
        <origin rpy="0 0 0" xyz="4.117874862132975e-18 0 -0.06725" />
        <axis xyz="0.7071067811865476 0.7071067811865476 0.0" />
        <dynamics damping="0.0" friction="0.001" />
        <parent link="right_front_wheel" />
        <child link="right_front_roller_0" />
    </joint>
    <gazebo reference="right_front_roller_0">
        <mu1 value="2000.0" />
        <mu2 value="2000.0" />
        <kp value="1000000.0" />
        <kd value="100.0" />
        <material>Gazebo/Black</material>
    </gazebo>
    <!--  link  -->
    <link name="right_front_roller_1">
        <collision>
            <geometry>
                <sphere radius="0.009" />
            </geometry>
        </collision>
        <inertial>
            <mass value="0.036" />
            <inertia ixx="3128e-9" ixy="0.0" ixz="0.0" iyy="3128e-9" iyz="0.0" izz="3128e-9" />
            <origin xyz="0 0 0" rpy="0 0 0" />
        </inertial>
    </link>
    <joint name="right_front_roller_1_joint" type="continuous">
        <origin rpy="0 0 0" xyz="0.025754155985525513 0 -0.06212315147731336" />
        <axis xyz="0.653200024955946 0.7071067811865476 0.27079462217250855" />
        <dynamics damping="0.0" friction="0.001" />
        <parent link="right_front_wheel" />
        <child link="right_front_roller_1" />
    </joint>
    <gazebo reference="right_front_roller_1">
        <mu1 value="2000.0" />
        <mu2 value="2000.0" />
        <kp value="1000000.0" />
        <kd value="100.0" />
        <material>Gazebo/Black</material>
    </gazebo>
    <!--  link  -->
    <link name="right_front_roller_2">
        <collision>
            <geometry>
                <sphere radius="0.009" />
            </geometry>
        </collision>
        <inertial>
            <mass value="0.036" />
            <inertia ixx="3128e-9" ixy="0.0" ixz="0.0" iyy="3128e-9" iyz="0.0" izz="3128e-9" />
            <origin xyz="0 0 0" rpy="0 0 0" />
        </inertial>
    </link>
    <joint name="right_front_roller_2_joint" type="continuous">
        <origin rpy="0 0 0" xyz="0.04758154151551398 0 -0.04752430333005861" />
        <axis xyz="0.49969899116506866 0.7071067811865476 0.5003008277312888" />
        <dynamics damping="0.0" friction="0.001" />
        <parent link="right_front_wheel" />
        <child link="right_front_roller_2" />
    </joint>
    <gazebo reference="right_front_roller_2">
        <mu1 value="2000.0" />
        <mu2 value="2000.0" />
        <kp value="1000000.0" />
        <kd value="100.0" />
        <material>Gazebo/Black</material>
    </gazebo>
    <!--  link  -->
    <link name="right_front_roller_3">
        <collision>
            <geometry>
                <sphere radius="0.009" />
            </geometry>
        </collision>
        <inertial>
            <mass value="0.036" />
            <inertia ixx="3128e-9" ixy="0.0" ixz="0.0" iyy="3128e-9" iyz="0.0" izz="3128e-9" />
            <origin xyz="0 0 0" rpy="0 0 0" />
        </inertial>
    </link>
    <joint name="right_front_roller_3_joint" type="continuous">
        <origin rpy="0 0 0" xyz="0.062154106054395655 0 -0.02567936137404779" />
        <axis xyz="0.2700081868271984 0.7071067811865476 0.6535254999204613" />
        <dynamics damping="0.0" friction="0.001" />
        <parent link="right_front_wheel" />
        <child link="right_front_roller_3" />
    </joint>
    <gazebo reference="right_front_roller_3">
        <mu1 value="2000.0" />
        <mu2 value="2000.0" />
        <kp value="1000000.0" />
        <kd value="100.0" />
        <material>Gazebo/Black</material>
    </gazebo>
    <!--  link  -->
    <link name="right_front_roller_4">
        <collision>
            <geometry>
                <sphere radius="0.009" />
            </geometry>
        </collision>
        <inertial>
            <mass value="0.036" />
            <inertia ixx="3128e-9" ixy="0.0" ixz="0.0" iyy="3128e-9" iyz="0.0" izz="3128e-9" />
            <origin xyz="0 0 0" rpy="0 0 0" />
        </inertial>
    </link>
    <joint name="right_front_roller_4_joint" type="continuous">
        <origin rpy="0 0 0" xyz="0.06724995128312455 0 8.094700349681064e-05" />
        <axis xyz="-0.0008511252801386329 0.7071067811865476 0.7071062689481388" />
        <dynamics damping="0.0" friction="0.001" />
        <parent link="right_front_wheel" />
        <child link="right_front_roller_4" />
    </joint>
    <gazebo reference="right_front_roller_4">
        <mu1 value="2000.0" />
        <mu2 value="2000.0" />
        <kp value="1000000.0" />
        <kd value="100.0" />
        <material>Gazebo/Black</material>
    </gazebo>
    <!--  link  -->
    <link name="right_front_roller_5">
        <collision>
            <geometry>
                <sphere radius="0.009" />
            </geometry>
        </collision>
        <inertial>
            <mass value="0.036" />
            <inertia ixx="3128e-9" ixy="0.0" ixz="0.0" iyy="3128e-9" iyz="0.0" izz="3128e-9" />
            <origin xyz="0 0 0" rpy="0 0 0" />
        </inertial>
    </link>
    <joint name="right_front_roller_5_joint" type="continuous">
        <origin rpy="0 0 0" xyz="0.06209210689440703 0 0.025828913283634913" />
        <axis xyz="-0.27158066518271434 0.7071067811865476 0.6528736036162853" />
        <dynamics damping="0.0" friction="0.001" />
        <parent link="right_front_wheel" />
        <child link="right_front_roller_5" />
    </joint>
    <gazebo reference="right_front_roller_5">
        <mu1 value="2000.0" />
        <mu2 value="2000.0" />
        <kp value="1000000.0" />
        <kd value="100.0" />
        <material>Gazebo/Black</material>
    </gazebo>
    <!--  link  -->
    <link name="right_front_roller_6">
        <collision>
            <geometry>
                <sphere radius="0.009" />
            </geometry>
        </collision>
        <inertial>
            <mass value="0.036" />
            <inertia ixx="3128e-9" ixy="0.0" ixz="0.0" iyy="3128e-9" iyz="0.0" izz="3128e-9" />
            <origin xyz="0 0 0" rpy="0 0 0" />
        </inertial>
    </link>
    <joint name="right_front_roller_6_joint" type="continuous">
        <origin rpy="0 0 0" xyz="0.04746699629001391 0 0.04763871076345167" />
        <axis xyz="-0.5009019394471561 0.7071067811865476 0.499096430620454" />
        <dynamics damping="0.0" friction="0.001" />
        <parent link="right_front_wheel" />
        <child link="right_front_roller_6" />
    </joint>
    <gazebo reference="right_front_roller_6">
        <mu1 value="2000.0" />
        <mu2 value="2000.0" />
        <kp value="1000000.0" />
        <kd value="100.0" />
        <material>Gazebo/Black</material>
    </gazebo>
    <!--  link  -->
    <link name="right_front_roller_7">
        <collision>
            <geometry>
                <sphere radius="0.009" />
            </geometry>
        </collision>
        <inertial>
            <mass value="0.036" />
            <inertia ixx="3128e-9" ixy="0.0" ixz="0.0" iyy="3128e-9" iyz="0.0" izz="3128e-9" />
            <origin xyz="0 0 0" rpy="0 0 0" />
        </inertial>
    </link>
    <joint name="right_front_roller_7_joint" type="continuous">
        <origin rpy="0 0 0" xyz="0.02560452955756635 0 0.06218497058080603" />
        <axis xyz="-0.6538500280382736 0.7071067811865476 0.2692213602861942" />
        <dynamics damping="0.0" friction="0.001" />
        <parent link="right_front_wheel" />
        <child link="right_front_roller_7" />
    </joint>
    <gazebo reference="right_front_roller_7">
        <mu1 value="2000.0" />
        <mu2 value="2000.0" />
        <kp value="1000000.0" />
        <kd value="100.0" />
        <material>Gazebo/Black</material>
    </gazebo>
    <!--  link  -->
    <link name="right_front_roller_8">
        <collision>
            <geometry>
                <sphere radius="0.009" />
            </geometry>
        </collision>
        <inertial>
            <mass value="0.036" />
            <inertia ixx="3128e-9" ixy="0.0" ixz="0.0" iyy="3128e-9" iyz="0.0" izz="3128e-9" />
            <origin xyz="0 0 0" rpy="0 0 0" />
        </inertial>
    </link>
    <joint name="right_front_roller_8_joint" type="continuous">
        <origin rpy="0 0 0" xyz="-0.0001618938897152502 0 0.06724980513256877" />
        <axis xyz="-0.7071047322336546 0.7071067811865476 -0.0017022493271422689" />
        <dynamics damping="0.0" friction="0.001" />
        <parent link="right_front_wheel" />
        <child link="right_front_roller_8" />
    </joint>
    <gazebo reference="right_front_roller_8">
        <mu1 value="2000.0" />
        <mu2 value="2000.0" />
        <kp value="1000000.0" />
        <kd value="100.0" />
        <material>Gazebo/Black</material>
    </gazebo>
    <!--  link  -->
    <link name="right_front_roller_9">
        <collision>
            <geometry>
                <sphere radius="0.009" />
            </geometry>
        </collision>
        <inertial>
            <mass value="0.036" />
            <inertia ixx="3128e-9" ixy="0.0" ixz="0.0" iyy="3128e-9" iyz="0.0" izz="3128e-9" />
            <origin xyz="0 0 0" rpy="0 0 0" />
        </inertial>
    </link>
    <joint name="right_front_roller_9_joint" type="continuous">
        <origin rpy="0 0 0" xyz="-0.025903633160065442 0 0.062060972350654955" />
        <axis xyz="-0.6525462363744081 0.7071067811865476 -0.2723663147189738" />
        <dynamics damping="0.0" friction="0.001" />
        <parent link="right_front_wheel" />
        <child link="right_front_roller_9" />
    </joint>
    <gazebo reference="right_front_roller_9">
        <mu1 value="2000.0" />
        <mu2 value="2000.0" />
        <kp value="1000000.0" />
        <kd value="100.0" />
        <material>Gazebo/Black</material>
    </gazebo>
    <!--  link  -->
    <link name="right_front_roller_10">
        <collision>
            <geometry>
                <sphere radius="0.009" />
            </geometry>
        </collision>
        <inertial>
            <mass value="0.036" />
            <inertia ixx="3128e-9" ixy="0.0" ixz="0.0" iyy="3128e-9" iyz="0.0" izz="3128e-9" />
            <origin xyz="0 0 0" rpy="0 0 0" />
        </inertial>
    </link>
    <joint name="right_front_roller_10_joint" type="continuous">
        <origin rpy="0 0 0" xyz="-0.04769581099104322 0 0.04740962047840798" />
        <axis xyz="-0.49849314697045194 0.7071067811865476 -0.5015023254417625" />
        <dynamics damping="0.0" friction="0.001" />
        <parent link="right_front_wheel" />
        <child link="right_front_roller_10" />
    </joint>
    <gazebo reference="right_front_roller_10">
        <mu1 value="2000.0" />
        <mu2 value="2000.0" />
        <kp value="1000000.0" />
        <kd value="100.0" />
        <material>Gazebo/Black</material>
    </gazebo>
    <!--  link  -->
    <link name="right_front_roller_11">
        <collision>
            <geometry>
                <sphere radius="0.009" />
            </geometry>
        </collision>
        <inertial>
            <mass value="0.036" />
            <inertia ixx="3128e-9" ixy="0.0" ixz="0.0" iyy="3128e-9" iyz="0.0" izz="3128e-9" />
            <origin xyz="0 0 0" rpy="0 0 0" />
        </inertial>
    </link>
    <joint name="right_front_roller_11_joint" type="continuous">
        <origin rpy="0 0 0" xyz="-0.06221574501182705 0 0.02552966064449972" />
        <axis xyz="-0.2684341436894733 0.7071067811865476 -0.6541736088391974" />
        <dynamics damping="0.0" friction="0.001" />
        <parent link="right_front_wheel" />
        <child link="right_front_roller_11" />
    </joint>
    <gazebo reference="right_front_roller_11">
        <mu1 value="2000.0" />
        <mu2 value="2000.0" />
        <kp value="1000000.0" />
        <kd value="100.0" />
        <material>Gazebo/Black</material>
    </gazebo>
    <!--  link  -->
    <link name="right_front_roller_12">
        <collision>
            <geometry>
                <sphere radius="0.009" />
            </geometry>
        </collision>
        <inertial>
            <mass value="0.036" />
            <inertia ixx="3128e-9" ixy="0.0" ixz="0.0" iyy="3128e-9" iyz="0.0" izz="3128e-9" />
            <origin xyz="0 0 0" rpy="0 0 0" />
        </inertial>
    </link>
    <joint name="right_front_roller_12_joint" type="continuous">
        <origin rpy="0 0 0" xyz="-0.06724956154854442 0 -0.00024284054137712588" />
        <axis xyz="0.002553370907877698 0.7071067811865476 -0.7071021710453214" />
        <dynamics damping="0.0" friction="0.001" />
        <parent link="right_front_wheel" />
        <child link="right_front_roller_12" />
    </joint>
    <gazebo reference="right_front_roller_12">
        <mu1 value="2000.0" />
        <mu2 value="2000.0" />
        <kp value="1000000.0" />
        <kd value="100.0" />
        <material>Gazebo/Black</material>
    </gazebo>
    <!--  link  -->
    <link name="right_front_roller_13">
        <collision>
            <geometry>
                <sphere radius="0.009" />
            </geometry>
        </collision>
        <inertial>
            <mass value="0.036" />
            <inertia ixx="3128e-9" ixy="0.0" ixz="0.0" iyy="3128e-9" iyz="0.0" izz="3128e-9" />
            <origin xyz="0 0 0" rpy="0 0 0" />
        </inertial>
    </link>
    <joint name="right_front_roller_13_joint" type="continuous">
        <origin rpy="0 0 0" xyz="-0.062029747891165755 0 -0.025978315506560806" />
        <axis xyz="0.2731515696430154 0.7071067811865476 -0.6522179237046135" />
        <dynamics damping="0.0" friction="0.001" />
        <parent link="right_front_wheel" />
        <child link="right_front_roller_13" />
    </joint>
    <gazebo reference="right_front_roller_13">
        <mu1 value="2000.0" />
        <mu2 value="2000.0" />
        <kp value="1000000.0" />
        <kd value="100.0" />
        <material>Gazebo/Black</material>
    </gazebo>
    <!--  link  -->
    <link name="right_front_roller_14">
        <collision>
            <geometry>
                <sphere radius="0.009" />
            </geometry>
        </collision>
        <inertial>
            <mass value="0.036" />
            <inertia ixx="3128e-9" ixy="0.0" ixz="0.0" iyy="3128e-9" iyz="0.0" izz="3128e-9" />
            <origin xyz="0 0 0" rpy="0 0 0" />
        </inertial>
    </link>
    <joint name="right_front_roller_14_joint" type="continuous">
        <origin rpy="0 0 0" xyz="-0.047352175978368535 0 -0.04775284211556018" />
        <axis xyz="0.5021019848452515 0.7071067811865476 -0.49788914108911725" />
        <dynamics damping="0.0" friction="0.001" />
        <parent link="right_front_wheel" />
        <child link="right_front_roller_14" />
    </joint>
    <gazebo reference="right_front_roller_14">
        <mu1 value="2000.0" />
        <mu2 value="2000.0" />
        <kp value="1000000.0" />
        <kd value="100.0" />
        <material>Gazebo/Black</material>
    </gazebo>
    <!--  link  -->
    <link name="right_front_roller_15">
        <collision>
            <geometry>
                <sphere radius="0.009" />
            </geometry>
        </collision>
        <inertial>
            <mass value="0.036" />
            <inertia ixx="3128e-9" ixy="0.0" ixz="0.0" iyy="3128e-9" iyz="0.0" izz="3128e-9" />
            <origin xyz="0 0 0" rpy="0 0 0" />
        </inertial>
    </link>
    <joint name="right_front_roller_15_joint" type="continuous">
        <origin rpy="0 0 0" xyz="-0.025454754743320145 0 -0.06224642930287183" />
        <axis xyz="0.6544962418544192 0.7071067811865476 -0.2676465381775779" />
        <dynamics damping="0.0" friction="0.001" />
        <parent link="right_front_wheel" />
        <child link="right_front_roller_15" />
    </joint>
    <gazebo reference="right_front_roller_15">
        <mu1 value="2000.0" />
        <mu2 value="2000.0" />
        <kp value="1000000.0" />
        <kd value="100.0" />
        <material>Gazebo/Black</material>
    </gazebo>
    <!--  link  -->
    <link name="left_back_wheel">
        <visual>
            <geometry>
                <mesh filename="package://sp_description/meshes/common/mecanum_wheel/left_threaded_mecanum_wheel.stl" scale="0.001 0.001 0.001" />
            </geometry>
        </visual>
        <inertial>
            <mass value="0.59" />
            <inertia ixx="1.416e-3" ixy="0.0" ixz="0.0" iyy="2.749e-3" iyz="0.0" izz="1.416e-3" />
        </inertial>
    </link>
    <!--  joint  -->
    <joint name="left_back_wheel_joint" type="revolute">
        <axis xyz="0 1 0" />
        <origin rpy="0 0 0" xyz="-0.19727 0.223 -0.00111" />
        <!--      limit not work while type="continuous"-->
        <limit effort="10" lower="-1e9" upper="1e9" velocity="70" />
        <dynamics damping="0.0" friction="0.05" />
        <parent link="base_link" />
        <child link="left_back_wheel" />
    </joint>
    <!--  link  -->
    <link name="left_back_roller_0">
        <collision>
            <geometry>
                <sphere radius="0.009" />
            </geometry>
        </collision>
        <inertial>
            <mass value="0.036" />
            <inertia ixx="3128e-9" ixy="0.0" ixz="0.0" iyy="3128e-9" iyz="0.0" izz="3128e-9" />
            <origin xyz="0 0 0" rpy="0 0 0" />
        </inertial>
    </link>
    <joint name="left_back_roller_0_joint" type="continuous">
        <origin rpy="0 0 0" xyz="4.117874862132975e-18 0 -0.06725" />
        <axis xyz="0.7071067811865476 0.7071067811865476 0.0" />
        <dynamics damping="0.0" friction="0.001" />
        <parent link="left_back_wheel" />
        <child link="left_back_roller_0" />
    </joint>
    <gazebo reference="left_back_roller_0">
        <mu1 value="2000.0" />
        <mu2 value="2000.0" />
        <kp value="1000000.0" />
        <kd value="100.0" />
        <material>Gazebo/Black</material>
    </gazebo>
    <!--  link  -->
    <link name="left_back_roller_1">
        <collision>
            <geometry>
                <sphere radius="0.009" />
            </geometry>
        </collision>
        <inertial>
            <mass value="0.036" />
            <inertia ixx="3128e-9" ixy="0.0" ixz="0.0" iyy="3128e-9" iyz="0.0" izz="3128e-9" />
            <origin xyz="0 0 0" rpy="0 0 0" />
        </inertial>
    </link>
    <joint name="left_back_roller_1_joint" type="continuous">
        <origin rpy="0 0 0" xyz="0.025754155985525513 0 -0.06212315147731336" />
        <axis xyz="0.653200024955946 0.7071067811865476 0.27079462217250855" />
        <dynamics damping="0.0" friction="0.001" />
        <parent link="left_back_wheel" />
        <child link="left_back_roller_1" />
    </joint>
    <gazebo reference="left_back_roller_1">
        <mu1 value="2000.0" />
        <mu2 value="2000.0" />
        <kp value="1000000.0" />
        <kd value="100.0" />
        <material>Gazebo/Black</material>
    </gazebo>
    <!--  link  -->
    <link name="left_back_roller_2">
        <collision>
            <geometry>
                <sphere radius="0.009" />
            </geometry>
        </collision>
        <inertial>
            <mass value="0.036" />
            <inertia ixx="3128e-9" ixy="0.0" ixz="0.0" iyy="3128e-9" iyz="0.0" izz="3128e-9" />
            <origin xyz="0 0 0" rpy="0 0 0" />
        </inertial>
    </link>
    <joint name="left_back_roller_2_joint" type="continuous">
        <origin rpy="0 0 0" xyz="0.04758154151551398 0 -0.04752430333005861" />
        <axis xyz="0.49969899116506866 0.7071067811865476 0.5003008277312888" />
        <dynamics damping="0.0" friction="0.001" />
        <parent link="left_back_wheel" />
        <child link="left_back_roller_2" />
    </joint>
    <gazebo reference="left_back_roller_2">
        <mu1 value="2000.0" />
        <mu2 value="2000.0" />
        <kp value="1000000.0" />
        <kd value="100.0" />
        <material>Gazebo/Black</material>
    </gazebo>
    <!--  link  -->
    <link name="left_back_roller_3">
        <collision>
            <geometry>
                <sphere radius="0.009" />
            </geometry>
        </collision>
        <inertial>
            <mass value="0.036" />
            <inertia ixx="3128e-9" ixy="0.0" ixz="0.0" iyy="3128e-9" iyz="0.0" izz="3128e-9" />
            <origin xyz="0 0 0" rpy="0 0 0" />
        </inertial>
    </link>
    <joint name="left_back_roller_3_joint" type="continuous">
        <origin rpy="0 0 0" xyz="0.062154106054395655 0 -0.02567936137404779" />
        <axis xyz="0.2700081868271984 0.7071067811865476 0.6535254999204613" />
        <dynamics damping="0.0" friction="0.001" />
        <parent link="left_back_wheel" />
        <child link="left_back_roller_3" />
    </joint>
    <gazebo reference="left_back_roller_3">
        <mu1 value="2000.0" />
        <mu2 value="2000.0" />
        <kp value="1000000.0" />
        <kd value="100.0" />
        <material>Gazebo/Black</material>
    </gazebo>
    <!--  link  -->
    <link name="left_back_roller_4">
        <collision>
            <geometry>
                <sphere radius="0.009" />
            </geometry>
        </collision>
        <inertial>
            <mass value="0.036" />
            <inertia ixx="3128e-9" ixy="0.0" ixz="0.0" iyy="3128e-9" iyz="0.0" izz="3128e-9" />
            <origin xyz="0 0 0" rpy="0 0 0" />
        </inertial>
    </link>
    <joint name="left_back_roller_4_joint" type="continuous">
        <origin rpy="0 0 0" xyz="0.06724995128312455 0 8.094700349681064e-05" />
        <axis xyz="-0.0008511252801386329 0.7071067811865476 0.7071062689481388" />
        <dynamics damping="0.0" friction="0.001" />
        <parent link="left_back_wheel" />
        <child link="left_back_roller_4" />
    </joint>
    <gazebo reference="left_back_roller_4">
        <mu1 value="2000.0" />
        <mu2 value="2000.0" />
        <kp value="1000000.0" />
        <kd value="100.0" />
        <material>Gazebo/Black</material>
    </gazebo>
    <!--  link  -->
    <link name="left_back_roller_5">
        <collision>
            <geometry>
                <sphere radius="0.009" />
            </geometry>
        </collision>
        <inertial>
            <mass value="0.036" />
            <inertia ixx="3128e-9" ixy="0.0" ixz="0.0" iyy="3128e-9" iyz="0.0" izz="3128e-9" />
            <origin xyz="0 0 0" rpy="0 0 0" />
        </inertial>
    </link>
    <joint name="left_back_roller_5_joint" type="continuous">
        <origin rpy="0 0 0" xyz="0.06209210689440703 0 0.025828913283634913" />
        <axis xyz="-0.27158066518271434 0.7071067811865476 0.6528736036162853" />
        <dynamics damping="0.0" friction="0.001" />
        <parent link="left_back_wheel" />
        <child link="left_back_roller_5" />
    </joint>
    <gazebo reference="left_back_roller_5">
        <mu1 value="2000.0" />
        <mu2 value="2000.0" />
        <kp value="1000000.0" />
        <kd value="100.0" />
        <material>Gazebo/Black</material>
    </gazebo>
    <!--  link  -->
    <link name="left_back_roller_6">
        <collision>
            <geometry>
                <sphere radius="0.009" />
            </geometry>
        </collision>
        <inertial>
            <mass value="0.036" />
            <inertia ixx="3128e-9" ixy="0.0" ixz="0.0" iyy="3128e-9" iyz="0.0" izz="3128e-9" />
            <origin xyz="0 0 0" rpy="0 0 0" />
        </inertial>
    </link>
    <joint name="left_back_roller_6_joint" type="continuous">
        <origin rpy="0 0 0" xyz="0.04746699629001391 0 0.04763871076345167" />
        <axis xyz="-0.5009019394471561 0.7071067811865476 0.499096430620454" />
        <dynamics damping="0.0" friction="0.001" />
        <parent link="left_back_wheel" />
        <child link="left_back_roller_6" />
    </joint>
    <gazebo reference="left_back_roller_6">
        <mu1 value="2000.0" />
        <mu2 value="2000.0" />
        <kp value="1000000.0" />
        <kd value="100.0" />
        <material>Gazebo/Black</material>
    </gazebo>
    <!--  link  -->
    <link name="left_back_roller_7">
        <collision>
            <geometry>
                <sphere radius="0.009" />
            </geometry>
        </collision>
        <inertial>
            <mass value="0.036" />
            <inertia ixx="3128e-9" ixy="0.0" ixz="0.0" iyy="3128e-9" iyz="0.0" izz="3128e-9" />
            <origin xyz="0 0 0" rpy="0 0 0" />
        </inertial>
    </link>
    <joint name="left_back_roller_7_joint" type="continuous">
        <origin rpy="0 0 0" xyz="0.02560452955756635 0 0.06218497058080603" />
        <axis xyz="-0.6538500280382736 0.7071067811865476 0.2692213602861942" />
        <dynamics damping="0.0" friction="0.001" />
        <parent link="left_back_wheel" />
        <child link="left_back_roller_7" />
    </joint>
    <gazebo reference="left_back_roller_7">
        <mu1 value="2000.0" />
        <mu2 value="2000.0" />
        <kp value="1000000.0" />
        <kd value="100.0" />
        <material>Gazebo/Black</material>
    </gazebo>
    <!--  link  -->
    <link name="left_back_roller_8">
        <collision>
            <geometry>
                <sphere radius="0.009" />
            </geometry>
        </collision>
        <inertial>
            <mass value="0.036" />
            <inertia ixx="3128e-9" ixy="0.0" ixz="0.0" iyy="3128e-9" iyz="0.0" izz="3128e-9" />
            <origin xyz="0 0 0" rpy="0 0 0" />
        </inertial>
    </link>
    <joint name="left_back_roller_8_joint" type="continuous">
        <origin rpy="0 0 0" xyz="-0.0001618938897152502 0 0.06724980513256877" />
        <axis xyz="-0.7071047322336546 0.7071067811865476 -0.0017022493271422689" />
        <dynamics damping="0.0" friction="0.001" />
        <parent link="left_back_wheel" />
        <child link="left_back_roller_8" />
    </joint>
    <gazebo reference="left_back_roller_8">
        <mu1 value="2000.0" />
        <mu2 value="2000.0" />
        <kp value="1000000.0" />
        <kd value="100.0" />
        <material>Gazebo/Black</material>
    </gazebo>
    <!--  link  -->
    <link name="left_back_roller_9">
        <collision>
            <geometry>
                <sphere radius="0.009" />
            </geometry>
        </collision>
        <inertial>
            <mass value="0.036" />
            <inertia ixx="3128e-9" ixy="0.0" ixz="0.0" iyy="3128e-9" iyz="0.0" izz="3128e-9" />
            <origin xyz="0 0 0" rpy="0 0 0" />
        </inertial>
    </link>
    <joint name="left_back_roller_9_joint" type="continuous">
        <origin rpy="0 0 0" xyz="-0.025903633160065442 0 0.062060972350654955" />
        <axis xyz="-0.6525462363744081 0.7071067811865476 -0.2723663147189738" />
        <dynamics damping="0.0" friction="0.001" />
        <parent link="left_back_wheel" />
        <child link="left_back_roller_9" />
    </joint>
    <gazebo reference="left_back_roller_9">
        <mu1 value="2000.0" />
        <mu2 value="2000.0" />
        <kp value="1000000.0" />
        <kd value="100.0" />
        <material>Gazebo/Black</material>
    </gazebo>
    <!--  link  -->
    <link name="left_back_roller_10">
        <collision>
            <geometry>
                <sphere radius="0.009" />
            </geometry>
        </collision>
        <inertial>
            <mass value="0.036" />
            <inertia ixx="3128e-9" ixy="0.0" ixz="0.0" iyy="3128e-9" iyz="0.0" izz="3128e-9" />
            <origin xyz="0 0 0" rpy="0 0 0" />
        </inertial>
    </link>
    <joint name="left_back_roller_10_joint" type="continuous">
        <origin rpy="0 0 0" xyz="-0.04769581099104322 0 0.04740962047840798" />
        <axis xyz="-0.49849314697045194 0.7071067811865476 -0.5015023254417625" />
        <dynamics damping="0.0" friction="0.001" />
        <parent link="left_back_wheel" />
        <child link="left_back_roller_10" />
    </joint>
    <gazebo reference="left_back_roller_10">
        <mu1 value="2000.0" />
        <mu2 value="2000.0" />
        <kp value="1000000.0" />
        <kd value="100.0" />
        <material>Gazebo/Black</material>
    </gazebo>
    <!--  link  -->
    <link name="left_back_roller_11">
        <collision>
            <geometry>
                <sphere radius="0.009" />
            </geometry>
        </collision>
        <inertial>
            <mass value="0.036" />
            <inertia ixx="3128e-9" ixy="0.0" ixz="0.0" iyy="3128e-9" iyz="0.0" izz="3128e-9" />
            <origin xyz="0 0 0" rpy="0 0 0" />
        </inertial>
    </link>
    <joint name="left_back_roller_11_joint" type="continuous">
        <origin rpy="0 0 0" xyz="-0.06221574501182705 0 0.02552966064449972" />
        <axis xyz="-0.2684341436894733 0.7071067811865476 -0.6541736088391974" />
        <dynamics damping="0.0" friction="0.001" />
        <parent link="left_back_wheel" />
        <child link="left_back_roller_11" />
    </joint>
    <gazebo reference="left_back_roller_11">
        <mu1 value="2000.0" />
        <mu2 value="2000.0" />
        <kp value="1000000.0" />
        <kd value="100.0" />
        <material>Gazebo/Black</material>
    </gazebo>
    <!--  link  -->
    <link name="left_back_roller_12">
        <collision>
            <geometry>
                <sphere radius="0.009" />
            </geometry>
        </collision>
        <inertial>
            <mass value="0.036" />
            <inertia ixx="3128e-9" ixy="0.0" ixz="0.0" iyy="3128e-9" iyz="0.0" izz="3128e-9" />
            <origin xyz="0 0 0" rpy="0 0 0" />
        </inertial>
    </link>
    <joint name="left_back_roller_12_joint" type="continuous">
        <origin rpy="0 0 0" xyz="-0.06724956154854442 0 -0.00024284054137712588" />
        <axis xyz="0.002553370907877698 0.7071067811865476 -0.7071021710453214" />
        <dynamics damping="0.0" friction="0.001" />
        <parent link="left_back_wheel" />
        <child link="left_back_roller_12" />
    </joint>
    <gazebo reference="left_back_roller_12">
        <mu1 value="2000.0" />
        <mu2 value="2000.0" />
        <kp value="1000000.0" />
        <kd value="100.0" />
        <material>Gazebo/Black</material>
    </gazebo>
    <!--  link  -->
    <link name="left_back_roller_13">
        <collision>
            <geometry>
                <sphere radius="0.009" />
            </geometry>
        </collision>
        <inertial>
            <mass value="0.036" />
            <inertia ixx="3128e-9" ixy="0.0" ixz="0.0" iyy="3128e-9" iyz="0.0" izz="3128e-9" />
            <origin xyz="0 0 0" rpy="0 0 0" />
        </inertial>
    </link>
    <joint name="left_back_roller_13_joint" type="continuous">
        <origin rpy="0 0 0" xyz="-0.062029747891165755 0 -0.025978315506560806" />
        <axis xyz="0.2731515696430154 0.7071067811865476 -0.6522179237046135" />
        <dynamics damping="0.0" friction="0.001" />
        <parent link="left_back_wheel" />
        <child link="left_back_roller_13" />
    </joint>
    <gazebo reference="left_back_roller_13">
        <mu1 value="2000.0" />
        <mu2 value="2000.0" />
        <kp value="1000000.0" />
        <kd value="100.0" />
        <material>Gazebo/Black</material>
    </gazebo>
    <!--  link  -->
    <link name="left_back_roller_14">
        <collision>
            <geometry>
                <sphere radius="0.009" />
            </geometry>
        </collision>
        <inertial>
            <mass value="0.036" />
            <inertia ixx="3128e-9" ixy="0.0" ixz="0.0" iyy="3128e-9" iyz="0.0" izz="3128e-9" />
            <origin xyz="0 0 0" rpy="0 0 0" />
        </inertial>
    </link>
    <joint name="left_back_roller_14_joint" type="continuous">
        <origin rpy="0 0 0" xyz="-0.047352175978368535 0 -0.04775284211556018" />
        <axis xyz="0.5021019848452515 0.7071067811865476 -0.49788914108911725" />
        <dynamics damping="0.0" friction="0.001" />
        <parent link="left_back_wheel" />
        <child link="left_back_roller_14" />
    </joint>
    <gazebo reference="left_back_roller_14">
        <mu1 value="2000.0" />
        <mu2 value="2000.0" />
        <kp value="1000000.0" />
        <kd value="100.0" />
        <material>Gazebo/Black</material>
    </gazebo>
    <!--  link  -->
    <link name="left_back_roller_15">
        <collision>
            <geometry>
                <sphere radius="0.009" />
            </geometry>
        </collision>
        <inertial>
            <mass value="0.036" />
            <inertia ixx="3128e-9" ixy="0.0" ixz="0.0" iyy="3128e-9" iyz="0.0" izz="3128e-9" />
            <origin xyz="0 0 0" rpy="0 0 0" />
        </inertial>
    </link>
    <joint name="left_back_roller_15_joint" type="continuous">
        <origin rpy="0 0 0" xyz="-0.025454754743320145 0 -0.06224642930287183" />
        <axis xyz="0.6544962418544192 0.7071067811865476 -0.2676465381775779" />
        <dynamics damping="0.0" friction="0.001" />
        <parent link="left_back_wheel" />
        <child link="left_back_roller_15" />
    </joint>
    <gazebo reference="left_back_roller_15">
        <mu1 value="2000.0" />
        <mu2 value="2000.0" />
        <kp value="1000000.0" />
        <kd value="100.0" />
        <material>Gazebo/Black</material>
    </gazebo>
    <!--  link  -->
    <link name="right_back_wheel">
        <visual>
            <geometry>
                <mesh filename="package://sp_description/meshes/common/mecanum_wheel/right_threaded_mecanum_wheel.stl" scale="0.001 0.001 0.001" />
            </geometry>
        </visual>
        <inertial>
            <mass value="0.59" />
            <inertia ixx="1.416e-3" ixy="0.0" ixz="0.0" iyy="2.749e-3" iyz="0.0" izz="1.416e-3" />
        </inertial>
    </link>
    <!--  joint  -->
    <joint name="right_back_wheel_joint" type="revolute">
        <axis xyz="0 1 0" />
        <origin rpy="0 0 0" xyz="-0.19727 -0.223 -0.00111" />
        <!--      limit not work while type="continuous"-->
        <limit effort="10" lower="-1e9" upper="1e9" velocity="70" />
        <dynamics damping="0.0" friction="0.05" />
        <parent link="base_link" />
        <child link="right_back_wheel" />
    </joint>
    <!--  link  -->
    <link name="right_back_roller_0">
        <collision>
            <geometry>
                <sphere radius="0.009" />
            </geometry>
        </collision>
        <inertial>
            <mass value="0.036" />
            <inertia ixx="3128e-9" ixy="0.0" ixz="0.0" iyy="3128e-9" iyz="0.0" izz="3128e-9" />
            <origin xyz="0 0 0" rpy="0 0 0" />
        </inertial>
    </link>
    <joint name="right_back_roller_0_joint" type="continuous">
        <origin rpy="0 0 0" xyz="4.117874862132975e-18 0 -0.06725" />
        <axis xyz="0.7071067811865476 -0.7071067811865476 0.0" />
        <dynamics damping="0.0" friction="0.001" />
        <parent link="right_back_wheel" />
        <child link="right_back_roller_0" />
    </joint>
    <gazebo reference="right_back_roller_0">
        <mu1 value="2000.0" />
        <mu2 value="2000.0" />
        <kp value="1000000.0" />
        <kd value="100.0" />
        <material>Gazebo/Black</material>
    </gazebo>
    <!--  link  -->
    <link name="right_back_roller_1">
        <collision>
            <geometry>
                <sphere radius="0.009" />
            </geometry>
        </collision>
        <inertial>
            <mass value="0.036" />
            <inertia ixx="3128e-9" ixy="0.0" ixz="0.0" iyy="3128e-9" iyz="0.0" izz="3128e-9" />
            <origin xyz="0 0 0" rpy="0 0 0" />
        </inertial>
    </link>
    <joint name="right_back_roller_1_joint" type="continuous">
        <origin rpy="0 0 0" xyz="0.025754155985525513 0 -0.06212315147731336" />
        <axis xyz="0.653200024955946 -0.7071067811865476 0.27079462217250855" />
        <dynamics damping="0.0" friction="0.001" />
        <parent link="right_back_wheel" />
        <child link="right_back_roller_1" />
    </joint>
    <gazebo reference="right_back_roller_1">
        <mu1 value="2000.0" />
        <mu2 value="2000.0" />
        <kp value="1000000.0" />
        <kd value="100.0" />
        <material>Gazebo/Black</material>
    </gazebo>
    <!--  link  -->
    <link name="right_back_roller_2">
        <collision>
            <geometry>
                <sphere radius="0.009" />
            </geometry>
        </collision>
        <inertial>
            <mass value="0.036" />
            <inertia ixx="3128e-9" ixy="0.0" ixz="0.0" iyy="3128e-9" iyz="0.0" izz="3128e-9" />
            <origin xyz="0 0 0" rpy="0 0 0" />
        </inertial>
    </link>
    <joint name="right_back_roller_2_joint" type="continuous">
        <origin rpy="0 0 0" xyz="0.04758154151551398 0 -0.04752430333005861" />
        <axis xyz="0.49969899116506866 -0.7071067811865476 0.5003008277312888" />
        <dynamics damping="0.0" friction="0.001" />
        <parent link="right_back_wheel" />
        <child link="right_back_roller_2" />
    </joint>
    <gazebo reference="right_back_roller_2">
        <mu1 value="2000.0" />
        <mu2 value="2000.0" />
        <kp value="1000000.0" />
        <kd value="100.0" />
        <material>Gazebo/Black</material>
    </gazebo>
    <!--  link  -->
    <link name="right_back_roller_3">
        <collision>
            <geometry>
                <sphere radius="0.009" />
            </geometry>
        </collision>
        <inertial>
            <mass value="0.036" />
            <inertia ixx="3128e-9" ixy="0.0" ixz="0.0" iyy="3128e-9" iyz="0.0" izz="3128e-9" />
            <origin xyz="0 0 0" rpy="0 0 0" />
        </inertial>
    </link>
    <joint name="right_back_roller_3_joint" type="continuous">
        <origin rpy="0 0 0" xyz="0.062154106054395655 0 -0.02567936137404779" />
        <axis xyz="0.2700081868271984 -0.7071067811865476 0.6535254999204613" />
        <dynamics damping="0.0" friction="0.001" />
        <parent link="right_back_wheel" />
        <child link="right_back_roller_3" />
    </joint>
    <gazebo reference="right_back_roller_3">
        <mu1 value="2000.0" />
        <mu2 value="2000.0" />
        <kp value="1000000.0" />
        <kd value="100.0" />
        <material>Gazebo/Black</material>
    </gazebo>
    <!--  link  -->
    <link name="right_back_roller_4">
        <collision>
            <geometry>
                <sphere radius="0.009" />
            </geometry>
        </collision>
        <inertial>
            <mass value="0.036" />
            <inertia ixx="3128e-9" ixy="0.0" ixz="0.0" iyy="3128e-9" iyz="0.0" izz="3128e-9" />
            <origin xyz="0 0 0" rpy="0 0 0" />
        </inertial>
    </link>
    <joint name="right_back_roller_4_joint" type="continuous">
        <origin rpy="0 0 0" xyz="0.06724995128312455 0 8.094700349681064e-05" />
        <axis xyz="-0.0008511252801386329 -0.7071067811865476 0.7071062689481388" />
        <dynamics damping="0.0" friction="0.001" />
        <parent link="right_back_wheel" />
        <child link="right_back_roller_4" />
    </joint>
    <gazebo reference="right_back_roller_4">
        <mu1 value="2000.0" />
        <mu2 value="2000.0" />
        <kp value="1000000.0" />
        <kd value="100.0" />
        <material>Gazebo/Black</material>
    </gazebo>
    <!--  link  -->
    <link name="right_back_roller_5">
        <collision>
            <geometry>
                <sphere radius="0.009" />
            </geometry>
        </collision>
        <inertial>
            <mass value="0.036" />
            <inertia ixx="3128e-9" ixy="0.0" ixz="0.0" iyy="3128e-9" iyz="0.0" izz="3128e-9" />
            <origin xyz="0 0 0" rpy="0 0 0" />
        </inertial>
    </link>
    <joint name="right_back_roller_5_joint" type="continuous">
        <origin rpy="0 0 0" xyz="0.06209210689440703 0 0.025828913283634913" />
        <axis xyz="-0.27158066518271434 -0.7071067811865476 0.6528736036162853" />
        <dynamics damping="0.0" friction="0.001" />
        <parent link="right_back_wheel" />
        <child link="right_back_roller_5" />
    </joint>
    <gazebo reference="right_back_roller_5">
        <mu1 value="2000.0" />
        <mu2 value="2000.0" />
        <kp value="1000000.0" />
        <kd value="100.0" />
        <material>Gazebo/Black</material>
    </gazebo>
    <!--  link  -->
    <link name="right_back_roller_6">
        <collision>
            <geometry>
                <sphere radius="0.009" />
            </geometry>
        </collision>
        <inertial>
            <mass value="0.036" />
            <inertia ixx="3128e-9" ixy="0.0" ixz="0.0" iyy="3128e-9" iyz="0.0" izz="3128e-9" />
            <origin xyz="0 0 0" rpy="0 0 0" />
        </inertial>
    </link>
    <joint name="right_back_roller_6_joint" type="continuous">
        <origin rpy="0 0 0" xyz="0.04746699629001391 0 0.04763871076345167" />
        <axis xyz="-0.5009019394471561 -0.7071067811865476 0.499096430620454" />
        <dynamics damping="0.0" friction="0.001" />
        <parent link="right_back_wheel" />
        <child link="right_back_roller_6" />
    </joint>
    <gazebo reference="right_back_roller_6">
        <mu1 value="2000.0" />
        <mu2 value="2000.0" />
        <kp value="1000000.0" />
        <kd value="100.0" />
        <material>Gazebo/Black</material>
    </gazebo>
    <!--  link  -->
    <link name="right_back_roller_7">
        <collision>
            <geometry>
                <sphere radius="0.009" />
            </geometry>
        </collision>
        <inertial>
            <mass value="0.036" />
            <inertia ixx="3128e-9" ixy="0.0" ixz="0.0" iyy="3128e-9" iyz="0.0" izz="3128e-9" />
            <origin xyz="0 0 0" rpy="0 0 0" />
        </inertial>
    </link>
    <joint name="right_back_roller_7_joint" type="continuous">
        <origin rpy="0 0 0" xyz="0.02560452955756635 0 0.06218497058080603" />
        <axis xyz="-0.6538500280382736 -0.7071067811865476 0.2692213602861942" />
        <dynamics damping="0.0" friction="0.001" />
        <parent link="right_back_wheel" />
        <child link="right_back_roller_7" />
    </joint>
    <gazebo reference="right_back_roller_7">
        <mu1 value="2000.0" />
        <mu2 value="2000.0" />
        <kp value="1000000.0" />
        <kd value="100.0" />
        <material>Gazebo/Black</material>
    </gazebo>
    <!--  link  -->
    <link name="right_back_roller_8">
        <collision>
            <geometry>
                <sphere radius="0.009" />
            </geometry>
        </collision>
        <inertial>
            <mass value="0.036" />
            <inertia ixx="3128e-9" ixy="0.0" ixz="0.0" iyy="3128e-9" iyz="0.0" izz="3128e-9" />
            <origin xyz="0 0 0" rpy="0 0 0" />
        </inertial>
    </link>
    <joint name="right_back_roller_8_joint" type="continuous">
        <origin rpy="0 0 0" xyz="-0.0001618938897152502 0 0.06724980513256877" />
        <axis xyz="-0.7071047322336546 -0.7071067811865476 -0.0017022493271422689" />
        <dynamics damping="0.0" friction="0.001" />
        <parent link="right_back_wheel" />
        <child link="right_back_roller_8" />
    </joint>
    <gazebo reference="right_back_roller_8">
        <mu1 value="2000.0" />
        <mu2 value="2000.0" />
        <kp value="1000000.0" />
        <kd value="100.0" />
        <material>Gazebo/Black</material>
    </gazebo>
    <!--  link  -->
    <link name="right_back_roller_9">
        <collision>
            <geometry>
                <sphere radius="0.009" />
            </geometry>
        </collision>
        <inertial>
            <mass value="0.036" />
            <inertia ixx="3128e-9" ixy="0.0" ixz="0.0" iyy="3128e-9" iyz="0.0" izz="3128e-9" />
            <origin xyz="0 0 0" rpy="0 0 0" />
        </inertial>
    </link>
    <joint name="right_back_roller_9_joint" type="continuous">
        <origin rpy="0 0 0" xyz="-0.025903633160065442 0 0.062060972350654955" />
        <axis xyz="-0.6525462363744081 -0.7071067811865476 -0.2723663147189738" />
        <dynamics damping="0.0" friction="0.001" />
        <parent link="right_back_wheel" />
        <child link="right_back_roller_9" />
    </joint>
    <gazebo reference="right_back_roller_9">
        <mu1 value="2000.0" />
        <mu2 value="2000.0" />
        <kp value="1000000.0" />
        <kd value="100.0" />
        <material>Gazebo/Black</material>
    </gazebo>
    <!--  link  -->
    <link name="right_back_roller_10">
        <collision>
            <geometry>
                <sphere radius="0.009" />
            </geometry>
        </collision>
        <inertial>
            <mass value="0.036" />
            <inertia ixx="3128e-9" ixy="0.0" ixz="0.0" iyy="3128e-9" iyz="0.0" izz="3128e-9" />
            <origin xyz="0 0 0" rpy="0 0 0" />
        </inertial>
    </link>
    <joint name="right_back_roller_10_joint" type="continuous">
        <origin rpy="0 0 0" xyz="-0.04769581099104322 0 0.04740962047840798" />
        <axis xyz="-0.49849314697045194 -0.7071067811865476 -0.5015023254417625" />
        <dynamics damping="0.0" friction="0.001" />
        <parent link="right_back_wheel" />
        <child link="right_back_roller_10" />
    </joint>
    <gazebo reference="right_back_roller_10">
        <mu1 value="2000.0" />
        <mu2 value="2000.0" />
        <kp value="1000000.0" />
        <kd value="100.0" />
        <material>Gazebo/Black</material>
    </gazebo>
    <!--  link  -->
    <link name="right_back_roller_11">
        <collision>
            <geometry>
                <sphere radius="0.009" />
            </geometry>
        </collision>
        <inertial>
            <mass value="0.036" />
            <inertia ixx="3128e-9" ixy="0.0" ixz="0.0" iyy="3128e-9" iyz="0.0" izz="3128e-9" />
            <origin xyz="0 0 0" rpy="0 0 0" />
        </inertial>
    </link>
    <joint name="right_back_roller_11_joint" type="continuous">
        <origin rpy="0 0 0" xyz="-0.06221574501182705 0 0.02552966064449972" />
        <axis xyz="-0.2684341436894733 -0.7071067811865476 -0.6541736088391974" />
        <dynamics damping="0.0" friction="0.001" />
        <parent link="right_back_wheel" />
        <child link="right_back_roller_11" />
    </joint>
    <gazebo reference="right_back_roller_11">
        <mu1 value="2000.0" />
        <mu2 value="2000.0" />
        <kp value="1000000.0" />
        <kd value="100.0" />
        <material>Gazebo/Black</material>
    </gazebo>
    <!--  link  -->
    <link name="right_back_roller_12">
        <collision>
            <geometry>
                <sphere radius="0.009" />
            </geometry>
        </collision>
        <inertial>
            <mass value="0.036" />
            <inertia ixx="3128e-9" ixy="0.0" ixz="0.0" iyy="3128e-9" iyz="0.0" izz="3128e-9" />
            <origin xyz="0 0 0" rpy="0 0 0" />
        </inertial>
    </link>
    <joint name="right_back_roller_12_joint" type="continuous">
        <origin rpy="0 0 0" xyz="-0.06724956154854442 0 -0.00024284054137712588" />
        <axis xyz="0.002553370907877698 -0.7071067811865476 -0.7071021710453214" />
        <dynamics damping="0.0" friction="0.001" />
        <parent link="right_back_wheel" />
        <child link="right_back_roller_12" />
    </joint>
    <gazebo reference="right_back_roller_12">
        <mu1 value="2000.0" />
        <mu2 value="2000.0" />
        <kp value="1000000.0" />
        <kd value="100.0" />
        <material>Gazebo/Black</material>
    </gazebo>
    <!--  link  -->
    <link name="right_back_roller_13">
        <collision>
            <geometry>
                <sphere radius="0.009" />
            </geometry>
        </collision>
        <inertial>
            <mass value="0.036" />
            <inertia ixx="3128e-9" ixy="0.0" ixz="0.0" iyy="3128e-9" iyz="0.0" izz="3128e-9" />
            <origin xyz="0 0 0" rpy="0 0 0" />
        </inertial>
    </link>
    <joint name="right_back_roller_13_joint" type="continuous">
        <origin rpy="0 0 0" xyz="-0.062029747891165755 0 -0.025978315506560806" />
        <axis xyz="0.2731515696430154 -0.7071067811865476 -0.6522179237046135" />
        <dynamics damping="0.0" friction="0.001" />
        <parent link="right_back_wheel" />
        <child link="right_back_roller_13" />
    </joint>
    <gazebo reference="right_back_roller_13">
        <mu1 value="2000.0" />
        <mu2 value="2000.0" />
        <kp value="1000000.0" />
        <kd value="100.0" />
        <material>Gazebo/Black</material>
    </gazebo>
    <!--  link  -->
    <link name="right_back_roller_14">
        <collision>
            <geometry>
                <sphere radius="0.009" />
            </geometry>
        </collision>
        <inertial>
            <mass value="0.036" />
            <inertia ixx="3128e-9" ixy="0.0" ixz="0.0" iyy="3128e-9" iyz="0.0" izz="3128e-9" />
            <origin xyz="0 0 0" rpy="0 0 0" />
        </inertial>
    </link>
    <joint name="right_back_roller_14_joint" type="continuous">
        <origin rpy="0 0 0" xyz="-0.047352175978368535 0 -0.04775284211556018" />
        <axis xyz="0.5021019848452515 -0.7071067811865476 -0.49788914108911725" />
        <dynamics damping="0.0" friction="0.001" />
        <parent link="right_back_wheel" />
        <child link="right_back_roller_14" />
    </joint>
    <gazebo reference="right_back_roller_14">
        <mu1 value="2000.0" />
        <mu2 value="2000.0" />
        <kp value="1000000.0" />
        <kd value="100.0" />
        <material>Gazebo/Black</material>
    </gazebo>
    <!--  link  -->
    <link name="right_back_roller_15">
        <collision>
            <geometry>
                <sphere radius="0.009" />
            </geometry>
        </collision>
        <inertial>
            <mass value="0.036" />
            <inertia ixx="3128e-9" ixy="0.0" ixz="0.0" iyy="3128e-9" iyz="0.0" izz="3128e-9" />
            <origin xyz="0 0 0" rpy="0 0 0" />
        </inertial>
    </link>
    <joint name="right_back_roller_15_joint" type="continuous">
        <origin rpy="0 0 0" xyz="-0.025454754743320145 0 -0.06224642930287183" />
        <axis xyz="0.6544962418544192 -0.7071067811865476 -0.2676465381775779" />
        <dynamics damping="0.0" friction="0.001" />
        <parent link="right_back_wheel" />
        <child link="right_back_roller_15" />
    </joint>
    <gazebo reference="right_back_roller_15">
        <mu1 value="2000.0" />
        <mu2 value="2000.0" />
        <kp value="1000000.0" />
        <kd value="100.0" />
        <material>Gazebo/Black</material>
    </gazebo>
    <transmission name="left_front_wheel_trans">
        <type>transmission_interface/SimpleTransmission</type>
        <actuator name="left_front_wheel_motor">
            <hardwareInterface>hardware_interface/EffortJointInterface</hardwareInterface>
            <mechanicalReduction>19.2032</mechanicalReduction>
        </actuator>
        <joint name="left_front_wheel_joint">
            <hardwareInterface>hardware_interface/EffortJointInterface</hardwareInterface>
        </joint>
    </transmission>
    <transmission name="right_front_wheel_trans">
        <type>transmission_interface/SimpleTransmission</type>
        <actuator name="right_front_wheel_motor">
            <hardwareInterface>hardware_interface/EffortJointInterface</hardwareInterface>
            <mechanicalReduction>-19.2032</mechanicalReduction>
        </actuator>
        <joint name="right_front_wheel_joint">
            <hardwareInterface>hardware_interface/EffortJointInterface</hardwareInterface>
        </joint>
    </transmission>
    <transmission name="left_back_wheel_trans">
        <type>transmission_interface/SimpleTransmission</type>
        <actuator name="left_back_wheel_motor">
            <hardwareInterface>hardware_interface/EffortJointInterface</hardwareInterface>
            <mechanicalReduction>19.2032</mechanicalReduction>
        </actuator>
        <joint name="left_back_wheel_joint">
            <hardwareInterface>hardware_interface/EffortJointInterface</hardwareInterface>
        </joint>
    </transmission>
    <transmission name="right_back_wheel_trans">
        <type>transmission_interface/SimpleTransmission</type>
        <actuator name="right_back_wheel_motor">
            <hardwareInterface>hardware_interface/EffortJointInterface</hardwareInterface>
            <mechanicalReduction>-19.2032</mechanicalReduction>
        </actuator>
        <joint name="right_back_wheel_joint">
            <hardwareInterface>hardware_interface/EffortJointInterface</hardwareInterface>
        </joint>
    </transmission>
    <link name="fpv_base_link">
        <inertial>
            <origin rpy="0 0 0" xyz="-0.00837197593310401 0.000140523225172551 0.260650515078393" />
            <mass value="0.318290775105411" />
            <inertia ixx="0.000973615562452728" ixy="9.93132176470742E-08" ixz="-1.69679963274217E-08" iyy="0.000982867792635814" iyz="-2.29555898593292E-07" izz="3.91535142867244E-05" />
        </inertial>
        <visual>
            <origin rpy="0 0 0" xyz="0 0 0" />
            <geometry>
                <mesh filename="package://sp_description/meshes/fpv_module/base_link.STL" />
            </geometry>
            <material name="">
                <color rgba="0.898039215686275 0.917647058823529 0.929411764705882 1" />
            </material>
        </visual>
        <collision>
            <origin rpy="0 0 0" xyz="-0.029 0.0 0.1213" />
            <geometry>
                <box size="0.025 0.025 0.27" />
            </geometry>
        </collision>
        <collision>
            <origin rpy="0 0 0" xyz="0.0085 0.01 0.2963" />
            <geometry>
                <box size="0.1 0.09 0.08" />
            </geometry>
        </collision>
    </link>
    <link name="mast">
        <inertial>
            <origin rpy="0 0 0" xyz="0.00716538024583485 -0.00264462585813141 0.223656429556577" />
            <mass value="0.434967907171886" />
            <inertia ixx="0.00352779149135138" ixy="-3.17747244925809E-06" ixz="-8.40259572495528E-08" iyy="0.00361813573645971" iyz="-5.8119648700945E-09" izz="0.000252286197843195" />
        </inertial>
        <visual>
            <origin rpy="0 0 0" xyz="0 0 0" />
            <geometry>
                <mesh filename="package://sp_description/meshes/fpv_module/mast.STL" />
            </geometry>
            <material name="">
                <color rgba="0.823529411764706 0.870588235294118 0.980392156862745 1" />
            </material>
        </visual>
        <collision>
            <origin rpy="0 0 0" xyz="0.003 0 0.1738" />
            <geometry>
                <box size="0.031 0.036 0.375" />
            </geometry>
        </collision>
        <collision>
            <origin rpy="0 0 0" xyz="0.038 -0.008 0.3813" />
            <geometry>
                <box size="0.2 0.12 0.06" />
            </geometry>
        </collision>
    </link>
    <joint name="mast_joint" type="prismatic">
        <origin rpy="0 0 0" xyz="0 0 0" />
        <parent link="fpv_base_link" />
        <child link="mast" />
        <!---->
        <axis xyz="0 0 1" />
        <limit effort="50" lower="0" upper="0.235" velocity="0.8" />
    </joint>
    <link name="fpv_yaw">
        <inertial>
            <origin rpy="0 0 0" xyz="-0.00916957696697959 0.0441061978242165 0.0183084882784505" />
            <mass value="0.0608808554843221" />
            <inertia ixx="9.04027463419959E-03" ixy="9.88988932831204E-05" ixz="4.51337209267773E-05" iyy="1.46381906705228E-02" iyz="3.26266079201928E-04" izz="1.94937658359286E-02" />
        </inertial>
        <visual>
            <origin rpy="0 0 0" xyz="0 0 0" />
            <geometry>
                <mesh filename="package://sp_description/meshes/fpv_module/fpv_yaw.STL" />
            </geometry>
            <material name="">
                <color rgba="0.498039215686275 0.498039215686275 0.498039215686275 1" />
            </material>
        </visual>
        <collision>
            <origin rpy="0 0 0" xyz="0.0012 0.023 0.0285" />
            <geometry>
                <box size="0.07 0.075 0.025" />
            </geometry>
        </collision>
    </link>
    <joint name="fpv_yaw_joint" type="revolute">
        <origin rpy="0 0 0" xyz="0 -0.0285 0.3853" />
        <parent link="mast" />
        <child link="fpv_yaw" />
        <axis xyz="0 0 1" />
        <limit effort="1.3" lower="-1.5708" upper="1.5708" velocity="6" />
    </joint>
    <link name="fpv_pitch">
        <inertial>
            <origin rpy="0 0 0" xyz="-0.0174476716824312 -0.0555089282604818 -4.05421645252591E-05" />
            <mass value="0.790822100365449" />
            <inertia ixx="0.000904458627478079" ixy="-1.04817358797102E-03" ixz="3.64987845692274E-04" iyy="0.00117560347818278" iyz="8.43541198126057E-05" izz="0.000928104839953432" />
        </inertial>
        <visual>
            <origin rpy="0 0 0" xyz="0 0 0" />
            <geometry>
                <mesh filename="package://sp_description/meshes/fpv_module/fpv_pitch.STL" />
            </geometry>
            <material name="">
                <color rgba="0.498039215686275 0.498039215686275 0.498039215686275 1" />
            </material>
        </visual>
        <collision>
            <origin rpy="0 0 0" xyz="0.005 -0.05 0" />
            <geometry>
                <box size="0.11 0.07 0.05" />
            </geometry>
        </collision>
    </link>
    <joint name="fpv_pitch_joint" type="revolute">
        <origin rpy="-1.5708 0 -3.1416" xyz="0 0.0007 0.0275" />
        <parent link="fpv_yaw" />
        <child link="fpv_pitch" />
        <axis xyz="0 0 1" />
        <limit effort="1.3" lower="-1.5708" upper="1.5708" velocity="6" />
    </joint>
    <!-- Create laser reference frame -->
    <link name="camera_link">
        <inertial>
            <mass value="0.1" />
            <origin xyz="0 0 0" />
            <inertia ixx="0.01" ixy="0.0" ixz="0.0" iyy="0.01" iyz="0.0" izz="0.01" />
        </inertial>
    </link>
    <gazebo reference="camera_link">
        <sensor name="camera_node" type="camera">
            <update_rate>30.0</update_rate>
            <camera name="head">
                <horizontal_fov>1.3962634</horizontal_fov>
                <image>
                    <width>1280</width>
                    <height>720</height>
                    <format>R8G8B8</format>
                </image>
                <clip>
                    <near>0.02</near>
                    <far>300</far>
                </clip>
                <noise>
                    <type>gaussian</type>
                    <mean>0.0</mean>
                    <stddev>0.007</stddev>
                </noise>
            </camera>
            <plugin filename="libgazebo_ros_camera.so" name="gazebo_camera">
                <alwaysOn>true</alwaysOn>
                <updateRate>0.0</updateRate>
                <cameraName>/camera</cameraName>
                <imageTopicName>image_raw</imageTopicName>
                <cameraInfoTopicName>camera_info</cameraInfoTopicName>
                <frameName>camera_link</frameName>
                <hackBaseline>0.07</hackBaseline>
                <distortionK1>0.0</distortionK1>
                <distortionK2>0.0</distortionK2>
                <distortionK3>0.0</distortionK3>
                <distortionT1>0.0</distortionT1>
                <distortionT2>0.0</distortionT2>
            </plugin>
        </sensor>
    </gazebo>
    <joint name="camera_joint" type="fixed">
        <origin rpy="-1.5707 0 3.1416" xyz="-0.05 -0.04 0" />
        <parent link="fpv_pitch" />
        <child link="camera_link" />
        <axis xyz="0 0 1" />
    </joint>
    <!--Transmission-->
    <transmission name="trans_mast_joint">
        <type>transmission_interface/SimpleTransmission</type>
        <actuator name="mast_joint_motor">
            <mechanicalReduction>1</mechanicalReduction>
            <hardwareInterface>hardware_interface/EffortJointInterface</hardwareInterface>
        </actuator>
        <joint name="mast_joint">
            <hardwareInterface>hardware_interface/PositionJointInterface</hardwareInterface>
        </joint>
    </transmission>
    <transmission name="trans_fpv_yaw_joint">
        <type>transmission_interface/SimpleTransmission</type>
        <actuator name="fpv_yaw_joint_motor">
            <mechanicalReduction>1</mechanicalReduction>
            <hardwareInterface>hardware_interface/EffortJointInterface</hardwareInterface>
        </actuator>
        <joint name="fpv_yaw_joint">
            <hardwareInterface>hardware_interface/PositionJointInterface</hardwareInterface>
        </joint>
    </transmission>
    <transmission name="trans_fpv_pitch_joint">
        <type>transmission_interface/SimpleTransmission</type>
        <actuator name="fpv_pitch_joint_motor">
            <mechanicalReduction>1</mechanicalReduction>
            <hardwareInterface>hardware_interface/EffortJointInterface</hardwareInterface>
        </actuator>
        <joint name="fpv_pitch_joint">
            <hardwareInterface>hardware_interface/PositionJointInterface</hardwareInterface>
        </joint>
    </transmission>
    <link name="arm_base_link">
        <inertial>
            <origin rpy="0 0 0" xyz="-0.0518095743713841 -0.00026336608241872 0.00154016786617812" />
            <mass value="0.288208331551669" />
            <inertia ixx="0.000244031290955245" ixy="8.67714690500338E-09" ixz="-2.40360210663764E-08" iyy="0.000405348993289901" iyz="-4.31198411045797E-09" izz="0.000644301933435004" />
        </inertial>
        <visual>
            <origin rpy="0 0 0" xyz="0 0 0" />
            <geometry>
                <mesh filename="package://sp_description/meshes/engineer2_manipulator/baselink.STL" />
            </geometry>
            <material name="">
                <color rgba="0.333333333333333 0.333333333333333 0.333333333333333 1" />
            </material>
        </visual>
        <collision>
            <origin rpy="0 0 0" xyz="0 0 0" />
            <geometry>
                <mesh filename="package://sp_description/meshes/engineer2_manipulator/baselink.STL" />
            </geometry>
        </collision>
    </link>
    <link name="link1">
        <inertial>
            <origin rpy="0 0 0" xyz="-0.000374224071529143 0.0136841926250667 0.0310279395315023" />
            <mass value="0.378634616635792" />
            <inertia ixx="0.000399769050341828" ixy="-1.12279959742056E-07" ixz="7.4174975368788E-07" iyy="0.000605852920055866" iyz="-9.01688301312537E-07" izz="0.000409205953927844" />
        </inertial>
        <visual>
            <origin rpy="0 0 0" xyz="0 0 0" />
            <geometry>
                <mesh filename="package://sp_description/meshes/engineer2_manipulator/link1.STL" />
            </geometry>
            <material name="">
                <color rgba="0.333333333333333 0.333333333333333 0.333333333333333 1" />
            </material>
        </visual>
        <collision>
            <origin rpy="0 0 0" xyz="0 0 0" />
            <geometry>
                <mesh filename="package://sp_description/meshes/engineer2_manipulator/link1.STL" />
            </geometry>
        </collision>
    </link>
    <joint name="joint1" type="revolute">
        <origin rpy="0 0 0" xyz="0 0 0.024" />
        <parent link="arm_base_link" />
        <child link="link1" />
        <axis xyz="0 0 1" />
        <limit effort="20" lower="-3.14" upper="3.14" velocity="5" />
    </joint>
    <link name="link2">
        <inertial>
            <origin rpy="0 0 0" xyz="0.0664236740686057 0.000776109930885217 0.0223130383419596" />
            <mass value="0.992951364752065" />
            <inertia ixx="0.000867761598325693" ixy="-5.62561657469764E-06" ixz="-1.26329828147808E-07" iyy="0.00129570980259147" iyz="1.40832854585324E-06" izz="0.00161881028021324" />
        </inertial>
        <visual>
            <origin rpy="0 0 0" xyz="0 0 0" />
            <geometry>
                <mesh filename="package://sp_description/meshes/engineer2_manipulator/link2.STL" />
            </geometry>
            <material name="">
                <color rgba="0.898039215686275 0.917647058823529 0.929411764705882 1" />
            </material>
        </visual>
        <collision>
            <origin rpy="0 0 0" xyz="0 0 0" />
            <geometry>
                <mesh filename="package://sp_description/meshes/engineer2_manipulator/link2.STL" />
            </geometry>
        </collision>
    </link>
    <joint name="joint2" type="revolute">
        <origin rpy="1.5708 -1.5708 0" xyz="0 0.022 0.065" />
        <parent link="link1" />
        <child link="link2" />
        <axis xyz="0 0 -1" />
        <limit effort="20" lower="-1.57" upper="1.57" velocity="5" />
    </joint>
    <link name="link3">
        <inertial>
            <origin rpy="0 0 0" xyz="0.0529953233929685 -0.00087340330976007 -0.00332798770534426" />
            <mass value="1.29043542087694" />
            <inertia ixx="0.000660438768204008" ixy="-9.41385714382025E-07" ixz="-2.73606948597533E-05" iyy="0.000654878904373999" iyz="-7.84069267827581E-08" izz="0.000611429702633374" />
        </inertial>
        <visual>
            <origin rpy="0 0 0" xyz="0 0 0" />
            <geometry>
                <mesh filename="package://sp_description/meshes/engineer2_manipulator/link3.STL" />
            </geometry>
            <material name="">
                <color rgba="0.898039215686275 0.917647058823529 0.929411764705882 1" />
            </material>
        </visual>
        <collision>
            <origin rpy="0 0 0" xyz="0 0 0" />
            <geometry>
                <mesh filename="package://sp_description/meshes/engineer2_manipulator/link3.STL" />
            </geometry>
        </collision>
    </link>
    <joint name="joint3" type="revolute">
        <origin rpy="0 0 0.0114314489445579" xyz="0.199986932336027 0.00228624032540565 0" />
        <parent link="link2" />
        <child link="link3" />
        <axis xyz="0 0 -1" />
        <limit effort="20" lower="-1.57" upper="1.57" velocity="5" />
    </joint>
    <link name="swiping_card">
        <inertial>
            <origin rpy="0 0 0" xyz="-0.043679 3.1364E-15 0.0024775" />
            <mass value="0.12034" />
            <inertia ixx="0.00013212" ixy="6.8395E-06" ixz="-2.4208E-06" iyy="0.00035298" iyz="-4.3226E-06" izz="0.00048461" />
        </inertial>
        <visual>
            <origin rpy="0 0 0" xyz="0 0 0" />
            <geometry>
                <mesh filename="package://sp_description/meshes/engineer_chassis/swiping_card.STL" />
            </geometry>
        </visual>
        <collision>
            <origin rpy="0 0 0" xyz="0 0 0" />
            <geometry>
                <mesh filename="package://sp_description/meshes/engineer_chassis/swiping_card.STL" />
            </geometry>
        </collision>
    </link>
    <joint name="card_joint" type="prismatic">
        <origin rpy="0 0 0" xyz="0.235 0 -0.0155" />
        <parent link="base_link" />
        <child link="swiping_card" />
        <axis xyz="1 0 0" />
        <limit effort="80" lower="0" upper="0.2" velocity="2" />
    </joint>
    <transmission name="trans_card_joint">
        <type>transmission_interface/SimpleTransmission</type>
        <actuator name="card_joint_motor">
            <mechanicalReduction>49.97</mechanicalReduction>
            <hardwareInterface>hardware_interface/EffortJointInterface</hardwareInterface>
        </actuator>
        <joint name="card_joint">
            <hardwareInterface>hardware_interface/EffortJointInterface</hardwareInterface>
        </joint>
    </transmission>
    <!-- Lidar is fixed to the connected_to link -->
    <joint name="rplidar_front_joint" type="fixed">
        <origin rpy="0 0 0" xyz="0.22 0 0.165" />
        <parent link="base_link" />
        <child link="rplidar_front" />
    </joint>
    <!-- Lidar link -->
    <link name="rplidar_front">
        <inertial>
            <mass value="0.114" />
            <origin xyz="0 0 0" rpy="0 0 0" />
            <inertia ixx="0.001" ixy="0.0" ixz="0.0" iyy="0.001" iyz="0.0" izz="0.001" />
        </inertial>
        <visual>
            <origin rpy="0 0 3.14159" xyz="0 0 0.0" />
            <geometry>
                <mesh filename="package://sp_description/meshes/common/lds.stl" scale="0.001 0.001 0.001" />
            </geometry>
        </visual>
        <collision>
            <origin rpy="0 0 3.14159" xyz="0.015 0 -0.0065" />
            <geometry>
                <cylinder length="0.0315" radius="0.055" />
            </geometry>
        </collision>
    </link>
    <gazebo reference="rplidar_front">
        <material>Gazebo/FlatBlack</material>
        <sensor name="rplidar_front_sensor" type="ray">
            <pose>0 0 0 0 0 0</pose>
            <visualize>false</visualize>
            <update_rate>5</update_rate>
            <ray>
                <scan>
                    <horizontal>
                        <samples>360</samples>
                        <resolution>1</resolution>
                        <min_angle>-1.5707</min_angle>
                        <max_angle>1.5707</max_angle>
                    </horizontal>
                </scan>
                <range>
                    <min>0.1</min>
                    <max>8</max>
                    <resolution>0.015</resolution>
                </range>
                <noise>
                    <type>gaussian</type>
                    <mean>0.0</mean>
                    <stddev>0.01</stddev>
                </noise>
            </ray>
            <plugin filename="libgazebo_ros_laser.so" name="gazebo_rplidar_front_controller">
                <topicName>scan_rplidar_front</topicName>
                <frameName>rplidar_front</frameName>
            </plugin>
        </sensor>
    </gazebo>
    <!-- Lidar is fixed to the connected_to link -->
    <joint name="rplidar_back_joint" type="fixed">
        <origin rpy="0 0 3.14159" xyz="-0.22 0 0.165" />
        <parent link="base_link" />
        <child link="rplidar_back" />
    </joint>
    <!-- Lidar link -->
    <link name="rplidar_back">
        <inertial>
            <mass value="0.114" />
            <origin xyz="0 0 0" rpy="0 0 0" />
            <inertia ixx="0.001" ixy="0.0" ixz="0.0" iyy="0.001" iyz="0.0" izz="0.001" />
        </inertial>
        <visual>
            <origin rpy="0 0 3.14159" xyz="0 0 0.0" />
            <geometry>
                <mesh filename="package://sp_description/meshes/common/lds.stl" scale="0.001 0.001 0.001" />
            </geometry>
        </visual>
        <collision>
            <origin rpy="0 0 3.14159" xyz="0.015 0 -0.0065" />
            <geometry>
                <cylinder length="0.0315" radius="0.055" />
            </geometry>
        </collision>
    </link>
    <gazebo reference="rplidar_back">
        <material>Gazebo/FlatBlack</material>
        <sensor name="rplidar_back_sensor" type="ray">
            <pose>0 0 0 0 0 0</pose>
            <visualize>false</visualize>
            <update_rate>5</update_rate>
            <ray>
                <scan>
                    <horizontal>
                        <samples>360</samples>
                        <resolution>1</resolution>
                        <min_angle>-1.5707</min_angle>
                        <max_angle>1.5707</max_angle>
                    </horizontal>
                </scan>
                <range>
                    <min>0.1</min>
                    <max>8</max>
                    <resolution>0.015</resolution>
                </range>
                <noise>
                    <type>gaussian</type>
                    <mean>0.0</mean>
                    <stddev>0.01</stddev>
                </noise>
            </ray>
            <plugin filename="libgazebo_ros_laser.so" name="gazebo_rplidar_back_controller">
                <topicName>scan_rplidar_back</topicName>
                <frameName>rplidar_back</frameName>
            </plugin>
        </sensor>
    </gazebo>
    <joint name="joint_arm2body" type="fixed">
        <axis xyz="0 0 1" />
        <origin rpy="0 0 0" xyz="0.0445 0.197 0.237" />
        <parent link="base_link" />
        <child link="arm_base_link" />
    </joint>
    <joint name="joint_mast2body" type="fixed">
        <axis xyz="0 0 1" />
        <origin rpy="0 0 1.5707" xyz="-0.2295 -0.0815 0.0157" />
        <parent link="base_link" />
        <child link="fpv_base_link" />
    </joint>
    <gazebo>
        <plugin filename="libgazebo_ros_control.so" name="gazebo_ros_control">
            <robotNamespace>/</robotNamespace>
        </plugin>
        <plugin filename="libchassis_controller.so" name="chassis_controller">
            <robotNamespace>/</robotNamespace>
        </plugin>
        <plugin filename="libgimbal_controller.so" name="gimbal_controller">
            <robotNamespace>/</robotNamespace>
        </plugin>
    </gazebo>
    <transmission name="trans_left_front_roller_0_joint">
        <type>transmission_interface/SimpleTransmission</type>
        <joint name="left_front_roller_0_joint">
            <hardwareInterface>hardware_interface/EffortJointInterface</hardwareInterface>
        </joint>
        <actuator name="left_front_roller_0_joint_motor">
            <hardwareInterface>hardware_interface/EffortJointInterface</hardwareInterface>
            <mechanicalReduction>1</mechanicalReduction>
        </actuator>
    </transmission>
    <transmission name="trans_left_front_roller_1_joint">
        <type>transmission_interface/SimpleTransmission</type>
        <joint name="left_front_roller_1_joint">
            <hardwareInterface>hardware_interface/EffortJointInterface</hardwareInterface>
        </joint>
        <actuator name="left_front_roller_1_joint_motor">
            <hardwareInterface>hardware_interface/EffortJointInterface</hardwareInterface>
            <mechanicalReduction>1</mechanicalReduction>
        </actuator>
    </transmission>
    <transmission name="trans_left_front_roller_2_joint">
        <type>transmission_interface/SimpleTransmission</type>
        <joint name="left_front_roller_2_joint">
            <hardwareInterface>hardware_interface/EffortJointInterface</hardwareInterface>
        </joint>
        <actuator name="left_front_roller_2_joint_motor">
            <hardwareInterface>hardware_interface/EffortJointInterface</hardwareInterface>
            <mechanicalReduction>1</mechanicalReduction>
        </actuator>
    </transmission>
    <transmission name="trans_left_front_roller_3_joint">
        <type>transmission_interface/SimpleTransmission</type>
        <joint name="left_front_roller_3_joint">
            <hardwareInterface>hardware_interface/EffortJointInterface</hardwareInterface>
        </joint>
        <actuator name="left_front_roller_3_joint_motor">
            <hardwareInterface>hardware_interface/EffortJointInterface</hardwareInterface>
            <mechanicalReduction>1</mechanicalReduction>
        </actuator>
    </transmission>
    <transmission name="trans_left_front_roller_4_joint">
        <type>transmission_interface/SimpleTransmission</type>
        <joint name="left_front_roller_4_joint">
            <hardwareInterface>hardware_interface/EffortJointInterface</hardwareInterface>
        </joint>
        <actuator name="left_front_roller_4_joint_motor">
            <hardwareInterface>hardware_interface/EffortJointInterface</hardwareInterface>
            <mechanicalReduction>1</mechanicalReduction>
        </actuator>
    </transmission>
    <transmission name="trans_left_front_roller_5_joint">
        <type>transmission_interface/SimpleTransmission</type>
        <joint name="left_front_roller_5_joint">
            <hardwareInterface>hardware_interface/EffortJointInterface</hardwareInterface>
        </joint>
        <actuator name="left_front_roller_5_joint_motor">
            <hardwareInterface>hardware_interface/EffortJointInterface</hardwareInterface>
            <mechanicalReduction>1</mechanicalReduction>
        </actuator>
    </transmission>
    <transmission name="trans_left_front_roller_6_joint">
        <type>transmission_interface/SimpleTransmission</type>
        <joint name="left_front_roller_6_joint">
            <hardwareInterface>hardware_interface/EffortJointInterface</hardwareInterface>
        </joint>
        <actuator name="left_front_roller_6_joint_motor">
            <hardwareInterface>hardware_interface/EffortJointInterface</hardwareInterface>
            <mechanicalReduction>1</mechanicalReduction>
        </actuator>
    </transmission>
    <transmission name="trans_left_front_roller_7_joint">
        <type>transmission_interface/SimpleTransmission</type>
        <joint name="left_front_roller_7_joint">
            <hardwareInterface>hardware_interface/EffortJointInterface</hardwareInterface>
        </joint>
        <actuator name="left_front_roller_7_joint_motor">
            <hardwareInterface>hardware_interface/EffortJointInterface</hardwareInterface>
            <mechanicalReduction>1</mechanicalReduction>
        </actuator>
    </transmission>
    <transmission name="trans_left_front_roller_8_joint">
        <type>transmission_interface/SimpleTransmission</type>
        <joint name="left_front_roller_8_joint">
            <hardwareInterface>hardware_interface/EffortJointInterface</hardwareInterface>
        </joint>
        <actuator name="left_front_roller_8_joint_motor">
            <hardwareInterface>hardware_interface/EffortJointInterface</hardwareInterface>
            <mechanicalReduction>1</mechanicalReduction>
        </actuator>
    </transmission>
    <transmission name="trans_left_front_roller_9_joint">
        <type>transmission_interface/SimpleTransmission</type>
        <joint name="left_front_roller_9_joint">
            <hardwareInterface>hardware_interface/EffortJointInterface</hardwareInterface>
        </joint>
        <actuator name="left_front_roller_9_joint_motor">
            <hardwareInterface>hardware_interface/EffortJointInterface</hardwareInterface>
            <mechanicalReduction>1</mechanicalReduction>
        </actuator>
    </transmission>
    <transmission name="trans_left_front_roller_10_joint">
        <type>transmission_interface/SimpleTransmission</type>
        <joint name="left_front_roller_10_joint">
            <hardwareInterface>hardware_interface/EffortJointInterface</hardwareInterface>
        </joint>
        <actuator name="left_front_roller_10_joint_motor">
            <hardwareInterface>hardware_interface/EffortJointInterface</hardwareInterface>
            <mechanicalReduction>1</mechanicalReduction>
        </actuator>
    </transmission>
    <transmission name="trans_left_front_roller_11_joint">
        <type>transmission_interface/SimpleTransmission</type>
        <joint name="left_front_roller_11_joint">
            <hardwareInterface>hardware_interface/EffortJointInterface</hardwareInterface>
        </joint>
        <actuator name="left_front_roller_11_joint_motor">
            <hardwareInterface>hardware_interface/EffortJointInterface</hardwareInterface>
            <mechanicalReduction>1</mechanicalReduction>
        </actuator>
    </transmission>
    <transmission name="trans_left_front_roller_12_joint">
        <type>transmission_interface/SimpleTransmission</type>
        <joint name="left_front_roller_12_joint">
            <hardwareInterface>hardware_interface/EffortJointInterface</hardwareInterface>
        </joint>
        <actuator name="left_front_roller_12_joint_motor">
            <hardwareInterface>hardware_interface/EffortJointInterface</hardwareInterface>
            <mechanicalReduction>1</mechanicalReduction>
        </actuator>
    </transmission>
    <transmission name="trans_left_front_roller_13_joint">
        <type>transmission_interface/SimpleTransmission</type>
        <joint name="left_front_roller_13_joint">
            <hardwareInterface>hardware_interface/EffortJointInterface</hardwareInterface>
        </joint>
        <actuator name="left_front_roller_13_joint_motor">
            <hardwareInterface>hardware_interface/EffortJointInterface</hardwareInterface>
            <mechanicalReduction>1</mechanicalReduction>
        </actuator>
    </transmission>
    <transmission name="trans_left_front_roller_14_joint">
        <type>transmission_interface/SimpleTransmission</type>
        <joint name="left_front_roller_14_joint">
            <hardwareInterface>hardware_interface/EffortJointInterface</hardwareInterface>
        </joint>
        <actuator name="left_front_roller_14_joint_motor">
            <hardwareInterface>hardware_interface/EffortJointInterface</hardwareInterface>
            <mechanicalReduction>1</mechanicalReduction>
        </actuator>
    </transmission>
    <transmission name="trans_left_front_roller_15_joint">
        <type>transmission_interface/SimpleTransmission</type>
        <joint name="left_front_roller_15_joint">
            <hardwareInterface>hardware_interface/EffortJointInterface</hardwareInterface>
        </joint>
        <actuator name="left_front_roller_15_joint_motor">
            <hardwareInterface>hardware_interface/EffortJointInterface</hardwareInterface>
            <mechanicalReduction>1</mechanicalReduction>
        </actuator>
    </transmission>
    <transmission name="trans_right_front_roller_0_joint">
        <type>transmission_interface/SimpleTransmission</type>
        <joint name="right_front_roller_0_joint">
            <hardwareInterface>hardware_interface/EffortJointInterface</hardwareInterface>
        </joint>
        <actuator name="right_front_roller_0_joint_motor">
            <hardwareInterface>hardware_interface/EffortJointInterface</hardwareInterface>
            <mechanicalReduction>1</mechanicalReduction>
        </actuator>
    </transmission>
    <transmission name="trans_right_front_roller_1_joint">
        <type>transmission_interface/SimpleTransmission</type>
        <joint name="right_front_roller_1_joint">
            <hardwareInterface>hardware_interface/EffortJointInterface</hardwareInterface>
        </joint>
        <actuator name="right_front_roller_1_joint_motor">
            <hardwareInterface>hardware_interface/EffortJointInterface</hardwareInterface>
            <mechanicalReduction>1</mechanicalReduction>
        </actuator>
    </transmission>
    <transmission name="trans_right_front_roller_2_joint">
        <type>transmission_interface/SimpleTransmission</type>
        <joint name="right_front_roller_2_joint">
            <hardwareInterface>hardware_interface/EffortJointInterface</hardwareInterface>
        </joint>
        <actuator name="right_front_roller_2_joint_motor">
            <hardwareInterface>hardware_interface/EffortJointInterface</hardwareInterface>
            <mechanicalReduction>1</mechanicalReduction>
        </actuator>
    </transmission>
    <transmission name="trans_right_front_roller_3_joint">
        <type>transmission_interface/SimpleTransmission</type>
        <joint name="right_front_roller_3_joint">
            <hardwareInterface>hardware_interface/EffortJointInterface</hardwareInterface>
        </joint>
        <actuator name="right_front_roller_3_joint_motor">
            <hardwareInterface>hardware_interface/EffortJointInterface</hardwareInterface>
            <mechanicalReduction>1</mechanicalReduction>
        </actuator>
    </transmission>
    <transmission name="trans_right_front_roller_4_joint">
        <type>transmission_interface/SimpleTransmission</type>
        <joint name="right_front_roller_4_joint">
            <hardwareInterface>hardware_interface/EffortJointInterface</hardwareInterface>
        </joint>
        <actuator name="right_front_roller_4_joint_motor">
            <hardwareInterface>hardware_interface/EffortJointInterface</hardwareInterface>
            <mechanicalReduction>1</mechanicalReduction>
        </actuator>
    </transmission>
    <transmission name="trans_right_front_roller_5_joint">
        <type>transmission_interface/SimpleTransmission</type>
        <joint name="right_front_roller_5_joint">
            <hardwareInterface>hardware_interface/EffortJointInterface</hardwareInterface>
        </joint>
        <actuator name="right_front_roller_5_joint_motor">
            <hardwareInterface>hardware_interface/EffortJointInterface</hardwareInterface>
            <mechanicalReduction>1</mechanicalReduction>
        </actuator>
    </transmission>
    <transmission name="trans_right_front_roller_6_joint">
        <type>transmission_interface/SimpleTransmission</type>
        <joint name="right_front_roller_6_joint">
            <hardwareInterface>hardware_interface/EffortJointInterface</hardwareInterface>
        </joint>
        <actuator name="right_front_roller_6_joint_motor">
            <hardwareInterface>hardware_interface/EffortJointInterface</hardwareInterface>
            <mechanicalReduction>1</mechanicalReduction>
        </actuator>
    </transmission>
    <transmission name="trans_right_front_roller_7_joint">
        <type>transmission_interface/SimpleTransmission</type>
        <joint name="right_front_roller_7_joint">
            <hardwareInterface>hardware_interface/EffortJointInterface</hardwareInterface>
        </joint>
        <actuator name="right_front_roller_7_joint_motor">
            <hardwareInterface>hardware_interface/EffortJointInterface</hardwareInterface>
            <mechanicalReduction>1</mechanicalReduction>
        </actuator>
    </transmission>
    <transmission name="trans_right_front_roller_8_joint">
        <type>transmission_interface/SimpleTransmission</type>
        <joint name="right_front_roller_8_joint">
            <hardwareInterface>hardware_interface/EffortJointInterface</hardwareInterface>
        </joint>
        <actuator name="right_front_roller_8_joint_motor">
            <hardwareInterface>hardware_interface/EffortJointInterface</hardwareInterface>
            <mechanicalReduction>1</mechanicalReduction>
        </actuator>
    </transmission>
    <transmission name="trans_right_front_roller_9_joint">
        <type>transmission_interface/SimpleTransmission</type>
        <joint name="right_front_roller_9_joint">
            <hardwareInterface>hardware_interface/EffortJointInterface</hardwareInterface>
        </joint>
        <actuator name="right_front_roller_9_joint_motor">
            <hardwareInterface>hardware_interface/EffortJointInterface</hardwareInterface>
            <mechanicalReduction>1</mechanicalReduction>
        </actuator>
    </transmission>
    <transmission name="trans_right_front_roller_10_joint">
        <type>transmission_interface/SimpleTransmission</type>
        <joint name="right_front_roller_10_joint">
            <hardwareInterface>hardware_interface/EffortJointInterface</hardwareInterface>
        </joint>
        <actuator name="right_front_roller_10_joint_motor">
            <hardwareInterface>hardware_interface/EffortJointInterface</hardwareInterface>
            <mechanicalReduction>1</mechanicalReduction>
        </actuator>
    </transmission>
    <transmission name="trans_right_front_roller_11_joint">
        <type>transmission_interface/SimpleTransmission</type>
        <joint name="right_front_roller_11_joint">
            <hardwareInterface>hardware_interface/EffortJointInterface</hardwareInterface>
        </joint>
        <actuator name="right_front_roller_11_joint_motor">
            <hardwareInterface>hardware_interface/EffortJointInterface</hardwareInterface>
            <mechanicalReduction>1</mechanicalReduction>
        </actuator>
    </transmission>
    <transmission name="trans_right_front_roller_12_joint">
        <type>transmission_interface/SimpleTransmission</type>
        <joint name="right_front_roller_12_joint">
            <hardwareInterface>hardware_interface/EffortJointInterface</hardwareInterface>
        </joint>
        <actuator name="right_front_roller_12_joint_motor">
            <hardwareInterface>hardware_interface/EffortJointInterface</hardwareInterface>
            <mechanicalReduction>1</mechanicalReduction>
        </actuator>
    </transmission>
    <transmission name="trans_right_front_roller_13_joint">
        <type>transmission_interface/SimpleTransmission</type>
        <joint name="right_front_roller_13_joint">
            <hardwareInterface>hardware_interface/EffortJointInterface</hardwareInterface>
        </joint>
        <actuator name="right_front_roller_13_joint_motor">
            <hardwareInterface>hardware_interface/EffortJointInterface</hardwareInterface>
            <mechanicalReduction>1</mechanicalReduction>
        </actuator>
    </transmission>
    <transmission name="trans_right_front_roller_14_joint">
        <type>transmission_interface/SimpleTransmission</type>
        <joint name="right_front_roller_14_joint">
            <hardwareInterface>hardware_interface/EffortJointInterface</hardwareInterface>
        </joint>
        <actuator name="right_front_roller_14_joint_motor">
            <hardwareInterface>hardware_interface/EffortJointInterface</hardwareInterface>
            <mechanicalReduction>1</mechanicalReduction>
        </actuator>
    </transmission>
    <transmission name="trans_right_front_roller_15_joint">
        <type>transmission_interface/SimpleTransmission</type>
        <joint name="right_front_roller_15_joint">
            <hardwareInterface>hardware_interface/EffortJointInterface</hardwareInterface>
        </joint>
        <actuator name="right_front_roller_15_joint_motor">
            <hardwareInterface>hardware_interface/EffortJointInterface</hardwareInterface>
            <mechanicalReduction>1</mechanicalReduction>
        </actuator>
    </transmission>
    <transmission name="trans_left_back_roller_0_joint">
        <type>transmission_interface/SimpleTransmission</type>
        <joint name="left_back_roller_0_joint">
            <hardwareInterface>hardware_interface/EffortJointInterface</hardwareInterface>
        </joint>
        <actuator name="left_back_roller_0_joint_motor">
            <hardwareInterface>hardware_interface/EffortJointInterface</hardwareInterface>
            <mechanicalReduction>1</mechanicalReduction>
        </actuator>
    </transmission>
    <transmission name="trans_left_back_roller_1_joint">
        <type>transmission_interface/SimpleTransmission</type>
        <joint name="left_back_roller_1_joint">
            <hardwareInterface>hardware_interface/EffortJointInterface</hardwareInterface>
        </joint>
        <actuator name="left_back_roller_1_joint_motor">
            <hardwareInterface>hardware_interface/EffortJointInterface</hardwareInterface>
            <mechanicalReduction>1</mechanicalReduction>
        </actuator>
    </transmission>
    <transmission name="trans_left_back_roller_2_joint">
        <type>transmission_interface/SimpleTransmission</type>
        <joint name="left_back_roller_2_joint">
            <hardwareInterface>hardware_interface/EffortJointInterface</hardwareInterface>
        </joint>
        <actuator name="left_back_roller_2_joint_motor">
            <hardwareInterface>hardware_interface/EffortJointInterface</hardwareInterface>
            <mechanicalReduction>1</mechanicalReduction>
        </actuator>
    </transmission>
    <transmission name="trans_left_back_roller_3_joint">
        <type>transmission_interface/SimpleTransmission</type>
        <joint name="left_back_roller_3_joint">
            <hardwareInterface>hardware_interface/EffortJointInterface</hardwareInterface>
        </joint>
        <actuator name="left_back_roller_3_joint_motor">
            <hardwareInterface>hardware_interface/EffortJointInterface</hardwareInterface>
            <mechanicalReduction>1</mechanicalReduction>
        </actuator>
    </transmission>
    <transmission name="trans_left_back_roller_4_joint">
        <type>transmission_interface/SimpleTransmission</type>
        <joint name="left_back_roller_4_joint">
            <hardwareInterface>hardware_interface/EffortJointInterface</hardwareInterface>
        </joint>
        <actuator name="left_back_roller_4_joint_motor">
            <hardwareInterface>hardware_interface/EffortJointInterface</hardwareInterface>
            <mechanicalReduction>1</mechanicalReduction>
        </actuator>
    </transmission>
    <transmission name="trans_left_back_roller_5_joint">
        <type>transmission_interface/SimpleTransmission</type>
        <joint name="left_back_roller_5_joint">
            <hardwareInterface>hardware_interface/EffortJointInterface</hardwareInterface>
        </joint>
        <actuator name="left_back_roller_5_joint_motor">
            <hardwareInterface>hardware_interface/EffortJointInterface</hardwareInterface>
            <mechanicalReduction>1</mechanicalReduction>
        </actuator>
    </transmission>
    <transmission name="trans_left_back_roller_6_joint">
        <type>transmission_interface/SimpleTransmission</type>
        <joint name="left_back_roller_6_joint">
            <hardwareInterface>hardware_interface/EffortJointInterface</hardwareInterface>
        </joint>
        <actuator name="left_back_roller_6_joint_motor">
            <hardwareInterface>hardware_interface/EffortJointInterface</hardwareInterface>
            <mechanicalReduction>1</mechanicalReduction>
        </actuator>
    </transmission>
    <transmission name="trans_left_back_roller_7_joint">
        <type>transmission_interface/SimpleTransmission</type>
        <joint name="left_back_roller_7_joint">
            <hardwareInterface>hardware_interface/EffortJointInterface</hardwareInterface>
        </joint>
        <actuator name="left_back_roller_7_joint_motor">
            <hardwareInterface>hardware_interface/EffortJointInterface</hardwareInterface>
            <mechanicalReduction>1</mechanicalReduction>
        </actuator>
    </transmission>
    <transmission name="trans_left_back_roller_8_joint">
        <type>transmission_interface/SimpleTransmission</type>
        <joint name="left_back_roller_8_joint">
            <hardwareInterface>hardware_interface/EffortJointInterface</hardwareInterface>
        </joint>
        <actuator name="left_back_roller_8_joint_motor">
            <hardwareInterface>hardware_interface/EffortJointInterface</hardwareInterface>
            <mechanicalReduction>1</mechanicalReduction>
        </actuator>
    </transmission>
    <transmission name="trans_left_back_roller_9_joint">
        <type>transmission_interface/SimpleTransmission</type>
        <joint name="left_back_roller_9_joint">
            <hardwareInterface>hardware_interface/EffortJointInterface</hardwareInterface>
        </joint>
        <actuator name="left_back_roller_9_joint_motor">
            <hardwareInterface>hardware_interface/EffortJointInterface</hardwareInterface>
            <mechanicalReduction>1</mechanicalReduction>
        </actuator>
    </transmission>
    <transmission name="trans_left_back_roller_10_joint">
        <type>transmission_interface/SimpleTransmission</type>
        <joint name="left_back_roller_10_joint">
            <hardwareInterface>hardware_interface/EffortJointInterface</hardwareInterface>
        </joint>
        <actuator name="left_back_roller_10_joint_motor">
            <hardwareInterface>hardware_interface/EffortJointInterface</hardwareInterface>
            <mechanicalReduction>1</mechanicalReduction>
        </actuator>
    </transmission>
    <transmission name="trans_left_back_roller_11_joint">
        <type>transmission_interface/SimpleTransmission</type>
        <joint name="left_back_roller_11_joint">
            <hardwareInterface>hardware_interface/EffortJointInterface</hardwareInterface>
        </joint>
        <actuator name="left_back_roller_11_joint_motor">
            <hardwareInterface>hardware_interface/EffortJointInterface</hardwareInterface>
            <mechanicalReduction>1</mechanicalReduction>
        </actuator>
    </transmission>
    <transmission name="trans_left_back_roller_12_joint">
        <type>transmission_interface/SimpleTransmission</type>
        <joint name="left_back_roller_12_joint">
            <hardwareInterface>hardware_interface/EffortJointInterface</hardwareInterface>
        </joint>
        <actuator name="left_back_roller_12_joint_motor">
            <hardwareInterface>hardware_interface/EffortJointInterface</hardwareInterface>
            <mechanicalReduction>1</mechanicalReduction>
        </actuator>
    </transmission>
    <transmission name="trans_left_back_roller_13_joint">
        <type>transmission_interface/SimpleTransmission</type>
        <joint name="left_back_roller_13_joint">
            <hardwareInterface>hardware_interface/EffortJointInterface</hardwareInterface>
        </joint>
        <actuator name="left_back_roller_13_joint_motor">
            <hardwareInterface>hardware_interface/EffortJointInterface</hardwareInterface>
            <mechanicalReduction>1</mechanicalReduction>
        </actuator>
    </transmission>
    <transmission name="trans_left_back_roller_14_joint">
        <type>transmission_interface/SimpleTransmission</type>
        <joint name="left_back_roller_14_joint">
            <hardwareInterface>hardware_interface/EffortJointInterface</hardwareInterface>
        </joint>
        <actuator name="left_back_roller_14_joint_motor">
            <hardwareInterface>hardware_interface/EffortJointInterface</hardwareInterface>
            <mechanicalReduction>1</mechanicalReduction>
        </actuator>
    </transmission>
    <transmission name="trans_left_back_roller_15_joint">
        <type>transmission_interface/SimpleTransmission</type>
        <joint name="left_back_roller_15_joint">
            <hardwareInterface>hardware_interface/EffortJointInterface</hardwareInterface>
        </joint>
        <actuator name="left_back_roller_15_joint_motor">
            <hardwareInterface>hardware_interface/EffortJointInterface</hardwareInterface>
            <mechanicalReduction>1</mechanicalReduction>
        </actuator>
    </transmission>
    <transmission name="trans_right_back_roller_0_joint">
        <type>transmission_interface/SimpleTransmission</type>
        <joint name="right_back_roller_0_joint">
            <hardwareInterface>hardware_interface/EffortJointInterface</hardwareInterface>
        </joint>
        <actuator name="right_back_roller_0_joint_motor">
            <hardwareInterface>hardware_interface/EffortJointInterface</hardwareInterface>
            <mechanicalReduction>1</mechanicalReduction>
        </actuator>
    </transmission>
    <transmission name="trans_right_back_roller_1_joint">
        <type>transmission_interface/SimpleTransmission</type>
        <joint name="right_back_roller_1_joint">
            <hardwareInterface>hardware_interface/EffortJointInterface</hardwareInterface>
        </joint>
        <actuator name="right_back_roller_1_joint_motor">
            <hardwareInterface>hardware_interface/EffortJointInterface</hardwareInterface>
            <mechanicalReduction>1</mechanicalReduction>
        </actuator>
    </transmission>
    <transmission name="trans_right_back_roller_2_joint">
        <type>transmission_interface/SimpleTransmission</type>
        <joint name="right_back_roller_2_joint">
            <hardwareInterface>hardware_interface/EffortJointInterface</hardwareInterface>
        </joint>
        <actuator name="right_back_roller_2_joint_motor">
            <hardwareInterface>hardware_interface/EffortJointInterface</hardwareInterface>
            <mechanicalReduction>1</mechanicalReduction>
        </actuator>
    </transmission>
    <transmission name="trans_right_back_roller_3_joint">
        <type>transmission_interface/SimpleTransmission</type>
        <joint name="right_back_roller_3_joint">
            <hardwareInterface>hardware_interface/EffortJointInterface</hardwareInterface>
        </joint>
        <actuator name="right_back_roller_3_joint_motor">
            <hardwareInterface>hardware_interface/EffortJointInterface</hardwareInterface>
            <mechanicalReduction>1</mechanicalReduction>
        </actuator>
    </transmission>
    <transmission name="trans_right_back_roller_4_joint">
        <type>transmission_interface/SimpleTransmission</type>
        <joint name="right_back_roller_4_joint">
            <hardwareInterface>hardware_interface/EffortJointInterface</hardwareInterface>
        </joint>
        <actuator name="right_back_roller_4_joint_motor">
            <hardwareInterface>hardware_interface/EffortJointInterface</hardwareInterface>
            <mechanicalReduction>1</mechanicalReduction>
        </actuator>
    </transmission>
    <transmission name="trans_right_back_roller_5_joint">
        <type>transmission_interface/SimpleTransmission</type>
        <joint name="right_back_roller_5_joint">
            <hardwareInterface>hardware_interface/EffortJointInterface</hardwareInterface>
        </joint>
        <actuator name="right_back_roller_5_joint_motor">
            <hardwareInterface>hardware_interface/EffortJointInterface</hardwareInterface>
            <mechanicalReduction>1</mechanicalReduction>
        </actuator>
    </transmission>
    <transmission name="trans_right_back_roller_6_joint">
        <type>transmission_interface/SimpleTransmission</type>
        <joint name="right_back_roller_6_joint">
            <hardwareInterface>hardware_interface/EffortJointInterface</hardwareInterface>
        </joint>
        <actuator name="right_back_roller_6_joint_motor">
            <hardwareInterface>hardware_interface/EffortJointInterface</hardwareInterface>
            <mechanicalReduction>1</mechanicalReduction>
        </actuator>
    </transmission>
    <transmission name="trans_right_back_roller_7_joint">
        <type>transmission_interface/SimpleTransmission</type>
        <joint name="right_back_roller_7_joint">
            <hardwareInterface>hardware_interface/EffortJointInterface</hardwareInterface>
        </joint>
        <actuator name="right_back_roller_7_joint_motor">
            <hardwareInterface>hardware_interface/EffortJointInterface</hardwareInterface>
            <mechanicalReduction>1</mechanicalReduction>
        </actuator>
    </transmission>
    <transmission name="trans_right_back_roller_8_joint">
        <type>transmission_interface/SimpleTransmission</type>
        <joint name="right_back_roller_8_joint">
            <hardwareInterface>hardware_interface/EffortJointInterface</hardwareInterface>
        </joint>
        <actuator name="right_back_roller_8_joint_motor">
            <hardwareInterface>hardware_interface/EffortJointInterface</hardwareInterface>
            <mechanicalReduction>1</mechanicalReduction>
        </actuator>
    </transmission>
    <transmission name="trans_right_back_roller_9_joint">
        <type>transmission_interface/SimpleTransmission</type>
        <joint name="right_back_roller_9_joint">
            <hardwareInterface>hardware_interface/EffortJointInterface</hardwareInterface>
        </joint>
        <actuator name="right_back_roller_9_joint_motor">
            <hardwareInterface>hardware_interface/EffortJointInterface</hardwareInterface>
            <mechanicalReduction>1</mechanicalReduction>
        </actuator>
    </transmission>
    <transmission name="trans_right_back_roller_10_joint">
        <type>transmission_interface/SimpleTransmission</type>
        <joint name="right_back_roller_10_joint">
            <hardwareInterface>hardware_interface/EffortJointInterface</hardwareInterface>
        </joint>
        <actuator name="right_back_roller_10_joint_motor">
            <hardwareInterface>hardware_interface/EffortJointInterface</hardwareInterface>
            <mechanicalReduction>1</mechanicalReduction>
        </actuator>
    </transmission>
    <transmission name="trans_right_back_roller_11_joint">
        <type>transmission_interface/SimpleTransmission</type>
        <joint name="right_back_roller_11_joint">
            <hardwareInterface>hardware_interface/EffortJointInterface</hardwareInterface>
        </joint>
        <actuator name="right_back_roller_11_joint_motor">
            <hardwareInterface>hardware_interface/EffortJointInterface</hardwareInterface>
            <mechanicalReduction>1</mechanicalReduction>
        </actuator>
    </transmission>
    <transmission name="trans_right_back_roller_12_joint">
        <type>transmission_interface/SimpleTransmission</type>
        <joint name="right_back_roller_12_joint">
            <hardwareInterface>hardware_interface/EffortJointInterface</hardwareInterface>
        </joint>
        <actuator name="right_back_roller_12_joint_motor">
            <hardwareInterface>hardware_interface/EffortJointInterface</hardwareInterface>
            <mechanicalReduction>1</mechanicalReduction>
        </actuator>
    </transmission>
    <transmission name="trans_right_back_roller_13_joint">
        <type>transmission_interface/SimpleTransmission</type>
        <joint name="right_back_roller_13_joint">
            <hardwareInterface>hardware_interface/EffortJointInterface</hardwareInterface>
        </joint>
        <actuator name="right_back_roller_13_joint_motor">
            <hardwareInterface>hardware_interface/EffortJointInterface</hardwareInterface>
            <mechanicalReduction>1</mechanicalReduction>
        </actuator>
    </transmission>
    <transmission name="trans_right_back_roller_14_joint">
        <type>transmission_interface/SimpleTransmission</type>
        <joint name="right_back_roller_14_joint">
            <hardwareInterface>hardware_interface/EffortJointInterface</hardwareInterface>
        </joint>
        <actuator name="right_back_roller_14_joint_motor">
            <hardwareInterface>hardware_interface/EffortJointInterface</hardwareInterface>
            <mechanicalReduction>1</mechanicalReduction>
        </actuator>
    </transmission>
    <transmission name="trans_right_back_roller_15_joint">
        <type>transmission_interface/SimpleTransmission</type>
        <joint name="right_back_roller_15_joint">
            <hardwareInterface>hardware_interface/EffortJointInterface</hardwareInterface>
        </joint>
        <actuator name="right_back_roller_15_joint_motor">
            <hardwareInterface>hardware_interface/EffortJointInterface</hardwareInterface>
            <mechanicalReduction>1</mechanicalReduction>
        </actuator>
    </transmission>
</robot>

