<?xml version="1.0" ?>
<!-- =================================================================================== -->
<!-- |    This document was autogenerated by xacro from /home/cherrynova/catkin_ws/src/sp_control/sp_description/urdf/engineer_framed/engineer.xacro | -->
<!-- |    EDITING THIS FILE BY HAND IS NOT RECOMMENDED                                 | -->
<!-- =================================================================================== -->
<robot name="engineer_framed">
    <transmission name="trans_joint1">
        <type>transmission_interface/SimpleTransmission</type>
        <actuator name="joint1_motor">
            <mechanicalReduction>1</mechanicalReduction>
            <hardwareInterface>hardware_interface/PositionJointInterface</hardwareInterface>
        </actuator>
        <joint name="joint1">
            <hardwareInterface>hardware_interface/PositionJointInterface</hardwareInterface>
        </joint>
    </transmission>
    <transmission name="trans_joint2">
        <type>transmission_interface/SimpleTransmission</type>
        <actuator name="joint2_motor">
            <mechanicalReduction>1</mechanicalReduction>
            <hardwareInterface>hardware_interface/PositionJointInterface</hardwareInterface>
        </actuator>
        <joint name="joint2">
            <hardwareInterface>hardware_interface/PositionJointInterface</hardwareInterface>
        </joint>
    </transmission>
    <transmission name="trans_joint3">
        <type>transmission_interface/SimpleTransmission</type>
        <actuator name="joint3_motor">
            <mechanicalReduction>1</mechanicalReduction>
            <hardwareInterface>hardware_interface/PositionJointInterface</hardwareInterface>
        </actuator>
        <joint name="joint3">
            <hardwareInterface>hardware_interface/PositionJointInterface</hardwareInterface>
        </joint>
    </transmission>
    <transmission name="trans_joint4">
        <type>transmission_interface/SimpleTransmission</type>
        <actuator name="joint4_motor">
            <mechanicalReduction>1</mechanicalReduction>
            <hardwareInterface>hardware_interface/PositionJointInterface</hardwareInterface>
        </actuator>
        <joint name="joint4">
            <hardwareInterface>hardware_interface/PositionJointInterface</hardwareInterface>
        </joint>
    </transmission>
    <transmission name="trans_joint5">
        <type>transmission_interface/SimpleTransmission</type>
        <actuator name="joint5_motor">
            <mechanicalReduction>1</mechanicalReduction>
            <hardwareInterface>hardware_interface/PositionJointInterface</hardwareInterface>
        </actuator>
        <joint name="joint5">
            <hardwareInterface>hardware_interface/PositionJointInterface</hardwareInterface>
        </joint>
    </transmission>
    <transmission name="trans_joint6">
        <type>transmission_interface/SimpleTransmission</type>
        <actuator name="joint6_motor">
            <mechanicalReduction>1</mechanicalReduction>
            <hardwareInterface>hardware_interface/PositionJointInterface</hardwareInterface>
        </actuator>
        <joint name="joint6">
            <hardwareInterface>hardware_interface/PositionJointInterface</hardwareInterface>
        </joint>
    </transmission>
    <transmission name="trans_joint7">
        <type>transmission_interface/SimpleTransmission</type>
        <actuator name="joint7_motor">
            <mechanicalReduction>1</mechanicalReduction>
            <hardwareInterface>hardware_interface/PositionJointInterface</hardwareInterface>
        </actuator>
        <joint name="joint7">
            <hardwareInterface>hardware_interface/PositionJointInterface</hardwareInterface>
        </joint>
    </transmission>
    <!--<gazebo>
        <plugin name="gazebo_ros_vacuum_gripper" filename="libgazebo_ros_vacuum_gripper.so">
            <robotNamespace>/vacuum_gripper</robotNamespace>
            <bodyName>vacuum_gripper</bodyName>
            <topicName>grasping</topicName>
            <maxForce>100</maxForce>
            <maxDistance>0.05</maxDistance>
            <minDistance>0.01</minDistance>
        </plugin>
    </gazebo>	
    <gazebo reference="vacuum_gripper">
        <mu1>50</mu1>
        <mu2>50</mu2>
　　　   <minDepth>0.003</minDepth>
        <maxVel>0</maxVel>
        <kp>10000000000000.0</kp>
        <kd>1.0</kd>
        <ki>2.0</ki>
        <material>Gazebo/Grey</material>
    </gazebo>-->
    <link name="arm_base_link">
        <inertial>
            <origin rpy="0 0 0" xyz="-0.02624 -0.018282 0.25067" />
            <mass value="3.4509" />
            <inertia ixx="0.030137" ixy="-1.2844E-07" ixz="-3.1208E-06" iyy="0.030724" iyz="3.4634E-08" izz="0.0009827" />
        </inertial>
        <visual>
            <origin rpy="0 0 0" xyz="0 0 0" />
            <geometry>
                <mesh filename="package://sp_description/meshes/engineer_framed/engineer_manipulator_framed/arm_base_link.STL" />
            </geometry>
            <material name="">
                <color rgba="1 1 1 1" />
            </material>
        </visual>
        <collision>
            <origin rpy="0 0 0" xyz="0 0 0" />
            <geometry>
                <mesh filename="package://sp_description/meshes/engineer_framed/engineer_manipulator_framed/arm_base_link.STL" />
            </geometry>
        </collision>
    </link>
    <link name="link1">
        <inertial>
            <origin rpy="0 0 0" xyz="-0.045505 -0.011017 0.39513" />
            <mass value="3.3312" />
            <inertia ixx="0.0042512" ixy="-2.4588E-07" ixz="4.24E-06" iyy="0.047095" iyz="-5.1472E-08" izz="0.050676" />
        </inertial>
        <visual>
            <origin rpy="0 0 0" xyz="0 0 0" />
            <geometry>
                <mesh filename="package://sp_description/meshes/engineer_framed/engineer_manipulator_framed/link1.STL" />
            </geometry>
            <material name="">
                <color rgba="0.79216 0.81961 0.93333 1" />
            </material>
        </visual>
        <collision>
            <origin rpy="0 0 0" xyz="0 0 0" />
            <geometry>
                <mesh filename="package://sp_description/meshes/engineer_framed/engineer_manipulator_framed/link1.STL" />
            </geometry>
        </collision>
    </link>
    <joint name="joint1" type="prismatic">
        <origin rpy="0 0 0" xyz="0 0 -0.15" />
        <parent link="arm_base_link" />
        <child link="link1" />
        <axis xyz="0 0 1" />
        <limit effort="20" lower="0" upper="0.15" velocity="5" />
    </joint>
    <link name="link2">
        <inertial>
            <origin rpy="0 0 0" xyz="0.73763 -0.012605 0.069937" />
            <mass value="3.3677" />
            <inertia ixx="0.00060317" ixy="-1.317E-07" ixz="-5.0363E-06" iyy="0.059389" iyz="2.5076E-07" izz="0.059509" />
        </inertial>
        <visual>
            <origin rpy="0 0 0" xyz="0 0 0" />
            <geometry>
                <mesh filename="package://sp_description/meshes/engineer_framed/engineer_manipulator_framed/link2.STL" />
            </geometry>
            <material name="">
                <color rgba="0.77647 0.75686 0.73725 1" />
            </material>
        </visual>
        <collision>
            <origin rpy="0 0 0" xyz="0 0 0" />
            <geometry>
                <mesh filename="package://sp_description/meshes/engineer_framed/engineer_manipulator_framed/link2.STL" />
            </geometry>
        </collision>
    </link>
    <joint name="joint2" type="prismatic">
        <origin rpy="0 0 0" xyz="-0.7 0 0.3831" />
        <parent link="link1" />
        <child link="link2" />
        <axis xyz="-1 0 0" />
        <limit effort="0" lower="0" upper="0.86634" velocity="0" />
    </joint>
    <link name="link3">
        <inertial>
            <origin rpy="0 0 0" xyz="0.51091 -0.0045583 0.038639" />
            <mass value="0.53167" />
            <inertia ixx="0.0064927" ixy="-6.4359E-05" ixz="6.2407E-09" iyy="0.00010061" iyz="1.8149E-08" izz="0.0065666" />
        </inertial>
        <visual>
            <origin rpy="0 0 0" xyz="0 0 0" />
            <geometry>
                <mesh filename="package://sp_description/meshes/engineer_framed/engineer_manipulator_framed/link3.STL" />
            </geometry>
            <material name="">
                <color rgba="0.79216 0.81961 0.93333 1" />
            </material>
        </visual>
        <collision>
            <origin rpy="0 0 0" xyz="0 0 0" />
            <geometry>
                <mesh filename="package://sp_description/meshes/engineer_framed/engineer_manipulator_framed/link3.STL" />
            </geometry>
        </collision>
    </link>
    <joint name="joint3" type="prismatic">
        <origin rpy="0 3.3989E-05 0.01003" xyz="0.42794 0 0.072" />
        <parent link="link2" />
        <child link="link3" />
        <axis xyz="-1 0 0" />
        <limit effort="0" lower="0" upper="0.4754" velocity="0" />
    </joint>
    <link name="link4">
        <inertial>
            <origin rpy="0 0 0" xyz="0.0022111 0.055845 0.11382" />
            <mass value="2.5793" />
            <inertia ixx="0.0074201" ixy="-1.1003E-06" ixz="-7.0108E-06" iyy="0.00083556" iyz="-7.3369E-07" izz="0.0075834" />
        </inertial>
        <visual>
            <origin rpy="0 0 0" xyz="0 0 0" />
            <geometry>
                <mesh filename="package://sp_description/meshes/engineer_framed/engineer_manipulator_framed/link4.STL" />
            </geometry>
            <material name="">
                <color rgba="0.77647 0.75686 0.73725 1" />
            </material>
        </visual>
        <collision>
            <origin rpy="0 0 0" xyz="0 0 0" />
            <geometry>
                <mesh filename="package://sp_description/meshes/engineer_framed/engineer_manipulator_framed/link4.STL" />
            </geometry>
        </collision>
    </link>
    <joint name="joint4" type="prismatic">
        <origin rpy="0 -3.3987E-05 -0.01003" xyz="0.50967 -0.005112 0.034017" />
        <parent link="link3" />
        <child link="link4" />
        <axis xyz="0 1 0" />
        <limit effort="0" lower="-0.3" upper="0.3" velocity="0" />
    </joint>
    <link name="link5">
        <inertial>
            <origin rpy="0 0 0" xyz="0.037013 0.0011704 -0.028178" />
            <mass value="0.32118" />
            <inertia ixx="0.00016392" ixy="-3.0539E-08" ixz="5.3231E-08" iyy="9.5535E-05" iyz="7.5431E-08" izz="0.00010732" />
        </inertial>
        <visual>
            <origin rpy="0 0 0" xyz="0 0 0" />
            <geometry>
                <mesh filename="package://sp_description/meshes/engineer_framed/engineer_manipulator_framed/link5.STL" />
            </geometry>
            <material name="">
                <color rgba="0.77647 0.75686 0.73725 1" />
            </material>
        </visual>
        <collision>
            <origin rpy="0 0 0" xyz="0 0 0" />
            <geometry>
                <mesh filename="package://sp_description/meshes/engineer_framed/engineer_manipulator_framed/link5.STL" />
            </geometry>
        </collision>
    </link>
    <joint name="joint5" type="revolute">
        <origin rpy="1.5708 0 0" xyz="0 -0.018 0.128" />
        <parent link="link4" />
        <child link="link5" />
        <axis xyz="0 0 1" />
        <limit effort="0" lower="0" upper="3.14" velocity="0" />
    </joint>
    <link name="link6">
        <inertial>
            <origin rpy="0 0 0" xyz="0.00062599 -0.14196 -0.013409" />
            <mass value="0.69733" />
            <inertia ixx="0.00029313" ixy="1.0445E-08" ixz="1.6605E-08" iyy="0.00028267" iyz="-4.8697E-06" izz="0.00025509" />
        </inertial>
        <visual>
            <origin rpy="0 0 0" xyz="0 0 0" />
            <geometry>
                <mesh filename="package://sp_description/meshes/engineer_framed/engineer_manipulator_framed/link6.STL" />
            </geometry>
            <material name="">
                <color rgba="0.77647 0.75686 0.73725 1" />
            </material>
        </visual>
        <collision>
            <origin rpy="0 0 0" xyz="0 0 0" />
            <geometry>
                <mesh filename="package://sp_description/meshes/engineer_framed/engineer_manipulator_framed/link6.STL" />
            </geometry>
        </collision>
    </link>
    <joint name="joint6" type="revolute">
        <origin rpy="1.5708 -1.5674 1.5708" xyz="0.07179 0 -0.028" />
        <parent link="link5" />
        <child link="link6" />
        <axis xyz="0 0 -1" />
        <limit effort="0" lower="-1.57" upper="1.57" velocity="0" />
    </joint>
    <link name="link7">
        <inertial>
            <origin rpy="0 0 0" xyz="1.0099E-06 -0.062072 0.050902" />
            <mass value="0.16243" />
            <inertia ixx="0.00010545" ixy="-3.0539E-08" ixz="1.4953E-08" iyy="5.3443E-05" iyz="-3.1729E-08" izz="0.00014942" />
        </inertial>
        <visual>
            <origin rpy="0 0 0" xyz="0 0 0" />
            <geometry>
                <mesh filename="package://sp_description/meshes/engineer_framed/engineer_manipulator_framed/link7.STL" />
            </geometry>
            <material name="">
                <color rgba="1 1 1 1" />
            </material>
        </visual>
        <collision>
            <origin rpy="0 0 0" xyz="0 0 0" />
            <geometry>
                <mesh filename="package://sp_description/meshes/engineer_framed/engineer_manipulator_framed/link7.STL" />
            </geometry>
        </collision>
    </link>
    <joint name="joint7" type="revolute">
        <origin rpy="1.5704 0 0.0033889" xyz="0.00059574 -0.17579 -0.07179" />
        <parent link="link6" />
        <child link="link7" />
        <axis xyz="0.033366 0 0.99944" />
        <limit effort="20" lower="-3.14" upper="3.14" velocity="5" />
    </joint>
    <link name="base_link">
        <inertial>
            <origin rpy="0 0 0" xyz="0.047614 -0.013852 0.13893" />
            <mass value="12.232" />
            <inertia ixx="0.039383" ixy="2.7131E-05" ixz="0.00010315" iyy="0.048017" iyz="0.00051335" izz="0.075914" />
        </inertial>
        <visual>
            <origin rpy="0 0 0" xyz="0 0 0" />
            <geometry>
                <mesh filename="package://sp_description/meshes/engineer_framed/engineer_chassis/base_link.STL" />
            </geometry>
            <material name="">
                <color rgba="0.75294 0.75294 0.75294 1" />
            </material>
        </visual>
        <collision>
            <origin rpy="0 0 0" xyz="0 0 0" />
            <geometry>
                <mesh filename="package://sp_description/meshes/engineer_framed/engineer_chassis/base_link.STL" />
            </geometry>
        </collision>
    </link>
    <!--  link  -->
    <link name="left_front_wheel">
        <visual>
            <geometry>
                <mesh filename="package://sp_description/meshes/common/mecanum_wheel/right_mecanum_wheel.STL" />
            </geometry>
        </visual>
        <inertial>
            <mass value="0.4235" />
            <inertia ixx="4.122e-4" ixy="0.0" ixz="0.0" iyy="7.398e-4" iyz="0.0" izz="4.122e-4" />
        </inertial>
    </link>
    <!--  joint  -->
    <joint name="left_front_wheel_joint" type="revolute">
        <axis xyz="0 1 0" />
        <origin rpy="0 0 0" xyz="0.19185 0.221 0.077" />
        <!--      limit not work while type="continuous"-->
        <limit effort="10" lower="-1e9" upper="1e9" velocity="70" />
        <dynamics damping="0.0" friction="0.05" />
        <parent link="base_link" />
        <child link="left_front_wheel" />
    </joint>
    <!--  link  -->
    <link name="left_front_roller_0">
        <collision>
            <geometry>
                <sphere radius="0.009" />
            </geometry>
        </collision>
        <inertial>
            <mass value="0.036" />
            <inertia ixx="3128e-9" ixy="0.0" ixz="0.0" iyy="3128e-9" iyz="0.0" izz="3128e-9" />
            <origin xyz="0 0 0" rpy="0 0 0" />
        </inertial>
    </link>
    <joint name="left_front_roller_0_joint" type="continuous">
        <origin rpy="0 0 0" xyz="4.163799117101001e-18 0 -0.068" />
        <axis xyz="0.7071067811865476 -0.7071067811865476 0.0" />
        <dynamics damping="0.0" friction="0.001" />
        <parent link="left_front_wheel" />
        <child link="left_front_roller_0" />
    </joint>
    <gazebo reference="left_front_roller_0">
        <mu1 value="2000.0" />
        <mu2 value="2000.0" />
        <kp value="1000000.0" />
        <kd value="100.0" />
        <material>Gazebo/Black</material>
        <plugin name="gazebo_ros_control">
            <robotNamespace>/</robotNamespace>
        </plugin>
    </gazebo>
    <!--  link  -->
    <link name="left_front_roller_1">
        <collision>
            <geometry>
                <sphere radius="0.009" />
            </geometry>
        </collision>
        <inertial>
            <mass value="0.036" />
            <inertia ixx="3128e-9" ixy="0.0" ixz="0.0" iyy="3128e-9" iyz="0.0" izz="3128e-9" />
            <origin xyz="0 0 0" rpy="0 0 0" />
        </inertial>
    </link>
    <joint name="left_front_roller_1_joint" type="continuous">
        <origin rpy="0 0 0" xyz="0.026041377055996056 0 -0.06281597472798972" />
        <axis xyz="0.653200024955946 -0.7071067811865476 0.27079462217250855" />
        <dynamics damping="0.0" friction="0.001" />
        <parent link="left_front_wheel" />
        <child link="left_front_roller_1" />
    </joint>
    <gazebo reference="left_front_roller_1">
        <mu1 value="2000.0" />
        <mu2 value="2000.0" />
        <kp value="1000000.0" />
        <kd value="100.0" />
        <material>Gazebo/Black</material>
    </gazebo>
    <!--  link  -->
    <link name="left_front_roller_2">
        <collision>
            <geometry>
                <sphere radius="0.009" />
            </geometry>
        </collision>
        <inertial>
            <mass value="0.036" />
            <inertia ixx="3128e-9" ixy="0.0" ixz="0.0" iyy="3128e-9" iyz="0.0" izz="3128e-9" />
            <origin xyz="0 0 0" rpy="0 0 0" />
        </inertial>
    </link>
    <joint name="left_front_roller_2_joint" type="continuous">
        <origin rpy="0 0 0" xyz="0.04811219067739703 0 -0.048054314147865956" />
        <axis xyz="0.49969899116506866 -0.7071067811865476 0.5003008277312888" />
        <dynamics damping="0.0" friction="0.001" />
        <parent link="left_front_wheel" />
        <child link="left_front_roller_2" />
    </joint>
    <gazebo reference="left_front_roller_2">
        <mu1 value="2000.0" />
        <mu2 value="2000.0" />
        <kp value="1000000.0" />
        <kd value="100.0" />
        <material>Gazebo/Black</material>
    </gazebo>
    <!--  link  -->
    <link name="left_front_roller_3">
        <collision>
            <geometry>
                <sphere radius="0.009" />
            </geometry>
        </collision>
        <inertial>
            <mass value="0.036" />
            <inertia ixx="3128e-9" ixy="0.0" ixz="0.0" iyy="3128e-9" iyz="0.0" izz="3128e-9" />
            <origin xyz="0 0 0" rpy="0 0 0" />
        </inertial>
    </link>
    <joint name="left_front_roller_3_joint" type="continuous">
        <origin rpy="0 0 0" xyz="0.06284727452340379 0 -0.025965748303869884" />
        <axis xyz="0.2700081868271984 -0.7071067811865476 0.6535254999204613" />
        <dynamics damping="0.0" friction="0.001" />
        <parent link="left_front_wheel" />
        <child link="left_front_roller_3" />
    </joint>
    <gazebo reference="left_front_roller_3">
        <mu1 value="2000.0" />
        <mu2 value="2000.0" />
        <kp value="1000000.0" />
        <kd value="100.0" />
        <material>Gazebo/Black</material>
    </gazebo>
    <!--  link  -->
    <link name="left_front_roller_4">
        <collision>
            <geometry>
                <sphere radius="0.009" />
            </geometry>
        </collision>
        <inertial>
            <mass value="0.036" />
            <inertia ixx="3128e-9" ixy="0.0" ixz="0.0" iyy="3128e-9" iyz="0.0" izz="3128e-9" />
            <origin xyz="0 0 0" rpy="0 0 0" />
        </inertial>
    </link>
    <joint name="left_front_roller_4_joint" type="continuous">
        <origin rpy="0 0 0" xyz="0.06799995073981367 0 8.184975818264867e-05" />
        <axis xyz="-0.0008511252801386329 -0.7071067811865476 0.7071062689481388" />
        <dynamics damping="0.0" friction="0.001" />
        <parent link="left_front_wheel" />
        <child link="left_front_roller_4" />
    </joint>
    <gazebo reference="left_front_roller_4">
        <mu1 value="2000.0" />
        <mu2 value="2000.0" />
        <kp value="1000000.0" />
        <kd value="100.0" />
        <material>Gazebo/Black</material>
    </gazebo>
    <!--  link  -->
    <link name="left_front_roller_5">
        <collision>
            <geometry>
                <sphere radius="0.009" />
            </geometry>
        </collision>
        <inertial>
            <mass value="0.036" />
            <inertia ixx="3128e-9" ixy="0.0" ixz="0.0" iyy="3128e-9" iyz="0.0" izz="3128e-9" />
            <origin xyz="0 0 0" rpy="0 0 0" />
        </inertial>
    </link>
    <joint name="left_front_roller_5_joint" type="continuous">
        <origin rpy="0 0 0" xyz="0.06278458392296919 0 0.026116968078619688" />
        <axis xyz="-0.27158066518271434 -0.7071067811865476 0.6528736036162853" />
        <dynamics damping="0.0" friction="0.001" />
        <parent link="left_front_wheel" />
        <child link="left_front_roller_5" />
    </joint>
    <gazebo reference="left_front_roller_5">
        <mu1 value="2000.0" />
        <mu2 value="2000.0" />
        <kp value="1000000.0" />
        <kd value="100.0" />
        <material>Gazebo/Black</material>
    </gazebo>
    <!--  link  -->
    <link name="left_front_roller_6">
        <collision>
            <geometry>
                <sphere radius="0.009" />
            </geometry>
        </collision>
        <inertial>
            <mass value="0.036" />
            <inertia ixx="3128e-9" ixy="0.0" ixz="0.0" iyy="3128e-9" iyz="0.0" izz="3128e-9" />
            <origin xyz="0 0 0" rpy="0 0 0" />
        </inertial>
    </link>
    <joint name="left_front_roller_6_joint" type="continuous">
        <origin rpy="0 0 0" xyz="0.0479963679958505 0 0.04816999750059053" />
        <axis xyz="-0.5009019394471561 -0.7071067811865476 0.499096430620454" />
        <dynamics damping="0.0" friction="0.001" />
        <parent link="left_front_wheel" />
        <child link="left_front_roller_6" />
    </joint>
    <gazebo reference="left_front_roller_6">
        <mu1 value="2000.0" />
        <mu2 value="2000.0" />
        <kp value="1000000.0" />
        <kd value="100.0" />
        <material>Gazebo/Black</material>
    </gazebo>
    <!--  link  -->
    <link name="left_front_roller_7">
        <collision>
            <geometry>
                <sphere radius="0.009" />
            </geometry>
        </collision>
        <inertial>
            <mass value="0.036" />
            <inertia ixx="3128e-9" ixy="0.0" ixz="0.0" iyy="3128e-9" iyz="0.0" izz="3128e-9" />
            <origin xyz="0 0 0" rpy="0 0 0" />
        </inertial>
    </link>
    <joint name="left_front_roller_7_joint" type="continuous">
        <origin rpy="0 0 0" xyz="0.0258900819318143 0 0.06287848326386335" />
        <axis xyz="-0.6538500280382736 -0.7071067811865476 0.2692213602861942" />
        <dynamics damping="0.0" friction="0.001" />
        <parent link="left_front_wheel" />
        <child link="left_front_roller_7" />
    </joint>
    <gazebo reference="left_front_roller_7">
        <mu1 value="2000.0" />
        <mu2 value="2000.0" />
        <kp value="1000000.0" />
        <kd value="100.0" />
        <material>Gazebo/Black</material>
    </gazebo>
    <!--  link  -->
    <link name="left_front_roller_8">
        <collision>
            <geometry>
                <sphere radius="0.009" />
            </geometry>
        </collision>
        <inertial>
            <mass value="0.036" />
            <inertia ixx="3128e-9" ixy="0.0" ixz="0.0" iyy="3128e-9" iyz="0.0" izz="3128e-9" />
            <origin xyz="0 0 0" rpy="0 0 0" />
        </inertial>
    </link>
    <joint name="left_front_roller_8_joint" type="continuous">
        <origin rpy="0 0 0" xyz="-0.00016369939777898906 0 0.06799980295932605" />
        <axis xyz="-0.7071047322336546 -0.7071067811865476 -0.0017022493271422689" />
        <dynamics damping="0.0" friction="0.001" />
        <parent link="left_front_wheel" />
        <child link="left_front_roller_8" />
    </joint>
    <gazebo reference="left_front_roller_8">
        <mu1 value="2000.0" />
        <mu2 value="2000.0" />
        <kp value="1000000.0" />
        <kd value="100.0" />
        <material>Gazebo/Black</material>
    </gazebo>
    <!--  link  -->
    <link name="left_front_roller_9">
        <collision>
            <geometry>
                <sphere radius="0.009" />
            </geometry>
        </collision>
        <inertial>
            <mass value="0.036" />
            <inertia ixx="3128e-9" ixy="0.0" ixz="0.0" iyy="3128e-9" iyz="0.0" izz="3128e-9" />
            <origin xyz="0 0 0" rpy="0 0 0" />
        </inertial>
    </link>
    <joint name="left_front_roller_9_joint" type="continuous">
        <origin rpy="0 0 0" xyz="-0.026192521262222306 0 0.06275310215382211" />
        <axis xyz="-0.6525462363744081 -0.7071067811865476 -0.2723663147189738" />
        <dynamics damping="0.0" friction="0.001" />
        <parent link="left_front_wheel" />
        <child link="left_front_roller_9" />
    </joint>
    <gazebo reference="left_front_roller_9">
        <mu1 value="2000.0" />
        <mu2 value="2000.0" />
        <kp value="1000000.0" />
        <kd value="100.0" />
        <material>Gazebo/Black</material>
    </gazebo>
    <!--  link  -->
    <link name="left_front_roller_10">
        <collision>
            <geometry>
                <sphere radius="0.009" />
            </geometry>
        </collision>
        <inertial>
            <mass value="0.036" />
            <inertia ixx="3128e-9" ixy="0.0" ixz="0.0" iyy="3128e-9" iyz="0.0" izz="3128e-9" />
            <origin xyz="0 0 0" rpy="0 0 0" />
        </inertial>
    </link>
    <joint name="left_front_roller_10_joint" type="continuous">
        <origin rpy="0 0 0" xyz="-0.048227734533694264 0 0.04793835230530472" />
        <axis xyz="-0.49849314697045194 -0.7071067811865476 -0.5015023254417625" />
        <dynamics damping="0.0" friction="0.001" />
        <parent link="left_front_wheel" />
        <child link="left_front_roller_10" />
    </joint>
    <gazebo reference="left_front_roller_10">
        <mu1 value="2000.0" />
        <mu2 value="2000.0" />
        <kp value="1000000.0" />
        <kd value="100.0" />
        <material>Gazebo/Black</material>
    </gazebo>
    <!--  link  -->
    <link name="left_front_roller_11">
        <collision>
            <geometry>
                <sphere radius="0.009" />
            </geometry>
        </collision>
        <inertial>
            <mass value="0.036" />
            <inertia ixx="3128e-9" ixy="0.0" ixz="0.0" iyy="3128e-9" iyz="0.0" izz="3128e-9" />
            <origin xyz="0 0 0" rpy="0 0 0" />
        </inertial>
    </link>
    <joint name="left_front_roller_11_joint" type="continuous">
        <origin rpy="0 0 0" xyz="-0.06290960090415226 0 0.02581437804945697" />
        <axis xyz="-0.2684341436894733 -0.7071067811865476 -0.6541736088391974" />
        <dynamics damping="0.0" friction="0.001" />
        <parent link="left_front_wheel" />
        <child link="left_front_roller_11" />
    </joint>
    <gazebo reference="left_front_roller_11">
        <mu1 value="2000.0" />
        <mu2 value="2000.0" />
        <kp value="1000000.0" />
        <kd value="100.0" />
        <material>Gazebo/Black</material>
    </gazebo>
    <!--  link  -->
    <link name="left_front_roller_12">
        <collision>
            <geometry>
                <sphere radius="0.009" />
            </geometry>
        </collision>
        <inertial>
            <mass value="0.036" />
            <inertia ixx="3128e-9" ixy="0.0" ixz="0.0" iyy="3128e-9" iyz="0.0" izz="3128e-9" />
            <origin xyz="0 0 0" rpy="0 0 0" />
        </inertial>
    </link>
    <joint name="left_front_roller_12_joint" type="continuous">
        <origin rpy="0 0 0" xyz="-0.06799955665875124 0 -0.0002455488002028931" />
        <axis xyz="0.002553370907877698 -0.7071067811865476 -0.7071021710453214" />
        <dynamics damping="0.0" friction="0.001" />
        <parent link="left_front_wheel" />
        <child link="left_front_roller_12" />
    </joint>
    <gazebo reference="left_front_roller_12">
        <mu1 value="2000.0" />
        <mu2 value="2000.0" />
        <kp value="1000000.0" />
        <kd value="100.0" />
        <material>Gazebo/Black</material>
    </gazebo>
    <!--  link  -->
    <link name="left_front_roller_13">
        <collision>
            <geometry>
                <sphere radius="0.009" />
            </geometry>
        </collision>
        <inertial>
            <mass value="0.036" />
            <inertia ixx="3128e-9" ixy="0.0" ixz="0.0" iyy="3128e-9" iyz="0.0" izz="3128e-9" />
            <origin xyz="0 0 0" rpy="0 0 0" />
        </inertial>
    </link>
    <joint name="left_front_roller_13_joint" type="continuous">
        <origin rpy="0 0 0" xyz="-0.06272152946616016 0 -0.026268036497340295" />
        <axis xyz="0.2731515696430154 -0.7071067811865476 -0.6522179237046135" />
        <dynamics damping="0.0" friction="0.001" />
        <parent link="left_front_wheel" />
        <child link="left_front_roller_13" />
    </joint>
    <gazebo reference="left_front_roller_13">
        <mu1 value="2000.0" />
        <mu2 value="2000.0" />
        <kp value="1000000.0" />
        <kd value="100.0" />
        <material>Gazebo/Black</material>
    </gazebo>
    <!--  link  -->
    <link name="left_front_roller_14">
        <collision>
            <geometry>
                <sphere radius="0.009" />
            </geometry>
        </collision>
        <inertial>
            <mass value="0.036" />
            <inertia ixx="3128e-9" ixy="0.0" ixz="0.0" iyy="3128e-9" iyz="0.0" izz="3128e-9" />
            <origin xyz="0 0 0" rpy="0 0 0" />
        </inertial>
    </link>
    <joint name="left_front_roller_14_joint" type="continuous">
        <origin rpy="0 0 0" xyz="-0.04788026716028342 0 -0.04828540169305713" />
        <axis xyz="0.5021019848452515 -0.7071067811865476 -0.49788914108911725" />
        <dynamics damping="0.0" friction="0.001" />
        <parent link="left_front_wheel" />
        <child link="left_front_roller_14" />
    </joint>
    <gazebo reference="left_front_roller_14">
        <mu1 value="2000.0" />
        <mu2 value="2000.0" />
        <kp value="1000000.0" />
        <kd value="100.0" />
        <material>Gazebo/Black</material>
    </gazebo>
    <!--  link  -->
    <link name="left_front_roller_15">
        <collision>
            <geometry>
                <sphere radius="0.009" />
            </geometry>
        </collision>
        <inertial>
            <mass value="0.036" />
            <inertia ixx="3128e-9" ixy="0.0" ixz="0.0" iyy="3128e-9" iyz="0.0" izz="3128e-9" />
            <origin xyz="0 0 0" rpy="0 0 0" />
        </inertial>
    </link>
    <joint name="left_front_roller_15_joint" type="continuous">
        <origin rpy="0 0 0" xyz="-0.025738636766479847 0 -0.06294062739918639" />
        <axis xyz="0.6544962418544192 -0.7071067811865476 -0.2676465381775779" />
        <dynamics damping="0.0" friction="0.001" />
        <parent link="left_front_wheel" />
        <child link="left_front_roller_15" />
    </joint>
    <gazebo reference="left_front_roller_15">
        <mu1 value="2000.0" />
        <mu2 value="2000.0" />
        <kp value="1000000.0" />
        <kd value="100.0" />
        <material>Gazebo/Black</material>
    </gazebo>
    <!--  link  -->
    <link name="right_front_wheel">
        <visual>
            <geometry>
                <mesh filename="package://sp_description/meshes/common/mecanum_wheel/left_mecanum_wheel.STL" />
            </geometry>
        </visual>
        <inertial>
            <mass value="0.4235" />
            <inertia ixx="4.122e-4" ixy="0.0" ixz="0.0" iyy="7.398e-4" iyz="0.0" izz="4.122e-4" />
        </inertial>
    </link>
    <!--  joint  -->
    <joint name="right_front_wheel_joint" type="revolute">
        <axis xyz="0 1 0" />
        <origin rpy="0 0 0" xyz="0.19185 -0.221 0.077" />
        <!--      limit not work while type="continuous"-->
        <limit effort="10" lower="-1e9" upper="1e9" velocity="70" />
        <dynamics damping="0.0" friction="0.05" />
        <parent link="base_link" />
        <child link="right_front_wheel" />
    </joint>
    <!--  link  -->
    <link name="right_front_roller_0">
        <collision>
            <geometry>
                <sphere radius="0.009" />
            </geometry>
        </collision>
        <inertial>
            <mass value="0.036" />
            <inertia ixx="3128e-9" ixy="0.0" ixz="0.0" iyy="3128e-9" iyz="0.0" izz="3128e-9" />
            <origin xyz="0 0 0" rpy="0 0 0" />
        </inertial>
    </link>
    <joint name="right_front_roller_0_joint" type="continuous">
        <origin rpy="0 0 0" xyz="4.163799117101001e-18 0 -0.068" />
        <axis xyz="0.7071067811865476 0.7071067811865476 0.0" />
        <dynamics damping="0.0" friction="0.001" />
        <parent link="right_front_wheel" />
        <child link="right_front_roller_0" />
    </joint>
    <gazebo reference="right_front_roller_0">
        <mu1 value="2000.0" />
        <mu2 value="2000.0" />
        <kp value="1000000.0" />
        <kd value="100.0" />
        <material>Gazebo/Black</material>
    </gazebo>
    <!--  link  -->
    <link name="right_front_roller_1">
        <collision>
            <geometry>
                <sphere radius="0.009" />
            </geometry>
        </collision>
        <inertial>
            <mass value="0.036" />
            <inertia ixx="3128e-9" ixy="0.0" ixz="0.0" iyy="3128e-9" iyz="0.0" izz="3128e-9" />
            <origin xyz="0 0 0" rpy="0 0 0" />
        </inertial>
    </link>
    <joint name="right_front_roller_1_joint" type="continuous">
        <origin rpy="0 0 0" xyz="0.026041377055996056 0 -0.06281597472798972" />
        <axis xyz="0.653200024955946 0.7071067811865476 0.27079462217250855" />
        <dynamics damping="0.0" friction="0.001" />
        <parent link="right_front_wheel" />
        <child link="right_front_roller_1" />
    </joint>
    <gazebo reference="right_front_roller_1">
        <mu1 value="2000.0" />
        <mu2 value="2000.0" />
        <kp value="1000000.0" />
        <kd value="100.0" />
        <material>Gazebo/Black</material>
    </gazebo>
    <!--  link  -->
    <link name="right_front_roller_2">
        <collision>
            <geometry>
                <sphere radius="0.009" />
            </geometry>
        </collision>
        <inertial>
            <mass value="0.036" />
            <inertia ixx="3128e-9" ixy="0.0" ixz="0.0" iyy="3128e-9" iyz="0.0" izz="3128e-9" />
            <origin xyz="0 0 0" rpy="0 0 0" />
        </inertial>
    </link>
    <joint name="right_front_roller_2_joint" type="continuous">
        <origin rpy="0 0 0" xyz="0.04811219067739703 0 -0.048054314147865956" />
        <axis xyz="0.49969899116506866 0.7071067811865476 0.5003008277312888" />
        <dynamics damping="0.0" friction="0.001" />
        <parent link="right_front_wheel" />
        <child link="right_front_roller_2" />
    </joint>
    <gazebo reference="right_front_roller_2">
        <mu1 value="2000.0" />
        <mu2 value="2000.0" />
        <kp value="1000000.0" />
        <kd value="100.0" />
        <material>Gazebo/Black</material>
    </gazebo>
    <!--  link  -->
    <link name="right_front_roller_3">
        <collision>
            <geometry>
                <sphere radius="0.009" />
            </geometry>
        </collision>
        <inertial>
            <mass value="0.036" />
            <inertia ixx="3128e-9" ixy="0.0" ixz="0.0" iyy="3128e-9" iyz="0.0" izz="3128e-9" />
            <origin xyz="0 0 0" rpy="0 0 0" />
        </inertial>
    </link>
    <joint name="right_front_roller_3_joint" type="continuous">
        <origin rpy="0 0 0" xyz="0.06284727452340379 0 -0.025965748303869884" />
        <axis xyz="0.2700081868271984 0.7071067811865476 0.6535254999204613" />
        <dynamics damping="0.0" friction="0.001" />
        <parent link="right_front_wheel" />
        <child link="right_front_roller_3" />
    </joint>
    <gazebo reference="right_front_roller_3">
        <mu1 value="2000.0" />
        <mu2 value="2000.0" />
        <kp value="1000000.0" />
        <kd value="100.0" />
        <material>Gazebo/Black</material>
    </gazebo>
    <!--  link  -->
    <link name="right_front_roller_4">
        <collision>
            <geometry>
                <sphere radius="0.009" />
            </geometry>
        </collision>
        <inertial>
            <mass value="0.036" />
            <inertia ixx="3128e-9" ixy="0.0" ixz="0.0" iyy="3128e-9" iyz="0.0" izz="3128e-9" />
            <origin xyz="0 0 0" rpy="0 0 0" />
        </inertial>
    </link>
    <joint name="right_front_roller_4_joint" type="continuous">
        <origin rpy="0 0 0" xyz="0.06799995073981367 0 8.184975818264867e-05" />
        <axis xyz="-0.0008511252801386329 0.7071067811865476 0.7071062689481388" />
        <dynamics damping="0.0" friction="0.001" />
        <parent link="right_front_wheel" />
        <child link="right_front_roller_4" />
    </joint>
    <gazebo reference="right_front_roller_4">
        <mu1 value="2000.0" />
        <mu2 value="2000.0" />
        <kp value="1000000.0" />
        <kd value="100.0" />
        <material>Gazebo/Black</material>
    </gazebo>
    <!--  link  -->
    <link name="right_front_roller_5">
        <collision>
            <geometry>
                <sphere radius="0.009" />
            </geometry>
        </collision>
        <inertial>
            <mass value="0.036" />
            <inertia ixx="3128e-9" ixy="0.0" ixz="0.0" iyy="3128e-9" iyz="0.0" izz="3128e-9" />
            <origin xyz="0 0 0" rpy="0 0 0" />
        </inertial>
    </link>
    <joint name="right_front_roller_5_joint" type="continuous">
        <origin rpy="0 0 0" xyz="0.06278458392296919 0 0.026116968078619688" />
        <axis xyz="-0.27158066518271434 0.7071067811865476 0.6528736036162853" />
        <dynamics damping="0.0" friction="0.001" />
        <parent link="right_front_wheel" />
        <child link="right_front_roller_5" />
    </joint>
    <gazebo reference="right_front_roller_5">
        <mu1 value="2000.0" />
        <mu2 value="2000.0" />
        <kp value="1000000.0" />
        <kd value="100.0" />
        <material>Gazebo/Black</material>
    </gazebo>
    <!--  link  -->
    <link name="right_front_roller_6">
        <collision>
            <geometry>
                <sphere radius="0.009" />
            </geometry>
        </collision>
        <inertial>
            <mass value="0.036" />
            <inertia ixx="3128e-9" ixy="0.0" ixz="0.0" iyy="3128e-9" iyz="0.0" izz="3128e-9" />
            <origin xyz="0 0 0" rpy="0 0 0" />
        </inertial>
    </link>
    <joint name="right_front_roller_6_joint" type="continuous">
        <origin rpy="0 0 0" xyz="0.0479963679958505 0 0.04816999750059053" />
        <axis xyz="-0.5009019394471561 0.7071067811865476 0.499096430620454" />
        <dynamics damping="0.0" friction="0.001" />
        <parent link="right_front_wheel" />
        <child link="right_front_roller_6" />
    </joint>
    <gazebo reference="right_front_roller_6">
        <mu1 value="2000.0" />
        <mu2 value="2000.0" />
        <kp value="1000000.0" />
        <kd value="100.0" />
        <material>Gazebo/Black</material>
    </gazebo>
    <!--  link  -->
    <link name="right_front_roller_7">
        <collision>
            <geometry>
                <sphere radius="0.009" />
            </geometry>
        </collision>
        <inertial>
            <mass value="0.036" />
            <inertia ixx="3128e-9" ixy="0.0" ixz="0.0" iyy="3128e-9" iyz="0.0" izz="3128e-9" />
            <origin xyz="0 0 0" rpy="0 0 0" />
        </inertial>
    </link>
    <joint name="right_front_roller_7_joint" type="continuous">
        <origin rpy="0 0 0" xyz="0.0258900819318143 0 0.06287848326386335" />
        <axis xyz="-0.6538500280382736 0.7071067811865476 0.2692213602861942" />
        <dynamics damping="0.0" friction="0.001" />
        <parent link="right_front_wheel" />
        <child link="right_front_roller_7" />
    </joint>
    <gazebo reference="right_front_roller_7">
        <mu1 value="2000.0" />
        <mu2 value="2000.0" />
        <kp value="1000000.0" />
        <kd value="100.0" />
        <material>Gazebo/Black</material>
    </gazebo>
    <!--  link  -->
    <link name="right_front_roller_8">
        <collision>
            <geometry>
                <sphere radius="0.009" />
            </geometry>
        </collision>
        <inertial>
            <mass value="0.036" />
            <inertia ixx="3128e-9" ixy="0.0" ixz="0.0" iyy="3128e-9" iyz="0.0" izz="3128e-9" />
            <origin xyz="0 0 0" rpy="0 0 0" />
        </inertial>
    </link>
    <joint name="right_front_roller_8_joint" type="continuous">
        <origin rpy="0 0 0" xyz="-0.00016369939777898906 0 0.06799980295932605" />
        <axis xyz="-0.7071047322336546 0.7071067811865476 -0.0017022493271422689" />
        <dynamics damping="0.0" friction="0.001" />
        <parent link="right_front_wheel" />
        <child link="right_front_roller_8" />
    </joint>
    <gazebo reference="right_front_roller_8">
        <mu1 value="2000.0" />
        <mu2 value="2000.0" />
        <kp value="1000000.0" />
        <kd value="100.0" />
        <material>Gazebo/Black</material>
    </gazebo>
    <!--  link  -->
    <link name="right_front_roller_9">
        <collision>
            <geometry>
                <sphere radius="0.009" />
            </geometry>
        </collision>
        <inertial>
            <mass value="0.036" />
            <inertia ixx="3128e-9" ixy="0.0" ixz="0.0" iyy="3128e-9" iyz="0.0" izz="3128e-9" />
            <origin xyz="0 0 0" rpy="0 0 0" />
        </inertial>
    </link>
    <joint name="right_front_roller_9_joint" type="continuous">
        <origin rpy="0 0 0" xyz="-0.026192521262222306 0 0.06275310215382211" />
        <axis xyz="-0.6525462363744081 0.7071067811865476 -0.2723663147189738" />
        <dynamics damping="0.0" friction="0.001" />
        <parent link="right_front_wheel" />
        <child link="right_front_roller_9" />
    </joint>
    <gazebo reference="right_front_roller_9">
        <mu1 value="2000.0" />
        <mu2 value="2000.0" />
        <kp value="1000000.0" />
        <kd value="100.0" />
        <material>Gazebo/Black</material>
    </gazebo>
    <!--  link  -->
    <link name="right_front_roller_10">
        <collision>
            <geometry>
                <sphere radius="0.009" />
            </geometry>
        </collision>
        <inertial>
            <mass value="0.036" />
            <inertia ixx="3128e-9" ixy="0.0" ixz="0.0" iyy="3128e-9" iyz="0.0" izz="3128e-9" />
            <origin xyz="0 0 0" rpy="0 0 0" />
        </inertial>
    </link>
    <joint name="right_front_roller_10_joint" type="continuous">
        <origin rpy="0 0 0" xyz="-0.048227734533694264 0 0.04793835230530472" />
        <axis xyz="-0.49849314697045194 0.7071067811865476 -0.5015023254417625" />
        <dynamics damping="0.0" friction="0.001" />
        <parent link="right_front_wheel" />
        <child link="right_front_roller_10" />
    </joint>
    <gazebo reference="right_front_roller_10">
        <mu1 value="2000.0" />
        <mu2 value="2000.0" />
        <kp value="1000000.0" />
        <kd value="100.0" />
        <material>Gazebo/Black</material>
    </gazebo>
    <!--  link  -->
    <link name="right_front_roller_11">
        <collision>
            <geometry>
                <sphere radius="0.009" />
            </geometry>
        </collision>
        <inertial>
            <mass value="0.036" />
            <inertia ixx="3128e-9" ixy="0.0" ixz="0.0" iyy="3128e-9" iyz="0.0" izz="3128e-9" />
            <origin xyz="0 0 0" rpy="0 0 0" />
        </inertial>
    </link>
    <joint name="right_front_roller_11_joint" type="continuous">
        <origin rpy="0 0 0" xyz="-0.06290960090415226 0 0.02581437804945697" />
        <axis xyz="-0.2684341436894733 0.7071067811865476 -0.6541736088391974" />
        <dynamics damping="0.0" friction="0.001" />
        <parent link="right_front_wheel" />
        <child link="right_front_roller_11" />
    </joint>
    <gazebo reference="right_front_roller_11">
        <mu1 value="2000.0" />
        <mu2 value="2000.0" />
        <kp value="1000000.0" />
        <kd value="100.0" />
        <material>Gazebo/Black</material>
    </gazebo>
    <!--  link  -->
    <link name="right_front_roller_12">
        <collision>
            <geometry>
                <sphere radius="0.009" />
            </geometry>
        </collision>
        <inertial>
            <mass value="0.036" />
            <inertia ixx="3128e-9" ixy="0.0" ixz="0.0" iyy="3128e-9" iyz="0.0" izz="3128e-9" />
            <origin xyz="0 0 0" rpy="0 0 0" />
        </inertial>
    </link>
    <joint name="right_front_roller_12_joint" type="continuous">
        <origin rpy="0 0 0" xyz="-0.06799955665875124 0 -0.0002455488002028931" />
        <axis xyz="0.002553370907877698 0.7071067811865476 -0.7071021710453214" />
        <dynamics damping="0.0" friction="0.001" />
        <parent link="right_front_wheel" />
        <child link="right_front_roller_12" />
    </joint>
    <gazebo reference="right_front_roller_12">
        <mu1 value="2000.0" />
        <mu2 value="2000.0" />
        <kp value="1000000.0" />
        <kd value="100.0" />
        <material>Gazebo/Black</material>
    </gazebo>
    <!--  link  -->
    <link name="right_front_roller_13">
        <collision>
            <geometry>
                <sphere radius="0.009" />
            </geometry>
        </collision>
        <inertial>
            <mass value="0.036" />
            <inertia ixx="3128e-9" ixy="0.0" ixz="0.0" iyy="3128e-9" iyz="0.0" izz="3128e-9" />
            <origin xyz="0 0 0" rpy="0 0 0" />
        </inertial>
    </link>
    <joint name="right_front_roller_13_joint" type="continuous">
        <origin rpy="0 0 0" xyz="-0.06272152946616016 0 -0.026268036497340295" />
        <axis xyz="0.2731515696430154 0.7071067811865476 -0.6522179237046135" />
        <dynamics damping="0.0" friction="0.001" />
        <parent link="right_front_wheel" />
        <child link="right_front_roller_13" />
    </joint>
    <gazebo reference="right_front_roller_13">
        <mu1 value="2000.0" />
        <mu2 value="2000.0" />
        <kp value="1000000.0" />
        <kd value="100.0" />
        <material>Gazebo/Black</material>
    </gazebo>
    <!--  link  -->
    <link name="right_front_roller_14">
        <collision>
            <geometry>
                <sphere radius="0.009" />
            </geometry>
        </collision>
        <inertial>
            <mass value="0.036" />
            <inertia ixx="3128e-9" ixy="0.0" ixz="0.0" iyy="3128e-9" iyz="0.0" izz="3128e-9" />
            <origin xyz="0 0 0" rpy="0 0 0" />
        </inertial>
    </link>
    <joint name="right_front_roller_14_joint" type="continuous">
        <origin rpy="0 0 0" xyz="-0.04788026716028342 0 -0.04828540169305713" />
        <axis xyz="0.5021019848452515 0.7071067811865476 -0.49788914108911725" />
        <dynamics damping="0.0" friction="0.001" />
        <parent link="right_front_wheel" />
        <child link="right_front_roller_14" />
    </joint>
    <gazebo reference="right_front_roller_14">
        <mu1 value="2000.0" />
        <mu2 value="2000.0" />
        <kp value="1000000.0" />
        <kd value="100.0" />
        <material>Gazebo/Black</material>
    </gazebo>
    <!--  link  -->
    <link name="right_front_roller_15">
        <collision>
            <geometry>
                <sphere radius="0.009" />
            </geometry>
        </collision>
        <inertial>
            <mass value="0.036" />
            <inertia ixx="3128e-9" ixy="0.0" ixz="0.0" iyy="3128e-9" iyz="0.0" izz="3128e-9" />
            <origin xyz="0 0 0" rpy="0 0 0" />
        </inertial>
    </link>
    <joint name="right_front_roller_15_joint" type="continuous">
        <origin rpy="0 0 0" xyz="-0.025738636766479847 0 -0.06294062739918639" />
        <axis xyz="0.6544962418544192 0.7071067811865476 -0.2676465381775779" />
        <dynamics damping="0.0" friction="0.001" />
        <parent link="right_front_wheel" />
        <child link="right_front_roller_15" />
    </joint>
    <gazebo reference="right_front_roller_15">
        <mu1 value="2000.0" />
        <mu2 value="2000.0" />
        <kp value="1000000.0" />
        <kd value="100.0" />
        <material>Gazebo/Black</material>
    </gazebo>
    <!--  link  -->
    <link name="left_back_wheel">
        <visual>
            <geometry>
                <mesh filename="package://sp_description/meshes/common/mecanum_wheel/left_mecanum_wheel.STL" />
            </geometry>
        </visual>
        <inertial>
            <mass value="0.4235" />
            <inertia ixx="4.122e-4" ixy="0.0" ixz="0.0" iyy="7.398e-4" iyz="0.0" izz="4.122e-4" />
        </inertial>
    </link>
    <!--  joint  -->
    <joint name="left_back_wheel_joint" type="revolute">
        <axis xyz="0 1 0" />
        <origin rpy="0 0 0" xyz="-0.19152 0.221 0.077" />
        <!--      limit not work while type="continuous"-->
        <limit effort="10" lower="-1e9" upper="1e9" velocity="70" />
        <dynamics damping="0.0" friction="0.05" />
        <parent link="base_link" />
        <child link="left_back_wheel" />
    </joint>
    <!--  link  -->
    <link name="left_back_roller_0">
        <collision>
            <geometry>
                <sphere radius="0.009" />
            </geometry>
        </collision>
        <inertial>
            <mass value="0.036" />
            <inertia ixx="3128e-9" ixy="0.0" ixz="0.0" iyy="3128e-9" iyz="0.0" izz="3128e-9" />
            <origin xyz="0 0 0" rpy="0 0 0" />
        </inertial>
    </link>
    <joint name="left_back_roller_0_joint" type="continuous">
        <origin rpy="0 0 0" xyz="4.163799117101001e-18 0 -0.068" />
        <axis xyz="0.7071067811865476 0.7071067811865476 0.0" />
        <dynamics damping="0.0" friction="0.001" />
        <parent link="left_back_wheel" />
        <child link="left_back_roller_0" />
    </joint>
    <gazebo reference="left_back_roller_0">
        <mu1 value="2000.0" />
        <mu2 value="2000.0" />
        <kp value="1000000.0" />
        <kd value="100.0" />
        <material>Gazebo/Black</material>
    </gazebo>
    <!--  link  -->
    <link name="left_back_roller_1">
        <collision>
            <geometry>
                <sphere radius="0.009" />
            </geometry>
        </collision>
        <inertial>
            <mass value="0.036" />
            <inertia ixx="3128e-9" ixy="0.0" ixz="0.0" iyy="3128e-9" iyz="0.0" izz="3128e-9" />
            <origin xyz="0 0 0" rpy="0 0 0" />
        </inertial>
    </link>
    <joint name="left_back_roller_1_joint" type="continuous">
        <origin rpy="0 0 0" xyz="0.026041377055996056 0 -0.06281597472798972" />
        <axis xyz="0.653200024955946 0.7071067811865476 0.27079462217250855" />
        <dynamics damping="0.0" friction="0.001" />
        <parent link="left_back_wheel" />
        <child link="left_back_roller_1" />
    </joint>
    <gazebo reference="left_back_roller_1">
        <mu1 value="2000.0" />
        <mu2 value="2000.0" />
        <kp value="1000000.0" />
        <kd value="100.0" />
        <material>Gazebo/Black</material>
    </gazebo>
    <!--  link  -->
    <link name="left_back_roller_2">
        <collision>
            <geometry>
                <sphere radius="0.009" />
            </geometry>
        </collision>
        <inertial>
            <mass value="0.036" />
            <inertia ixx="3128e-9" ixy="0.0" ixz="0.0" iyy="3128e-9" iyz="0.0" izz="3128e-9" />
            <origin xyz="0 0 0" rpy="0 0 0" />
        </inertial>
    </link>
    <joint name="left_back_roller_2_joint" type="continuous">
        <origin rpy="0 0 0" xyz="0.04811219067739703 0 -0.048054314147865956" />
        <axis xyz="0.49969899116506866 0.7071067811865476 0.5003008277312888" />
        <dynamics damping="0.0" friction="0.001" />
        <parent link="left_back_wheel" />
        <child link="left_back_roller_2" />
    </joint>
    <gazebo reference="left_back_roller_2">
        <mu1 value="2000.0" />
        <mu2 value="2000.0" />
        <kp value="1000000.0" />
        <kd value="100.0" />
        <material>Gazebo/Black</material>
    </gazebo>
    <!--  link  -->
    <link name="left_back_roller_3">
        <collision>
            <geometry>
                <sphere radius="0.009" />
            </geometry>
        </collision>
        <inertial>
            <mass value="0.036" />
            <inertia ixx="3128e-9" ixy="0.0" ixz="0.0" iyy="3128e-9" iyz="0.0" izz="3128e-9" />
            <origin xyz="0 0 0" rpy="0 0 0" />
        </inertial>
    </link>
    <joint name="left_back_roller_3_joint" type="continuous">
        <origin rpy="0 0 0" xyz="0.06284727452340379 0 -0.025965748303869884" />
        <axis xyz="0.2700081868271984 0.7071067811865476 0.6535254999204613" />
        <dynamics damping="0.0" friction="0.001" />
        <parent link="left_back_wheel" />
        <child link="left_back_roller_3" />
    </joint>
    <gazebo reference="left_back_roller_3">
        <mu1 value="2000.0" />
        <mu2 value="2000.0" />
        <kp value="1000000.0" />
        <kd value="100.0" />
        <material>Gazebo/Black</material>
    </gazebo>
    <!--  link  -->
    <link name="left_back_roller_4">
        <collision>
            <geometry>
                <sphere radius="0.009" />
            </geometry>
        </collision>
        <inertial>
            <mass value="0.036" />
            <inertia ixx="3128e-9" ixy="0.0" ixz="0.0" iyy="3128e-9" iyz="0.0" izz="3128e-9" />
            <origin xyz="0 0 0" rpy="0 0 0" />
        </inertial>
    </link>
    <joint name="left_back_roller_4_joint" type="continuous">
        <origin rpy="0 0 0" xyz="0.06799995073981367 0 8.184975818264867e-05" />
        <axis xyz="-0.0008511252801386329 0.7071067811865476 0.7071062689481388" />
        <dynamics damping="0.0" friction="0.001" />
        <parent link="left_back_wheel" />
        <child link="left_back_roller_4" />
    </joint>
    <gazebo reference="left_back_roller_4">
        <mu1 value="2000.0" />
        <mu2 value="2000.0" />
        <kp value="1000000.0" />
        <kd value="100.0" />
        <material>Gazebo/Black</material>
    </gazebo>
    <!--  link  -->
    <link name="left_back_roller_5">
        <collision>
            <geometry>
                <sphere radius="0.009" />
            </geometry>
        </collision>
        <inertial>
            <mass value="0.036" />
            <inertia ixx="3128e-9" ixy="0.0" ixz="0.0" iyy="3128e-9" iyz="0.0" izz="3128e-9" />
            <origin xyz="0 0 0" rpy="0 0 0" />
        </inertial>
    </link>
    <joint name="left_back_roller_5_joint" type="continuous">
        <origin rpy="0 0 0" xyz="0.06278458392296919 0 0.026116968078619688" />
        <axis xyz="-0.27158066518271434 0.7071067811865476 0.6528736036162853" />
        <dynamics damping="0.0" friction="0.001" />
        <parent link="left_back_wheel" />
        <child link="left_back_roller_5" />
    </joint>
    <gazebo reference="left_back_roller_5">
        <mu1 value="2000.0" />
        <mu2 value="2000.0" />
        <kp value="1000000.0" />
        <kd value="100.0" />
        <material>Gazebo/Black</material>
    </gazebo>
    <!--  link  -->
    <link name="left_back_roller_6">
        <collision>
            <geometry>
                <sphere radius="0.009" />
            </geometry>
        </collision>
        <inertial>
            <mass value="0.036" />
            <inertia ixx="3128e-9" ixy="0.0" ixz="0.0" iyy="3128e-9" iyz="0.0" izz="3128e-9" />
            <origin xyz="0 0 0" rpy="0 0 0" />
        </inertial>
    </link>
    <joint name="left_back_roller_6_joint" type="continuous">
        <origin rpy="0 0 0" xyz="0.0479963679958505 0 0.04816999750059053" />
        <axis xyz="-0.5009019394471561 0.7071067811865476 0.499096430620454" />
        <dynamics damping="0.0" friction="0.001" />
        <parent link="left_back_wheel" />
        <child link="left_back_roller_6" />
    </joint>
    <gazebo reference="left_back_roller_6">
        <mu1 value="2000.0" />
        <mu2 value="2000.0" />
        <kp value="1000000.0" />
        <kd value="100.0" />
        <material>Gazebo/Black</material>
    </gazebo>
    <!--  link  -->
    <link name="left_back_roller_7">
        <collision>
            <geometry>
                <sphere radius="0.009" />
            </geometry>
        </collision>
        <inertial>
            <mass value="0.036" />
            <inertia ixx="3128e-9" ixy="0.0" ixz="0.0" iyy="3128e-9" iyz="0.0" izz="3128e-9" />
            <origin xyz="0 0 0" rpy="0 0 0" />
        </inertial>
    </link>
    <joint name="left_back_roller_7_joint" type="continuous">
        <origin rpy="0 0 0" xyz="0.0258900819318143 0 0.06287848326386335" />
        <axis xyz="-0.6538500280382736 0.7071067811865476 0.2692213602861942" />
        <dynamics damping="0.0" friction="0.001" />
        <parent link="left_back_wheel" />
        <child link="left_back_roller_7" />
    </joint>
    <gazebo reference="left_back_roller_7">
        <mu1 value="2000.0" />
        <mu2 value="2000.0" />
        <kp value="1000000.0" />
        <kd value="100.0" />
        <material>Gazebo/Black</material>
    </gazebo>
    <!--  link  -->
    <link name="left_back_roller_8">
        <collision>
            <geometry>
                <sphere radius="0.009" />
            </geometry>
        </collision>
        <inertial>
            <mass value="0.036" />
            <inertia ixx="3128e-9" ixy="0.0" ixz="0.0" iyy="3128e-9" iyz="0.0" izz="3128e-9" />
            <origin xyz="0 0 0" rpy="0 0 0" />
        </inertial>
    </link>
    <joint name="left_back_roller_8_joint" type="continuous">
        <origin rpy="0 0 0" xyz="-0.00016369939777898906 0 0.06799980295932605" />
        <axis xyz="-0.7071047322336546 0.7071067811865476 -0.0017022493271422689" />
        <dynamics damping="0.0" friction="0.001" />
        <parent link="left_back_wheel" />
        <child link="left_back_roller_8" />
    </joint>
    <gazebo reference="left_back_roller_8">
        <mu1 value="2000.0" />
        <mu2 value="2000.0" />
        <kp value="1000000.0" />
        <kd value="100.0" />
        <material>Gazebo/Black</material>
    </gazebo>
    <!--  link  -->
    <link name="left_back_roller_9">
        <collision>
            <geometry>
                <sphere radius="0.009" />
            </geometry>
        </collision>
        <inertial>
            <mass value="0.036" />
            <inertia ixx="3128e-9" ixy="0.0" ixz="0.0" iyy="3128e-9" iyz="0.0" izz="3128e-9" />
            <origin xyz="0 0 0" rpy="0 0 0" />
        </inertial>
    </link>
    <joint name="left_back_roller_9_joint" type="continuous">
        <origin rpy="0 0 0" xyz="-0.026192521262222306 0 0.06275310215382211" />
        <axis xyz="-0.6525462363744081 0.7071067811865476 -0.2723663147189738" />
        <dynamics damping="0.0" friction="0.001" />
        <parent link="left_back_wheel" />
        <child link="left_back_roller_9" />
    </joint>
    <gazebo reference="left_back_roller_9">
        <mu1 value="2000.0" />
        <mu2 value="2000.0" />
        <kp value="1000000.0" />
        <kd value="100.0" />
        <material>Gazebo/Black</material>
    </gazebo>
    <!--  link  -->
    <link name="left_back_roller_10">
        <collision>
            <geometry>
                <sphere radius="0.009" />
            </geometry>
        </collision>
        <inertial>
            <mass value="0.036" />
            <inertia ixx="3128e-9" ixy="0.0" ixz="0.0" iyy="3128e-9" iyz="0.0" izz="3128e-9" />
            <origin xyz="0 0 0" rpy="0 0 0" />
        </inertial>
    </link>
    <joint name="left_back_roller_10_joint" type="continuous">
        <origin rpy="0 0 0" xyz="-0.048227734533694264 0 0.04793835230530472" />
        <axis xyz="-0.49849314697045194 0.7071067811865476 -0.5015023254417625" />
        <dynamics damping="0.0" friction="0.001" />
        <parent link="left_back_wheel" />
        <child link="left_back_roller_10" />
    </joint>
    <gazebo reference="left_back_roller_10">
        <mu1 value="2000.0" />
        <mu2 value="2000.0" />
        <kp value="1000000.0" />
        <kd value="100.0" />
        <material>Gazebo/Black</material>
    </gazebo>
    <!--  link  -->
    <link name="left_back_roller_11">
        <collision>
            <geometry>
                <sphere radius="0.009" />
            </geometry>
        </collision>
        <inertial>
            <mass value="0.036" />
            <inertia ixx="3128e-9" ixy="0.0" ixz="0.0" iyy="3128e-9" iyz="0.0" izz="3128e-9" />
            <origin xyz="0 0 0" rpy="0 0 0" />
        </inertial>
    </link>
    <joint name="left_back_roller_11_joint" type="continuous">
        <origin rpy="0 0 0" xyz="-0.06290960090415226 0 0.02581437804945697" />
        <axis xyz="-0.2684341436894733 0.7071067811865476 -0.6541736088391974" />
        <dynamics damping="0.0" friction="0.001" />
        <parent link="left_back_wheel" />
        <child link="left_back_roller_11" />
    </joint>
    <gazebo reference="left_back_roller_11">
        <mu1 value="2000.0" />
        <mu2 value="2000.0" />
        <kp value="1000000.0" />
        <kd value="100.0" />
        <material>Gazebo/Black</material>
    </gazebo>
    <!--  link  -->
    <link name="left_back_roller_12">
        <collision>
            <geometry>
                <sphere radius="0.009" />
            </geometry>
        </collision>
        <inertial>
            <mass value="0.036" />
            <inertia ixx="3128e-9" ixy="0.0" ixz="0.0" iyy="3128e-9" iyz="0.0" izz="3128e-9" />
            <origin xyz="0 0 0" rpy="0 0 0" />
        </inertial>
    </link>
    <joint name="left_back_roller_12_joint" type="continuous">
        <origin rpy="0 0 0" xyz="-0.06799955665875124 0 -0.0002455488002028931" />
        <axis xyz="0.002553370907877698 0.7071067811865476 -0.7071021710453214" />
        <dynamics damping="0.0" friction="0.001" />
        <parent link="left_back_wheel" />
        <child link="left_back_roller_12" />
    </joint>
    <gazebo reference="left_back_roller_12">
        <mu1 value="2000.0" />
        <mu2 value="2000.0" />
        <kp value="1000000.0" />
        <kd value="100.0" />
        <material>Gazebo/Black</material>
    </gazebo>
    <!--  link  -->
    <link name="left_back_roller_13">
        <collision>
            <geometry>
                <sphere radius="0.009" />
            </geometry>
        </collision>
        <inertial>
            <mass value="0.036" />
            <inertia ixx="3128e-9" ixy="0.0" ixz="0.0" iyy="3128e-9" iyz="0.0" izz="3128e-9" />
            <origin xyz="0 0 0" rpy="0 0 0" />
        </inertial>
    </link>
    <joint name="left_back_roller_13_joint" type="continuous">
        <origin rpy="0 0 0" xyz="-0.06272152946616016 0 -0.026268036497340295" />
        <axis xyz="0.2731515696430154 0.7071067811865476 -0.6522179237046135" />
        <dynamics damping="0.0" friction="0.001" />
        <parent link="left_back_wheel" />
        <child link="left_back_roller_13" />
    </joint>
    <gazebo reference="left_back_roller_13">
        <mu1 value="2000.0" />
        <mu2 value="2000.0" />
        <kp value="1000000.0" />
        <kd value="100.0" />
        <material>Gazebo/Black</material>
    </gazebo>
    <!--  link  -->
    <link name="left_back_roller_14">
        <collision>
            <geometry>
                <sphere radius="0.009" />
            </geometry>
        </collision>
        <inertial>
            <mass value="0.036" />
            <inertia ixx="3128e-9" ixy="0.0" ixz="0.0" iyy="3128e-9" iyz="0.0" izz="3128e-9" />
            <origin xyz="0 0 0" rpy="0 0 0" />
        </inertial>
    </link>
    <joint name="left_back_roller_14_joint" type="continuous">
        <origin rpy="0 0 0" xyz="-0.04788026716028342 0 -0.04828540169305713" />
        <axis xyz="0.5021019848452515 0.7071067811865476 -0.49788914108911725" />
        <dynamics damping="0.0" friction="0.001" />
        <parent link="left_back_wheel" />
        <child link="left_back_roller_14" />
    </joint>
    <gazebo reference="left_back_roller_14">
        <mu1 value="2000.0" />
        <mu2 value="2000.0" />
        <kp value="1000000.0" />
        <kd value="100.0" />
        <material>Gazebo/Black</material>
    </gazebo>
    <!--  link  -->
    <link name="left_back_roller_15">
        <collision>
            <geometry>
                <sphere radius="0.009" />
            </geometry>
        </collision>
        <inertial>
            <mass value="0.036" />
            <inertia ixx="3128e-9" ixy="0.0" ixz="0.0" iyy="3128e-9" iyz="0.0" izz="3128e-9" />
            <origin xyz="0 0 0" rpy="0 0 0" />
        </inertial>
    </link>
    <joint name="left_back_roller_15_joint" type="continuous">
        <origin rpy="0 0 0" xyz="-0.025738636766479847 0 -0.06294062739918639" />
        <axis xyz="0.6544962418544192 0.7071067811865476 -0.2676465381775779" />
        <dynamics damping="0.0" friction="0.001" />
        <parent link="left_back_wheel" />
        <child link="left_back_roller_15" />
    </joint>
    <gazebo reference="left_back_roller_15">
        <mu1 value="2000.0" />
        <mu2 value="2000.0" />
        <kp value="1000000.0" />
        <kd value="100.0" />
        <material>Gazebo/Black</material>
    </gazebo>
    <!--  link  -->
    <link name="right_back_wheel">
        <visual>
            <geometry>
                <mesh filename="package://sp_description/meshes/common/mecanum_wheel/right_mecanum_wheel.STL" />
            </geometry>
        </visual>
        <inertial>
            <mass value="0.4235" />
            <inertia ixx="4.122e-4" ixy="0.0" ixz="0.0" iyy="7.398e-4" iyz="0.0" izz="4.122e-4" />
        </inertial>
    </link>
    <!--  joint  -->
    <joint name="right_back_wheel_joint" type="revolute">
        <axis xyz="0 1 0" />
        <origin rpy="0 0 0" xyz="-0.19152 -0.221 0.077" />
        <!--      limit not work while type="continuous"-->
        <limit effort="10" lower="-1e9" upper="1e9" velocity="70" />
        <dynamics damping="0.0" friction="0.05" />
        <parent link="base_link" />
        <child link="right_back_wheel" />
    </joint>
    <!--  link  -->
    <link name="right_back_roller_0">
        <collision>
            <geometry>
                <sphere radius="0.009" />
            </geometry>
        </collision>
        <inertial>
            <mass value="0.036" />
            <inertia ixx="3128e-9" ixy="0.0" ixz="0.0" iyy="3128e-9" iyz="0.0" izz="3128e-9" />
            <origin xyz="0 0 0" rpy="0 0 0" />
        </inertial>
    </link>
    <joint name="right_back_roller_0_joint" type="continuous">
        <origin rpy="0 0 0" xyz="4.163799117101001e-18 0 -0.068" />
        <axis xyz="0.7071067811865476 -0.7071067811865476 0.0" />
        <dynamics damping="0.0" friction="0.001" />
        <parent link="right_back_wheel" />
        <child link="right_back_roller_0" />
    </joint>
    <gazebo reference="right_back_roller_0">
        <mu1 value="2000.0" />
        <mu2 value="2000.0" />
        <kp value="1000000.0" />
        <kd value="100.0" />
        <material>Gazebo/Black</material>
    </gazebo>
    <!--  link  -->
    <link name="right_back_roller_1">
        <collision>
            <geometry>
                <sphere radius="0.009" />
            </geometry>
        </collision>
        <inertial>
            <mass value="0.036" />
            <inertia ixx="3128e-9" ixy="0.0" ixz="0.0" iyy="3128e-9" iyz="0.0" izz="3128e-9" />
            <origin xyz="0 0 0" rpy="0 0 0" />
        </inertial>
    </link>
    <joint name="right_back_roller_1_joint" type="continuous">
        <origin rpy="0 0 0" xyz="0.026041377055996056 0 -0.06281597472798972" />
        <axis xyz="0.653200024955946 -0.7071067811865476 0.27079462217250855" />
        <dynamics damping="0.0" friction="0.001" />
        <parent link="right_back_wheel" />
        <child link="right_back_roller_1" />
    </joint>
    <gazebo reference="right_back_roller_1">
        <mu1 value="2000.0" />
        <mu2 value="2000.0" />
        <kp value="1000000.0" />
        <kd value="100.0" />
        <material>Gazebo/Black</material>
    </gazebo>
    <!--  link  -->
    <link name="right_back_roller_2">
        <collision>
            <geometry>
                <sphere radius="0.009" />
            </geometry>
        </collision>
        <inertial>
            <mass value="0.036" />
            <inertia ixx="3128e-9" ixy="0.0" ixz="0.0" iyy="3128e-9" iyz="0.0" izz="3128e-9" />
            <origin xyz="0 0 0" rpy="0 0 0" />
        </inertial>
    </link>
    <joint name="right_back_roller_2_joint" type="continuous">
        <origin rpy="0 0 0" xyz="0.04811219067739703 0 -0.048054314147865956" />
        <axis xyz="0.49969899116506866 -0.7071067811865476 0.5003008277312888" />
        <dynamics damping="0.0" friction="0.001" />
        <parent link="right_back_wheel" />
        <child link="right_back_roller_2" />
    </joint>
    <gazebo reference="right_back_roller_2">
        <mu1 value="2000.0" />
        <mu2 value="2000.0" />
        <kp value="1000000.0" />
        <kd value="100.0" />
        <material>Gazebo/Black</material>
    </gazebo>
    <!--  link  -->
    <link name="right_back_roller_3">
        <collision>
            <geometry>
                <sphere radius="0.009" />
            </geometry>
        </collision>
        <inertial>
            <mass value="0.036" />
            <inertia ixx="3128e-9" ixy="0.0" ixz="0.0" iyy="3128e-9" iyz="0.0" izz="3128e-9" />
            <origin xyz="0 0 0" rpy="0 0 0" />
        </inertial>
    </link>
    <joint name="right_back_roller_3_joint" type="continuous">
        <origin rpy="0 0 0" xyz="0.06284727452340379 0 -0.025965748303869884" />
        <axis xyz="0.2700081868271984 -0.7071067811865476 0.6535254999204613" />
        <dynamics damping="0.0" friction="0.001" />
        <parent link="right_back_wheel" />
        <child link="right_back_roller_3" />
    </joint>
    <gazebo reference="right_back_roller_3">
        <mu1 value="2000.0" />
        <mu2 value="2000.0" />
        <kp value="1000000.0" />
        <kd value="100.0" />
        <material>Gazebo/Black</material>
    </gazebo>
    <!--  link  -->
    <link name="right_back_roller_4">
        <collision>
            <geometry>
                <sphere radius="0.009" />
            </geometry>
        </collision>
        <inertial>
            <mass value="0.036" />
            <inertia ixx="3128e-9" ixy="0.0" ixz="0.0" iyy="3128e-9" iyz="0.0" izz="3128e-9" />
            <origin xyz="0 0 0" rpy="0 0 0" />
        </inertial>
    </link>
    <joint name="right_back_roller_4_joint" type="continuous">
        <origin rpy="0 0 0" xyz="0.06799995073981367 0 8.184975818264867e-05" />
        <axis xyz="-0.0008511252801386329 -0.7071067811865476 0.7071062689481388" />
        <dynamics damping="0.0" friction="0.001" />
        <parent link="right_back_wheel" />
        <child link="right_back_roller_4" />
    </joint>
    <gazebo reference="right_back_roller_4">
        <mu1 value="2000.0" />
        <mu2 value="2000.0" />
        <kp value="1000000.0" />
        <kd value="100.0" />
        <material>Gazebo/Black</material>
    </gazebo>
    <!--  link  -->
    <link name="right_back_roller_5">
        <collision>
            <geometry>
                <sphere radius="0.009" />
            </geometry>
        </collision>
        <inertial>
            <mass value="0.036" />
            <inertia ixx="3128e-9" ixy="0.0" ixz="0.0" iyy="3128e-9" iyz="0.0" izz="3128e-9" />
            <origin xyz="0 0 0" rpy="0 0 0" />
        </inertial>
    </link>
    <joint name="right_back_roller_5_joint" type="continuous">
        <origin rpy="0 0 0" xyz="0.06278458392296919 0 0.026116968078619688" />
        <axis xyz="-0.27158066518271434 -0.7071067811865476 0.6528736036162853" />
        <dynamics damping="0.0" friction="0.001" />
        <parent link="right_back_wheel" />
        <child link="right_back_roller_5" />
    </joint>
    <gazebo reference="right_back_roller_5">
        <mu1 value="2000.0" />
        <mu2 value="2000.0" />
        <kp value="1000000.0" />
        <kd value="100.0" />
        <material>Gazebo/Black</material>
    </gazebo>
    <!--  link  -->
    <link name="right_back_roller_6">
        <collision>
            <geometry>
                <sphere radius="0.009" />
            </geometry>
        </collision>
        <inertial>
            <mass value="0.036" />
            <inertia ixx="3128e-9" ixy="0.0" ixz="0.0" iyy="3128e-9" iyz="0.0" izz="3128e-9" />
            <origin xyz="0 0 0" rpy="0 0 0" />
        </inertial>
    </link>
    <joint name="right_back_roller_6_joint" type="continuous">
        <origin rpy="0 0 0" xyz="0.0479963679958505 0 0.04816999750059053" />
        <axis xyz="-0.5009019394471561 -0.7071067811865476 0.499096430620454" />
        <dynamics damping="0.0" friction="0.001" />
        <parent link="right_back_wheel" />
        <child link="right_back_roller_6" />
    </joint>
    <gazebo reference="right_back_roller_6">
        <mu1 value="2000.0" />
        <mu2 value="2000.0" />
        <kp value="1000000.0" />
        <kd value="100.0" />
        <material>Gazebo/Black</material>
    </gazebo>
    <!--  link  -->
    <link name="right_back_roller_7">
        <collision>
            <geometry>
                <sphere radius="0.009" />
            </geometry>
        </collision>
        <inertial>
            <mass value="0.036" />
            <inertia ixx="3128e-9" ixy="0.0" ixz="0.0" iyy="3128e-9" iyz="0.0" izz="3128e-9" />
            <origin xyz="0 0 0" rpy="0 0 0" />
        </inertial>
    </link>
    <joint name="right_back_roller_7_joint" type="continuous">
        <origin rpy="0 0 0" xyz="0.0258900819318143 0 0.06287848326386335" />
        <axis xyz="-0.6538500280382736 -0.7071067811865476 0.2692213602861942" />
        <dynamics damping="0.0" friction="0.001" />
        <parent link="right_back_wheel" />
        <child link="right_back_roller_7" />
    </joint>
    <gazebo reference="right_back_roller_7">
        <mu1 value="2000.0" />
        <mu2 value="2000.0" />
        <kp value="1000000.0" />
        <kd value="100.0" />
        <material>Gazebo/Black</material>
    </gazebo>
    <!--  link  -->
    <link name="right_back_roller_8">
        <collision>
            <geometry>
                <sphere radius="0.009" />
            </geometry>
        </collision>
        <inertial>
            <mass value="0.036" />
            <inertia ixx="3128e-9" ixy="0.0" ixz="0.0" iyy="3128e-9" iyz="0.0" izz="3128e-9" />
            <origin xyz="0 0 0" rpy="0 0 0" />
        </inertial>
    </link>
    <joint name="right_back_roller_8_joint" type="continuous">
        <origin rpy="0 0 0" xyz="-0.00016369939777898906 0 0.06799980295932605" />
        <axis xyz="-0.7071047322336546 -0.7071067811865476 -0.0017022493271422689" />
        <dynamics damping="0.0" friction="0.001" />
        <parent link="right_back_wheel" />
        <child link="right_back_roller_8" />
    </joint>
    <gazebo reference="right_back_roller_8">
        <mu1 value="2000.0" />
        <mu2 value="2000.0" />
        <kp value="1000000.0" />
        <kd value="100.0" />
        <material>Gazebo/Black</material>
    </gazebo>
    <!--  link  -->
    <link name="right_back_roller_9">
        <collision>
            <geometry>
                <sphere radius="0.009" />
            </geometry>
        </collision>
        <inertial>
            <mass value="0.036" />
            <inertia ixx="3128e-9" ixy="0.0" ixz="0.0" iyy="3128e-9" iyz="0.0" izz="3128e-9" />
            <origin xyz="0 0 0" rpy="0 0 0" />
        </inertial>
    </link>
    <joint name="right_back_roller_9_joint" type="continuous">
        <origin rpy="0 0 0" xyz="-0.026192521262222306 0 0.06275310215382211" />
        <axis xyz="-0.6525462363744081 -0.7071067811865476 -0.2723663147189738" />
        <dynamics damping="0.0" friction="0.001" />
        <parent link="right_back_wheel" />
        <child link="right_back_roller_9" />
    </joint>
    <gazebo reference="right_back_roller_9">
        <mu1 value="2000.0" />
        <mu2 value="2000.0" />
        <kp value="1000000.0" />
        <kd value="100.0" />
        <material>Gazebo/Black</material>
    </gazebo>
    <!--  link  -->
    <link name="right_back_roller_10">
        <collision>
            <geometry>
                <sphere radius="0.009" />
            </geometry>
        </collision>
        <inertial>
            <mass value="0.036" />
            <inertia ixx="3128e-9" ixy="0.0" ixz="0.0" iyy="3128e-9" iyz="0.0" izz="3128e-9" />
            <origin xyz="0 0 0" rpy="0 0 0" />
        </inertial>
    </link>
    <joint name="right_back_roller_10_joint" type="continuous">
        <origin rpy="0 0 0" xyz="-0.048227734533694264 0 0.04793835230530472" />
        <axis xyz="-0.49849314697045194 -0.7071067811865476 -0.5015023254417625" />
        <dynamics damping="0.0" friction="0.001" />
        <parent link="right_back_wheel" />
        <child link="right_back_roller_10" />
    </joint>
    <gazebo reference="right_back_roller_10">
        <mu1 value="2000.0" />
        <mu2 value="2000.0" />
        <kp value="1000000.0" />
        <kd value="100.0" />
        <material>Gazebo/Black</material>
    </gazebo>
    <!--  link  -->
    <link name="right_back_roller_11">
        <collision>
            <geometry>
                <sphere radius="0.009" />
            </geometry>
        </collision>
        <inertial>
            <mass value="0.036" />
            <inertia ixx="3128e-9" ixy="0.0" ixz="0.0" iyy="3128e-9" iyz="0.0" izz="3128e-9" />
            <origin xyz="0 0 0" rpy="0 0 0" />
        </inertial>
    </link>
    <joint name="right_back_roller_11_joint" type="continuous">
        <origin rpy="0 0 0" xyz="-0.06290960090415226 0 0.02581437804945697" />
        <axis xyz="-0.2684341436894733 -0.7071067811865476 -0.6541736088391974" />
        <dynamics damping="0.0" friction="0.001" />
        <parent link="right_back_wheel" />
        <child link="right_back_roller_11" />
    </joint>
    <gazebo reference="right_back_roller_11">
        <mu1 value="2000.0" />
        <mu2 value="2000.0" />
        <kp value="1000000.0" />
        <kd value="100.0" />
        <material>Gazebo/Black</material>
    </gazebo>
    <!--  link  -->
    <link name="right_back_roller_12">
        <collision>
            <geometry>
                <sphere radius="0.009" />
            </geometry>
        </collision>
        <inertial>
            <mass value="0.036" />
            <inertia ixx="3128e-9" ixy="0.0" ixz="0.0" iyy="3128e-9" iyz="0.0" izz="3128e-9" />
            <origin xyz="0 0 0" rpy="0 0 0" />
        </inertial>
    </link>
    <joint name="right_back_roller_12_joint" type="continuous">
        <origin rpy="0 0 0" xyz="-0.06799955665875124 0 -0.0002455488002028931" />
        <axis xyz="0.002553370907877698 -0.7071067811865476 -0.7071021710453214" />
        <dynamics damping="0.0" friction="0.001" />
        <parent link="right_back_wheel" />
        <child link="right_back_roller_12" />
    </joint>
    <gazebo reference="right_back_roller_12">
        <mu1 value="2000.0" />
        <mu2 value="2000.0" />
        <kp value="1000000.0" />
        <kd value="100.0" />
        <material>Gazebo/Black</material>
    </gazebo>
    <!--  link  -->
    <link name="right_back_roller_13">
        <collision>
            <geometry>
                <sphere radius="0.009" />
            </geometry>
        </collision>
        <inertial>
            <mass value="0.036" />
            <inertia ixx="3128e-9" ixy="0.0" ixz="0.0" iyy="3128e-9" iyz="0.0" izz="3128e-9" />
            <origin xyz="0 0 0" rpy="0 0 0" />
        </inertial>
    </link>
    <joint name="right_back_roller_13_joint" type="continuous">
        <origin rpy="0 0 0" xyz="-0.06272152946616016 0 -0.026268036497340295" />
        <axis xyz="0.2731515696430154 -0.7071067811865476 -0.6522179237046135" />
        <dynamics damping="0.0" friction="0.001" />
        <parent link="right_back_wheel" />
        <child link="right_back_roller_13" />
    </joint>
    <gazebo reference="right_back_roller_13">
        <mu1 value="2000.0" />
        <mu2 value="2000.0" />
        <kp value="1000000.0" />
        <kd value="100.0" />
        <material>Gazebo/Black</material>
    </gazebo>
    <!--  link  -->
    <link name="right_back_roller_14">
        <collision>
            <geometry>
                <sphere radius="0.009" />
            </geometry>
        </collision>
        <inertial>
            <mass value="0.036" />
            <inertia ixx="3128e-9" ixy="0.0" ixz="0.0" iyy="3128e-9" iyz="0.0" izz="3128e-9" />
            <origin xyz="0 0 0" rpy="0 0 0" />
        </inertial>
    </link>
    <joint name="right_back_roller_14_joint" type="continuous">
        <origin rpy="0 0 0" xyz="-0.04788026716028342 0 -0.04828540169305713" />
        <axis xyz="0.5021019848452515 -0.7071067811865476 -0.49788914108911725" />
        <dynamics damping="0.0" friction="0.001" />
        <parent link="right_back_wheel" />
        <child link="right_back_roller_14" />
    </joint>
    <gazebo reference="right_back_roller_14">
        <mu1 value="2000.0" />
        <mu2 value="2000.0" />
        <kp value="1000000.0" />
        <kd value="100.0" />
        <material>Gazebo/Black</material>
    </gazebo>
    <!--  link  -->
    <link name="right_back_roller_15">
        <collision>
            <geometry>
                <sphere radius="0.009" />
            </geometry>
        </collision>
        <inertial>
            <mass value="0.036" />
            <inertia ixx="3128e-9" ixy="0.0" ixz="0.0" iyy="3128e-9" iyz="0.0" izz="3128e-9" />
            <origin xyz="0 0 0" rpy="0 0 0" />
        </inertial>
    </link>
    <joint name="right_back_roller_15_joint" type="continuous">
        <origin rpy="0 0 0" xyz="-0.025738636766479847 0 -0.06294062739918639" />
        <axis xyz="0.6544962418544192 -0.7071067811865476 -0.2676465381775779" />
        <dynamics damping="0.0" friction="0.001" />
        <parent link="right_back_wheel" />
        <child link="right_back_roller_15" />
    </joint>
    <gazebo reference="right_back_roller_15">
        <mu1 value="2000.0" />
        <mu2 value="2000.0" />
        <kp value="1000000.0" />
        <kd value="100.0" />
        <material>Gazebo/Black</material>
    </gazebo>
    <transmission name="left_front_wheel_trans">
        <type>transmission_interface/SimpleTransmission</type>
        <actuator name="left_front_wheel_motor">
            <hardwareInterface>hardware_interface/EffortJointInterface</hardwareInterface>
            <mechanicalReduction>19.2032</mechanicalReduction>
        </actuator>
        <joint name="left_front_wheel_joint">
            <hardwareInterface>hardware_interface/EffortJointInterface</hardwareInterface>
        </joint>
    </transmission>
    <transmission name="right_front_wheel_trans">
        <type>transmission_interface/SimpleTransmission</type>
        <actuator name="right_front_wheel_motor">
            <hardwareInterface>hardware_interface/EffortJointInterface</hardwareInterface>
            <mechanicalReduction>-19.2032</mechanicalReduction>
        </actuator>
        <joint name="right_front_wheel_joint">
            <hardwareInterface>hardware_interface/EffortJointInterface</hardwareInterface>
        </joint>
    </transmission>
    <transmission name="left_back_wheel_trans">
        <type>transmission_interface/SimpleTransmission</type>
        <actuator name="left_back_wheel_motor">
            <hardwareInterface>hardware_interface/EffortJointInterface</hardwareInterface>
            <mechanicalReduction>19.2032</mechanicalReduction>
        </actuator>
        <joint name="left_back_wheel_joint">
            <hardwareInterface>hardware_interface/EffortJointInterface</hardwareInterface>
        </joint>
    </transmission>
    <transmission name="right_back_wheel_trans">
        <type>transmission_interface/SimpleTransmission</type>
        <actuator name="right_back_wheel_motor">
            <hardwareInterface>hardware_interface/EffortJointInterface</hardwareInterface>
            <mechanicalReduction>-19.2032</mechanicalReduction>
        </actuator>
        <joint name="right_back_wheel_joint">
            <hardwareInterface>hardware_interface/EffortJointInterface</hardwareInterface>
        </joint>
    </transmission>
    <joint name="joint_arm2body" type="fixed">
        <axis xyz="0 0 1" />
        <origin rpy="0 0 -1.57" xyz="-0.006 -0 0.12028" />
        <parent link="base_link" />
        <child link="arm_base_link" />
    </joint>
    <!--在机器人模型的urdf/xacro文件中添加gazebo_ros_control插件-->
    <gazebo>
        <plugin filename="libgazebo_ros_control.so" name="gazebo_ros_control">
            <robotNamespace>/</robotNamespace>
        </plugin>
        <plugin filename="libchassis_controller.so" name="chassis_controller">
            <robotNamespace>/</robotNamespace>
        </plugin>
    </gazebo>
    <transmission name="trans_left_front_roller_0_joint">
        <type>transmission_interface/SimpleTransmission</type>
        <joint name="left_front_roller_0_joint">
            <hardwareInterface>hardware_interface/EffortJointInterface</hardwareInterface>
        </joint>
        <actuator name="left_front_roller_0_joint_motor">
            <hardwareInterface>hardware_interface/EffortJointInterface</hardwareInterface>
            <mechanicalReduction>1</mechanicalReduction>
        </actuator>
    </transmission>
    <transmission name="trans_left_front_roller_1_joint">
        <type>transmission_interface/SimpleTransmission</type>
        <joint name="left_front_roller_1_joint">
            <hardwareInterface>hardware_interface/EffortJointInterface</hardwareInterface>
        </joint>
        <actuator name="left_front_roller_1_joint_motor">
            <hardwareInterface>hardware_interface/EffortJointInterface</hardwareInterface>
            <mechanicalReduction>1</mechanicalReduction>
        </actuator>
    </transmission>
    <transmission name="trans_left_front_roller_2_joint">
        <type>transmission_interface/SimpleTransmission</type>
        <joint name="left_front_roller_2_joint">
            <hardwareInterface>hardware_interface/EffortJointInterface</hardwareInterface>
        </joint>
        <actuator name="left_front_roller_2_joint_motor">
            <hardwareInterface>hardware_interface/EffortJointInterface</hardwareInterface>
            <mechanicalReduction>1</mechanicalReduction>
        </actuator>
    </transmission>
    <transmission name="trans_left_front_roller_3_joint">
        <type>transmission_interface/SimpleTransmission</type>
        <joint name="left_front_roller_3_joint">
            <hardwareInterface>hardware_interface/EffortJointInterface</hardwareInterface>
        </joint>
        <actuator name="left_front_roller_3_joint_motor">
            <hardwareInterface>hardware_interface/EffortJointInterface</hardwareInterface>
            <mechanicalReduction>1</mechanicalReduction>
        </actuator>
    </transmission>
    <transmission name="trans_left_front_roller_4_joint">
        <type>transmission_interface/SimpleTransmission</type>
        <joint name="left_front_roller_4_joint">
            <hardwareInterface>hardware_interface/EffortJointInterface</hardwareInterface>
        </joint>
        <actuator name="left_front_roller_4_joint_motor">
            <hardwareInterface>hardware_interface/EffortJointInterface</hardwareInterface>
            <mechanicalReduction>1</mechanicalReduction>
        </actuator>
    </transmission>
    <transmission name="trans_left_front_roller_5_joint">
        <type>transmission_interface/SimpleTransmission</type>
        <joint name="left_front_roller_5_joint">
            <hardwareInterface>hardware_interface/EffortJointInterface</hardwareInterface>
        </joint>
        <actuator name="left_front_roller_5_joint_motor">
            <hardwareInterface>hardware_interface/EffortJointInterface</hardwareInterface>
            <mechanicalReduction>1</mechanicalReduction>
        </actuator>
    </transmission>
    <transmission name="trans_left_front_roller_6_joint">
        <type>transmission_interface/SimpleTransmission</type>
        <joint name="left_front_roller_6_joint">
            <hardwareInterface>hardware_interface/EffortJointInterface</hardwareInterface>
        </joint>
        <actuator name="left_front_roller_6_joint_motor">
            <hardwareInterface>hardware_interface/EffortJointInterface</hardwareInterface>
            <mechanicalReduction>1</mechanicalReduction>
        </actuator>
    </transmission>
    <transmission name="trans_left_front_roller_7_joint">
        <type>transmission_interface/SimpleTransmission</type>
        <joint name="left_front_roller_7_joint">
            <hardwareInterface>hardware_interface/EffortJointInterface</hardwareInterface>
        </joint>
        <actuator name="left_front_roller_7_joint_motor">
            <hardwareInterface>hardware_interface/EffortJointInterface</hardwareInterface>
            <mechanicalReduction>1</mechanicalReduction>
        </actuator>
    </transmission>
    <transmission name="trans_left_front_roller_8_joint">
        <type>transmission_interface/SimpleTransmission</type>
        <joint name="left_front_roller_8_joint">
            <hardwareInterface>hardware_interface/EffortJointInterface</hardwareInterface>
        </joint>
        <actuator name="left_front_roller_8_joint_motor">
            <hardwareInterface>hardware_interface/EffortJointInterface</hardwareInterface>
            <mechanicalReduction>1</mechanicalReduction>
        </actuator>
    </transmission>
    <transmission name="trans_left_front_roller_9_joint">
        <type>transmission_interface/SimpleTransmission</type>
        <joint name="left_front_roller_9_joint">
            <hardwareInterface>hardware_interface/EffortJointInterface</hardwareInterface>
        </joint>
        <actuator name="left_front_roller_9_joint_motor">
            <hardwareInterface>hardware_interface/EffortJointInterface</hardwareInterface>
            <mechanicalReduction>1</mechanicalReduction>
        </actuator>
    </transmission>
    <transmission name="trans_left_front_roller_10_joint">
        <type>transmission_interface/SimpleTransmission</type>
        <joint name="left_front_roller_10_joint">
            <hardwareInterface>hardware_interface/EffortJointInterface</hardwareInterface>
        </joint>
        <actuator name="left_front_roller_10_joint_motor">
            <hardwareInterface>hardware_interface/EffortJointInterface</hardwareInterface>
            <mechanicalReduction>1</mechanicalReduction>
        </actuator>
    </transmission>
    <transmission name="trans_left_front_roller_11_joint">
        <type>transmission_interface/SimpleTransmission</type>
        <joint name="left_front_roller_11_joint">
            <hardwareInterface>hardware_interface/EffortJointInterface</hardwareInterface>
        </joint>
        <actuator name="left_front_roller_11_joint_motor">
            <hardwareInterface>hardware_interface/EffortJointInterface</hardwareInterface>
            <mechanicalReduction>1</mechanicalReduction>
        </actuator>
    </transmission>
    <transmission name="trans_left_front_roller_12_joint">
        <type>transmission_interface/SimpleTransmission</type>
        <joint name="left_front_roller_12_joint">
            <hardwareInterface>hardware_interface/EffortJointInterface</hardwareInterface>
        </joint>
        <actuator name="left_front_roller_12_joint_motor">
            <hardwareInterface>hardware_interface/EffortJointInterface</hardwareInterface>
            <mechanicalReduction>1</mechanicalReduction>
        </actuator>
    </transmission>
    <transmission name="trans_left_front_roller_13_joint">
        <type>transmission_interface/SimpleTransmission</type>
        <joint name="left_front_roller_13_joint">
            <hardwareInterface>hardware_interface/EffortJointInterface</hardwareInterface>
        </joint>
        <actuator name="left_front_roller_13_joint_motor">
            <hardwareInterface>hardware_interface/EffortJointInterface</hardwareInterface>
            <mechanicalReduction>1</mechanicalReduction>
        </actuator>
    </transmission>
    <transmission name="trans_left_front_roller_14_joint">
        <type>transmission_interface/SimpleTransmission</type>
        <joint name="left_front_roller_14_joint">
            <hardwareInterface>hardware_interface/EffortJointInterface</hardwareInterface>
        </joint>
        <actuator name="left_front_roller_14_joint_motor">
            <hardwareInterface>hardware_interface/EffortJointInterface</hardwareInterface>
            <mechanicalReduction>1</mechanicalReduction>
        </actuator>
    </transmission>
    <transmission name="trans_left_front_roller_15_joint">
        <type>transmission_interface/SimpleTransmission</type>
        <joint name="left_front_roller_15_joint">
            <hardwareInterface>hardware_interface/EffortJointInterface</hardwareInterface>
        </joint>
        <actuator name="left_front_roller_15_joint_motor">
            <hardwareInterface>hardware_interface/EffortJointInterface</hardwareInterface>
            <mechanicalReduction>1</mechanicalReduction>
        </actuator>
    </transmission>
    <transmission name="trans_right_front_roller_0_joint">
        <type>transmission_interface/SimpleTransmission</type>
        <joint name="right_front_roller_0_joint">
            <hardwareInterface>hardware_interface/EffortJointInterface</hardwareInterface>
        </joint>
        <actuator name="right_front_roller_0_joint_motor">
            <hardwareInterface>hardware_interface/EffortJointInterface</hardwareInterface>
            <mechanicalReduction>1</mechanicalReduction>
        </actuator>
    </transmission>
    <transmission name="trans_right_front_roller_1_joint">
        <type>transmission_interface/SimpleTransmission</type>
        <joint name="right_front_roller_1_joint">
            <hardwareInterface>hardware_interface/EffortJointInterface</hardwareInterface>
        </joint>
        <actuator name="right_front_roller_1_joint_motor">
            <hardwareInterface>hardware_interface/EffortJointInterface</hardwareInterface>
            <mechanicalReduction>1</mechanicalReduction>
        </actuator>
    </transmission>
    <transmission name="trans_right_front_roller_2_joint">
        <type>transmission_interface/SimpleTransmission</type>
        <joint name="right_front_roller_2_joint">
            <hardwareInterface>hardware_interface/EffortJointInterface</hardwareInterface>
        </joint>
        <actuator name="right_front_roller_2_joint_motor">
            <hardwareInterface>hardware_interface/EffortJointInterface</hardwareInterface>
            <mechanicalReduction>1</mechanicalReduction>
        </actuator>
    </transmission>
    <transmission name="trans_right_front_roller_3_joint">
        <type>transmission_interface/SimpleTransmission</type>
        <joint name="right_front_roller_3_joint">
            <hardwareInterface>hardware_interface/EffortJointInterface</hardwareInterface>
        </joint>
        <actuator name="right_front_roller_3_joint_motor">
            <hardwareInterface>hardware_interface/EffortJointInterface</hardwareInterface>
            <mechanicalReduction>1</mechanicalReduction>
        </actuator>
    </transmission>
    <transmission name="trans_right_front_roller_4_joint">
        <type>transmission_interface/SimpleTransmission</type>
        <joint name="right_front_roller_4_joint">
            <hardwareInterface>hardware_interface/EffortJointInterface</hardwareInterface>
        </joint>
        <actuator name="right_front_roller_4_joint_motor">
            <hardwareInterface>hardware_interface/EffortJointInterface</hardwareInterface>
            <mechanicalReduction>1</mechanicalReduction>
        </actuator>
    </transmission>
    <transmission name="trans_right_front_roller_5_joint">
        <type>transmission_interface/SimpleTransmission</type>
        <joint name="right_front_roller_5_joint">
            <hardwareInterface>hardware_interface/EffortJointInterface</hardwareInterface>
        </joint>
        <actuator name="right_front_roller_5_joint_motor">
            <hardwareInterface>hardware_interface/EffortJointInterface</hardwareInterface>
            <mechanicalReduction>1</mechanicalReduction>
        </actuator>
    </transmission>
    <transmission name="trans_right_front_roller_6_joint">
        <type>transmission_interface/SimpleTransmission</type>
        <joint name="right_front_roller_6_joint">
            <hardwareInterface>hardware_interface/EffortJointInterface</hardwareInterface>
        </joint>
        <actuator name="right_front_roller_6_joint_motor">
            <hardwareInterface>hardware_interface/EffortJointInterface</hardwareInterface>
            <mechanicalReduction>1</mechanicalReduction>
        </actuator>
    </transmission>
    <transmission name="trans_right_front_roller_7_joint">
        <type>transmission_interface/SimpleTransmission</type>
        <joint name="right_front_roller_7_joint">
            <hardwareInterface>hardware_interface/EffortJointInterface</hardwareInterface>
        </joint>
        <actuator name="right_front_roller_7_joint_motor">
            <hardwareInterface>hardware_interface/EffortJointInterface</hardwareInterface>
            <mechanicalReduction>1</mechanicalReduction>
        </actuator>
    </transmission>
    <transmission name="trans_right_front_roller_8_joint">
        <type>transmission_interface/SimpleTransmission</type>
        <joint name="right_front_roller_8_joint">
            <hardwareInterface>hardware_interface/EffortJointInterface</hardwareInterface>
        </joint>
        <actuator name="right_front_roller_8_joint_motor">
            <hardwareInterface>hardware_interface/EffortJointInterface</hardwareInterface>
            <mechanicalReduction>1</mechanicalReduction>
        </actuator>
    </transmission>
    <transmission name="trans_right_front_roller_9_joint">
        <type>transmission_interface/SimpleTransmission</type>
        <joint name="right_front_roller_9_joint">
            <hardwareInterface>hardware_interface/EffortJointInterface</hardwareInterface>
        </joint>
        <actuator name="right_front_roller_9_joint_motor">
            <hardwareInterface>hardware_interface/EffortJointInterface</hardwareInterface>
            <mechanicalReduction>1</mechanicalReduction>
        </actuator>
    </transmission>
    <transmission name="trans_right_front_roller_10_joint">
        <type>transmission_interface/SimpleTransmission</type>
        <joint name="right_front_roller_10_joint">
            <hardwareInterface>hardware_interface/EffortJointInterface</hardwareInterface>
        </joint>
        <actuator name="right_front_roller_10_joint_motor">
            <hardwareInterface>hardware_interface/EffortJointInterface</hardwareInterface>
            <mechanicalReduction>1</mechanicalReduction>
        </actuator>
    </transmission>
    <transmission name="trans_right_front_roller_11_joint">
        <type>transmission_interface/SimpleTransmission</type>
        <joint name="right_front_roller_11_joint">
            <hardwareInterface>hardware_interface/EffortJointInterface</hardwareInterface>
        </joint>
        <actuator name="right_front_roller_11_joint_motor">
            <hardwareInterface>hardware_interface/EffortJointInterface</hardwareInterface>
            <mechanicalReduction>1</mechanicalReduction>
        </actuator>
    </transmission>
    <transmission name="trans_right_front_roller_12_joint">
        <type>transmission_interface/SimpleTransmission</type>
        <joint name="right_front_roller_12_joint">
            <hardwareInterface>hardware_interface/EffortJointInterface</hardwareInterface>
        </joint>
        <actuator name="right_front_roller_12_joint_motor">
            <hardwareInterface>hardware_interface/EffortJointInterface</hardwareInterface>
            <mechanicalReduction>1</mechanicalReduction>
        </actuator>
    </transmission>
    <transmission name="trans_right_front_roller_13_joint">
        <type>transmission_interface/SimpleTransmission</type>
        <joint name="right_front_roller_13_joint">
            <hardwareInterface>hardware_interface/EffortJointInterface</hardwareInterface>
        </joint>
        <actuator name="right_front_roller_13_joint_motor">
            <hardwareInterface>hardware_interface/EffortJointInterface</hardwareInterface>
            <mechanicalReduction>1</mechanicalReduction>
        </actuator>
    </transmission>
    <transmission name="trans_right_front_roller_14_joint">
        <type>transmission_interface/SimpleTransmission</type>
        <joint name="right_front_roller_14_joint">
            <hardwareInterface>hardware_interface/EffortJointInterface</hardwareInterface>
        </joint>
        <actuator name="right_front_roller_14_joint_motor">
            <hardwareInterface>hardware_interface/EffortJointInterface</hardwareInterface>
            <mechanicalReduction>1</mechanicalReduction>
        </actuator>
    </transmission>
    <transmission name="trans_right_front_roller_15_joint">
        <type>transmission_interface/SimpleTransmission</type>
        <joint name="right_front_roller_15_joint">
            <hardwareInterface>hardware_interface/EffortJointInterface</hardwareInterface>
        </joint>
        <actuator name="right_front_roller_15_joint_motor">
            <hardwareInterface>hardware_interface/EffortJointInterface</hardwareInterface>
            <mechanicalReduction>1</mechanicalReduction>
        </actuator>
    </transmission>
    <transmission name="trans_left_back_roller_0_joint">
        <type>transmission_interface/SimpleTransmission</type>
        <joint name="left_back_roller_0_joint">
            <hardwareInterface>hardware_interface/EffortJointInterface</hardwareInterface>
        </joint>
        <actuator name="left_back_roller_0_joint_motor">
            <hardwareInterface>hardware_interface/EffortJointInterface</hardwareInterface>
            <mechanicalReduction>1</mechanicalReduction>
        </actuator>
    </transmission>
    <transmission name="trans_left_back_roller_1_joint">
        <type>transmission_interface/SimpleTransmission</type>
        <joint name="left_back_roller_1_joint">
            <hardwareInterface>hardware_interface/EffortJointInterface</hardwareInterface>
        </joint>
        <actuator name="left_back_roller_1_joint_motor">
            <hardwareInterface>hardware_interface/EffortJointInterface</hardwareInterface>
            <mechanicalReduction>1</mechanicalReduction>
        </actuator>
    </transmission>
    <transmission name="trans_left_back_roller_2_joint">
        <type>transmission_interface/SimpleTransmission</type>
        <joint name="left_back_roller_2_joint">
            <hardwareInterface>hardware_interface/EffortJointInterface</hardwareInterface>
        </joint>
        <actuator name="left_back_roller_2_joint_motor">
            <hardwareInterface>hardware_interface/EffortJointInterface</hardwareInterface>
            <mechanicalReduction>1</mechanicalReduction>
        </actuator>
    </transmission>
    <transmission name="trans_left_back_roller_3_joint">
        <type>transmission_interface/SimpleTransmission</type>
        <joint name="left_back_roller_3_joint">
            <hardwareInterface>hardware_interface/EffortJointInterface</hardwareInterface>
        </joint>
        <actuator name="left_back_roller_3_joint_motor">
            <hardwareInterface>hardware_interface/EffortJointInterface</hardwareInterface>
            <mechanicalReduction>1</mechanicalReduction>
        </actuator>
    </transmission>
    <transmission name="trans_left_back_roller_4_joint">
        <type>transmission_interface/SimpleTransmission</type>
        <joint name="left_back_roller_4_joint">
            <hardwareInterface>hardware_interface/EffortJointInterface</hardwareInterface>
        </joint>
        <actuator name="left_back_roller_4_joint_motor">
            <hardwareInterface>hardware_interface/EffortJointInterface</hardwareInterface>
            <mechanicalReduction>1</mechanicalReduction>
        </actuator>
    </transmission>
    <transmission name="trans_left_back_roller_5_joint">
        <type>transmission_interface/SimpleTransmission</type>
        <joint name="left_back_roller_5_joint">
            <hardwareInterface>hardware_interface/EffortJointInterface</hardwareInterface>
        </joint>
        <actuator name="left_back_roller_5_joint_motor">
            <hardwareInterface>hardware_interface/EffortJointInterface</hardwareInterface>
            <mechanicalReduction>1</mechanicalReduction>
        </actuator>
    </transmission>
    <transmission name="trans_left_back_roller_6_joint">
        <type>transmission_interface/SimpleTransmission</type>
        <joint name="left_back_roller_6_joint">
            <hardwareInterface>hardware_interface/EffortJointInterface</hardwareInterface>
        </joint>
        <actuator name="left_back_roller_6_joint_motor">
            <hardwareInterface>hardware_interface/EffortJointInterface</hardwareInterface>
            <mechanicalReduction>1</mechanicalReduction>
        </actuator>
    </transmission>
    <transmission name="trans_left_back_roller_7_joint">
        <type>transmission_interface/SimpleTransmission</type>
        <joint name="left_back_roller_7_joint">
            <hardwareInterface>hardware_interface/EffortJointInterface</hardwareInterface>
        </joint>
        <actuator name="left_back_roller_7_joint_motor">
            <hardwareInterface>hardware_interface/EffortJointInterface</hardwareInterface>
            <mechanicalReduction>1</mechanicalReduction>
        </actuator>
    </transmission>
    <transmission name="trans_left_back_roller_8_joint">
        <type>transmission_interface/SimpleTransmission</type>
        <joint name="left_back_roller_8_joint">
            <hardwareInterface>hardware_interface/EffortJointInterface</hardwareInterface>
        </joint>
        <actuator name="left_back_roller_8_joint_motor">
            <hardwareInterface>hardware_interface/EffortJointInterface</hardwareInterface>
            <mechanicalReduction>1</mechanicalReduction>
        </actuator>
    </transmission>
    <transmission name="trans_left_back_roller_9_joint">
        <type>transmission_interface/SimpleTransmission</type>
        <joint name="left_back_roller_9_joint">
            <hardwareInterface>hardware_interface/EffortJointInterface</hardwareInterface>
        </joint>
        <actuator name="left_back_roller_9_joint_motor">
            <hardwareInterface>hardware_interface/EffortJointInterface</hardwareInterface>
            <mechanicalReduction>1</mechanicalReduction>
        </actuator>
    </transmission>
    <transmission name="trans_left_back_roller_10_joint">
        <type>transmission_interface/SimpleTransmission</type>
        <joint name="left_back_roller_10_joint">
            <hardwareInterface>hardware_interface/EffortJointInterface</hardwareInterface>
        </joint>
        <actuator name="left_back_roller_10_joint_motor">
            <hardwareInterface>hardware_interface/EffortJointInterface</hardwareInterface>
            <mechanicalReduction>1</mechanicalReduction>
        </actuator>
    </transmission>
    <transmission name="trans_left_back_roller_11_joint">
        <type>transmission_interface/SimpleTransmission</type>
        <joint name="left_back_roller_11_joint">
            <hardwareInterface>hardware_interface/EffortJointInterface</hardwareInterface>
        </joint>
        <actuator name="left_back_roller_11_joint_motor">
            <hardwareInterface>hardware_interface/EffortJointInterface</hardwareInterface>
            <mechanicalReduction>1</mechanicalReduction>
        </actuator>
    </transmission>
    <transmission name="trans_left_back_roller_12_joint">
        <type>transmission_interface/SimpleTransmission</type>
        <joint name="left_back_roller_12_joint">
            <hardwareInterface>hardware_interface/EffortJointInterface</hardwareInterface>
        </joint>
        <actuator name="left_back_roller_12_joint_motor">
            <hardwareInterface>hardware_interface/EffortJointInterface</hardwareInterface>
            <mechanicalReduction>1</mechanicalReduction>
        </actuator>
    </transmission>
    <transmission name="trans_left_back_roller_13_joint">
        <type>transmission_interface/SimpleTransmission</type>
        <joint name="left_back_roller_13_joint">
            <hardwareInterface>hardware_interface/EffortJointInterface</hardwareInterface>
        </joint>
        <actuator name="left_back_roller_13_joint_motor">
            <hardwareInterface>hardware_interface/EffortJointInterface</hardwareInterface>
            <mechanicalReduction>1</mechanicalReduction>
        </actuator>
    </transmission>
    <transmission name="trans_left_back_roller_14_joint">
        <type>transmission_interface/SimpleTransmission</type>
        <joint name="left_back_roller_14_joint">
            <hardwareInterface>hardware_interface/EffortJointInterface</hardwareInterface>
        </joint>
        <actuator name="left_back_roller_14_joint_motor">
            <hardwareInterface>hardware_interface/EffortJointInterface</hardwareInterface>
            <mechanicalReduction>1</mechanicalReduction>
        </actuator>
    </transmission>
    <transmission name="trans_left_back_roller_15_joint">
        <type>transmission_interface/SimpleTransmission</type>
        <joint name="left_back_roller_15_joint">
            <hardwareInterface>hardware_interface/EffortJointInterface</hardwareInterface>
        </joint>
        <actuator name="left_back_roller_15_joint_motor">
            <hardwareInterface>hardware_interface/EffortJointInterface</hardwareInterface>
            <mechanicalReduction>1</mechanicalReduction>
        </actuator>
    </transmission>
    <transmission name="trans_right_back_roller_0_joint">
        <type>transmission_interface/SimpleTransmission</type>
        <joint name="right_back_roller_0_joint">
            <hardwareInterface>hardware_interface/EffortJointInterface</hardwareInterface>
        </joint>
        <actuator name="right_back_roller_0_joint_motor">
            <hardwareInterface>hardware_interface/EffortJointInterface</hardwareInterface>
            <mechanicalReduction>1</mechanicalReduction>
        </actuator>
    </transmission>
    <transmission name="trans_right_back_roller_1_joint">
        <type>transmission_interface/SimpleTransmission</type>
        <joint name="right_back_roller_1_joint">
            <hardwareInterface>hardware_interface/EffortJointInterface</hardwareInterface>
        </joint>
        <actuator name="right_back_roller_1_joint_motor">
            <hardwareInterface>hardware_interface/EffortJointInterface</hardwareInterface>
            <mechanicalReduction>1</mechanicalReduction>
        </actuator>
    </transmission>
    <transmission name="trans_right_back_roller_2_joint">
        <type>transmission_interface/SimpleTransmission</type>
        <joint name="right_back_roller_2_joint">
            <hardwareInterface>hardware_interface/EffortJointInterface</hardwareInterface>
        </joint>
        <actuator name="right_back_roller_2_joint_motor">
            <hardwareInterface>hardware_interface/EffortJointInterface</hardwareInterface>
            <mechanicalReduction>1</mechanicalReduction>
        </actuator>
    </transmission>
    <transmission name="trans_right_back_roller_3_joint">
        <type>transmission_interface/SimpleTransmission</type>
        <joint name="right_back_roller_3_joint">
            <hardwareInterface>hardware_interface/EffortJointInterface</hardwareInterface>
        </joint>
        <actuator name="right_back_roller_3_joint_motor">
            <hardwareInterface>hardware_interface/EffortJointInterface</hardwareInterface>
            <mechanicalReduction>1</mechanicalReduction>
        </actuator>
    </transmission>
    <transmission name="trans_right_back_roller_4_joint">
        <type>transmission_interface/SimpleTransmission</type>
        <joint name="right_back_roller_4_joint">
            <hardwareInterface>hardware_interface/EffortJointInterface</hardwareInterface>
        </joint>
        <actuator name="right_back_roller_4_joint_motor">
            <hardwareInterface>hardware_interface/EffortJointInterface</hardwareInterface>
            <mechanicalReduction>1</mechanicalReduction>
        </actuator>
    </transmission>
    <transmission name="trans_right_back_roller_5_joint">
        <type>transmission_interface/SimpleTransmission</type>
        <joint name="right_back_roller_5_joint">
            <hardwareInterface>hardware_interface/EffortJointInterface</hardwareInterface>
        </joint>
        <actuator name="right_back_roller_5_joint_motor">
            <hardwareInterface>hardware_interface/EffortJointInterface</hardwareInterface>
            <mechanicalReduction>1</mechanicalReduction>
        </actuator>
    </transmission>
    <transmission name="trans_right_back_roller_6_joint">
        <type>transmission_interface/SimpleTransmission</type>
        <joint name="right_back_roller_6_joint">
            <hardwareInterface>hardware_interface/EffortJointInterface</hardwareInterface>
        </joint>
        <actuator name="right_back_roller_6_joint_motor">
            <hardwareInterface>hardware_interface/EffortJointInterface</hardwareInterface>
            <mechanicalReduction>1</mechanicalReduction>
        </actuator>
    </transmission>
    <transmission name="trans_right_back_roller_7_joint">
        <type>transmission_interface/SimpleTransmission</type>
        <joint name="right_back_roller_7_joint">
            <hardwareInterface>hardware_interface/EffortJointInterface</hardwareInterface>
        </joint>
        <actuator name="right_back_roller_7_joint_motor">
            <hardwareInterface>hardware_interface/EffortJointInterface</hardwareInterface>
            <mechanicalReduction>1</mechanicalReduction>
        </actuator>
    </transmission>
    <transmission name="trans_right_back_roller_8_joint">
        <type>transmission_interface/SimpleTransmission</type>
        <joint name="right_back_roller_8_joint">
            <hardwareInterface>hardware_interface/EffortJointInterface</hardwareInterface>
        </joint>
        <actuator name="right_back_roller_8_joint_motor">
            <hardwareInterface>hardware_interface/EffortJointInterface</hardwareInterface>
            <mechanicalReduction>1</mechanicalReduction>
        </actuator>
    </transmission>
    <transmission name="trans_right_back_roller_9_joint">
        <type>transmission_interface/SimpleTransmission</type>
        <joint name="right_back_roller_9_joint">
            <hardwareInterface>hardware_interface/EffortJointInterface</hardwareInterface>
        </joint>
        <actuator name="right_back_roller_9_joint_motor">
            <hardwareInterface>hardware_interface/EffortJointInterface</hardwareInterface>
            <mechanicalReduction>1</mechanicalReduction>
        </actuator>
    </transmission>
    <transmission name="trans_right_back_roller_10_joint">
        <type>transmission_interface/SimpleTransmission</type>
        <joint name="right_back_roller_10_joint">
            <hardwareInterface>hardware_interface/EffortJointInterface</hardwareInterface>
        </joint>
        <actuator name="right_back_roller_10_joint_motor">
            <hardwareInterface>hardware_interface/EffortJointInterface</hardwareInterface>
            <mechanicalReduction>1</mechanicalReduction>
        </actuator>
    </transmission>
    <transmission name="trans_right_back_roller_11_joint">
        <type>transmission_interface/SimpleTransmission</type>
        <joint name="right_back_roller_11_joint">
            <hardwareInterface>hardware_interface/EffortJointInterface</hardwareInterface>
        </joint>
        <actuator name="right_back_roller_11_joint_motor">
            <hardwareInterface>hardware_interface/EffortJointInterface</hardwareInterface>
            <mechanicalReduction>1</mechanicalReduction>
        </actuator>
    </transmission>
    <transmission name="trans_right_back_roller_12_joint">
        <type>transmission_interface/SimpleTransmission</type>
        <joint name="right_back_roller_12_joint">
            <hardwareInterface>hardware_interface/EffortJointInterface</hardwareInterface>
        </joint>
        <actuator name="right_back_roller_12_joint_motor">
            <hardwareInterface>hardware_interface/EffortJointInterface</hardwareInterface>
            <mechanicalReduction>1</mechanicalReduction>
        </actuator>
    </transmission>
    <transmission name="trans_right_back_roller_13_joint">
        <type>transmission_interface/SimpleTransmission</type>
        <joint name="right_back_roller_13_joint">
            <hardwareInterface>hardware_interface/EffortJointInterface</hardwareInterface>
        </joint>
        <actuator name="right_back_roller_13_joint_motor">
            <hardwareInterface>hardware_interface/EffortJointInterface</hardwareInterface>
            <mechanicalReduction>1</mechanicalReduction>
        </actuator>
    </transmission>
    <transmission name="trans_right_back_roller_14_joint">
        <type>transmission_interface/SimpleTransmission</type>
        <joint name="right_back_roller_14_joint">
            <hardwareInterface>hardware_interface/EffortJointInterface</hardwareInterface>
        </joint>
        <actuator name="right_back_roller_14_joint_motor">
            <hardwareInterface>hardware_interface/EffortJointInterface</hardwareInterface>
            <mechanicalReduction>1</mechanicalReduction>
        </actuator>
    </transmission>
    <transmission name="trans_right_back_roller_15_joint">
        <type>transmission_interface/SimpleTransmission</type>
        <joint name="right_back_roller_15_joint">
            <hardwareInterface>hardware_interface/EffortJointInterface</hardwareInterface>
        </joint>
        <actuator name="right_back_roller_15_joint_motor">
            <hardwareInterface>hardware_interface/EffortJointInterface</hardwareInterface>
            <mechanicalReduction>1</mechanicalReduction>
        </actuator>
    </transmission>
</robot>

