<?xml version="1.0" encoding="utf-8"?>
<!-- This URDF was automatically created by SolidWorks to URDF Exporter! Originally created by Stephen Brawner (brawner@gmail.com) 
     Commit Version: 1.5.1-0-g916b5db  Build Version: 1.5.7152.31018
     For more information, please see http://wiki.ros.org/sw_urdf_exporter -->
<robot
  name="engineer_chassis"
  xmlns:xacro="http://www.ros.org/wiki/xacro">

  <xacro:include filename="$(find sp_description)/urdf/common/mecanum_wheel.urdf.xacro"/>

  <xacro:property name="wheel_front" value="0.19727"/>
  <xacro:property name="wheel_back" value="-0.19727"/>
  <xacro:property name="wheel_left" value="0.223"/>
  <xacro:property name="wheel_right" value="-0.223"/>
  <xacro:property name="wheel_offset_z" value="-0.00111"/>
  <xacro:property name="wheel_joint_damping" value="1.0"/>
  <xacro:property name="wheel_joint_friction" value="1.0"/>

  <xacro:macro name="engineer_chassis" params="roller_type">
<!--base link-->
  <link
    name="base_link">
    <inertial>
      <origin
        xyz="-0.0113738412352606 -0.0179737884364999 0.0629667320671845"
        rpy="0 0 0" />
      <mass
        value="12.478309558197" />
      <inertia
        ixx="0.0306729834251133"
        ixy="2.06989089203648E-05"
        ixz="-4.24062281514238E-06"
        iyy="0.0340671825531538"
        iyz="-3.89196837584769E-05"
        izz="0.0558921594392679" />
    </inertial>
    <visual>
      <origin
        xyz="0 0 0"
        rpy="0 0 0" />
      <geometry>
        <mesh
          filename="package://sp_description/meshes/engineer_chassis/base_link.STL" />
      </geometry>
      <material
        name="">
        <color
          rgba="0.898039215686275 0.917647058823529 0.929411764705882 1" />
      </material>
    </visual>
    <collision>
      <origin xyz="0 0 0" rpy="0 0 0" />
      <geometry>
        <box size="0.6 0.6 0.15"/>
      </geometry>
    </collision>
    <collision>
      <origin xyz="0.2375 0.0 0.11" rpy="0 0 0"/>
      <geometry>
        <box size="0.125 0.6 0.07"/>
      </geometry>
    </collision>
    <collision>
      <origin xyz="-0.205 0.0 0.11" rpy="0 0 0"/>
      <geometry>
        <box size="0.19 0.6 0.07"/>
      </geometry>
    </collision>
    <collision>
      <origin xyz="0.0325 0.1965 0.13" rpy="0 0 0"/>
      <geometry>
        <box size="0.285 0.207 0.11"/>
      </geometry>
    </collision>
    <collision>
      <origin xyz="0.0325 -0.2135 0.13" rpy="0 0 0"/>
      <geometry>
        <box size="0.285 0.173 0.11"/>
      </geometry>
    </collision>
    <collision>
      <origin xyz="0.0 0.2 0.21" rpy="0 0 0"/>
      <geometry>
        <box size="0.23 0.12 0.05"/>
      </geometry>
    </collision>
    <collision>
      <origin xyz="0.0 -0.1895 0.235" rpy="0 0 0"/>
      <geometry>
        <box size="0.32 0.125 0.1"/>
      </geometry>
    </collision>
    <collision>
      <origin xyz="0.0 0.098 0.25" rpy="0 0 0"/>
      <geometry>
        <box size="0.19 0.01 0.13" rpy="0 0 0"/>
      </geometry>
    </collision>
    <collision>
      <origin xyz="0.0 -0.132 0.3" rpy="0 0 0"/>
      <geometry>
        <box size="0.19 0.01 0.03"/>
      </geometry>
    </collision>
  </link> 

    <xacro:mecanum_wheel prefix="left_front" connected_to="base_link"
                         wheel_x_offset="${wheel_front}" wheel_y_offset="${wheel_left}"
                         wheel_z_offset="${wheel_offset_z}"
                         reflect="1" roller_type="${roller_type}"/>
    <xacro:mecanum_wheel prefix="right_front" connected_to="base_link"
                         wheel_x_offset="${wheel_front}" wheel_y_offset="${wheel_right}"
                         wheel_z_offset="${wheel_offset_z}"
                         reflect="-1" roller_type="${roller_type}"/>
    <xacro:mecanum_wheel prefix="left_back" connected_to="base_link"
                         wheel_x_offset="${wheel_back}" wheel_y_offset="${wheel_left}"
                         wheel_z_offset="${wheel_offset_z}"
                         reflect="-1" roller_type="${roller_type}"/>
    <xacro:mecanum_wheel prefix="right_back" connected_to="base_link"
                         wheel_x_offset="${wheel_back}" wheel_y_offset="${wheel_right}"
                         wheel_z_offset="${wheel_offset_z}"
                         reflect="1" roller_type="${roller_type}"/>
    <xacro:wheel_transmission prefix="left_front" mechanical_reduction="19.2032"/>
    <xacro:wheel_transmission prefix="right_front" mechanical_reduction="-19.2032"/>
    <xacro:wheel_transmission prefix="left_back" mechanical_reduction="19.2032"/>
    <xacro:wheel_transmission prefix="right_back" mechanical_reduction="-19.2032"/>
  </xacro:macro>

<!--swiping card link-->
  <xacro:macro name="swiping_card" >
  <link
    name="swiping_card">
    <inertial>
      <origin
        xyz="-0.043679 3.1364E-15 0.0024775"
        rpy="0 0 0" />
      <mass
        value="0.12034" />
      <inertia
        ixx="0.00013212"
        ixy="6.8395E-06"
        ixz="-2.4208E-06"
        iyy="0.00035298"
        iyz="-4.3226E-06"
        izz="0.00048461" />
    </inertial>
    <visual>
      <origin
        xyz="0 0 0"
        rpy="0 0 0" />
      <geometry>
        <mesh
          filename="package://sp_description/meshes/engineer_chassis/swiping_card.STL" />
      </geometry>
    </visual>
    <collision>
      <origin
        xyz="0 0 0"
        rpy="0 0 0" />
      <geometry>
        <mesh
          filename="package://sp_description/meshes/engineer_chassis/swiping_card.STL" />
      </geometry>
    </collision>
  </link>
  <joint
    name="card_joint"
    type="prismatic">
    <origin
      xyz="0.235 0 -0.0155"
      rpy="0 0 0" />
    <parent
      link="base_link" />
    <child
      link="swiping_card" />
    <axis
      xyz="1 0 0" />
    <limit
      lower="0"
      upper="0.2"
      effort="80"
      velocity="2" />
  </joint>

  <transmission name="trans_card_joint">
    <type>transmission_interface/SimpleTransmission</type>
    <actuator name="card_joint_motor">
      <mechanicalReduction>49.97</mechanicalReduction>
    </actuator>
    <joint name="card_joint">
      <hardwareInterface>hardware_interface/EffortJointInterface</hardwareInterface>
    </joint>
  </transmission>
  </xacro:macro>
</robot>
