<?xml version="1.0" encoding="utf-8"?>
<!-- This URDF was automatically created by SolidWorks to URDF Exporter! Originally created by Stephen Brawner (brawner@gmail.com) 
     Commit Version: 1.5.1-0-g916b5db  Build Version: 1.5.7152.31018
     For more information, please see http://wiki.ros.org/sw_urdf_exporter -->
<robot
  name="fpv_module"
  xmlns:xacro="http://www.ros.org/wiki/xacro">
  <xacro:macro name="fpv_module">
  <link
    name="fpv_base_link">
    <inertial>
      <origin
        xyz="-0.11049 -0.12139 0.39986"
        rpy="0 0 0" />
      <mass
        value="0.31829" />
      <inertia
        ixx="0.00097362"
        ixy="-1.6968E-08"
        ixz="9.9313E-08"
        iyy="3.9154E-05"
        iyz="-2.2956E-07"
        izz="0.00098287" />
    </inertial>
    <visual>
      <origin
        xyz="0 0 0"
        rpy="0 0 0" />
      <geometry>
        <mesh
          filename="package://sp_description/meshes/fpv_module/base_link.STL" />
      </geometry>
      <material
        name="">
        <color
          rgba="0.89804 0.91765 0.92941 1" />
      </material>
    </visual>
    <collision>
      <origin xyz="-0.029 0.0 00.1213" rpy="0 0 0" />
      <geometry>
        <box size="0.025 0.025 0.27"/>
      </geometry>
    </collision>
    <collision>
      <origin xyz="0.0085 0.01 0.2963" rpy="0 0 0"/>
      <geometry>
        <box size="0.1 0.09 0.08"/>
      </geometry>
    </collision>
  </link>
  <link
    name="mast">
    <inertial>
      <origin
        xyz="0.0071654 -0.0026446 0.22366"
        rpy="0 0 0" />
      <mass
        value="0.43497" />
      <inertia
        ixx="0.0035278"
        ixy="-3.1775E-06"
        ixz="-8.4026E-08"
        iyy="0.0036181"
        iyz="-5.812E-09"
        izz="0.00025229" />
    </inertial>
    <visual>
      <origin
        xyz="0 0 0"
        rpy="0 0 0" />
      <geometry>
        <mesh
          filename="package://sp_description/meshes/fpv_module/mast.STL" />
      </geometry>
      <material
        name="">
        <color
          rgba="0.82353 0.87059 0.98039 1" />
      </material>
    </visual>
    <collision>
      <origin xyz="0.003 0 0.1738" rpy="0 0 0" />
      <geometry>
        <box size="0.031 0.036 0.375"/>
      </geometry>
    </collision>
    <collision>
      <origin xyz="0.038 -0.008 0.3813" rpy="0 0 0"/>
      <geometry>
        <box size="0.2 0.12 0.06"/>
      </geometry>
    </collision>
  </link>
  <joint
    name="mast_joint"
    type="prismatic">
    <origin
      xyz="-0.11887 -0.4 0.13926"
      rpy="3.1416 0 -3.1416" />
    <parent
      link="fpv_base_link" />
    <child
      link="mast" />
    <axis
      xyz="0 0 -1" />
    <limit
      lower="0"
      upper="0.235"
      effort="50"
      velocity="0.8" />
  </joint>
  <link
    name="fpv_yaw">
    <inertial>
      <origin
        xyz="-0.0091696 0.044106 0.018308"
        rpy="0 0 0" />
      <mass
        value="0.060881" />
      <inertia
        ixx="9.0403E-06"
        ixy="9.8899E-08"
        ixz="4.5134E-08"
        iyy="1.4638E-05"
        iyz="3.2627E-07"
        izz="1.9494E-05" />
    </inertial>
    <visual>
      <origin
        xyz="0 0 0"
        rpy="0 0 0" />
      <geometry>
        <mesh
          filename="package://sp_description/meshes/fpv_module/fpv_yaw.STL" />
      </geometry>
      <material
        name="">
        <color
          rgba="0.49804 0.49804 0.49804 1" />
      </material>
    </visual>
    <collision>
      <origin xyz="-0.012 -0.0055 0.4138" rpy="0 0 0" />
      <geometry>
        <box size="0.07 0.075 0.025"/>
      </geometry>
    </collision>
  </link>
  <joint
    name="fpv_yaw_joint"
    type="revolute">
    <origin
      xyz="0 -0.0285 0.3853"
      rpy="0 0 0" />
    <parent
      link="mast" />
    <child
      link="fpv_yaw" />
    <axis
      xyz="0 0 -1" />
    <limit
      lower="-1.5708"
      upper="1.5708"
      effort="1.3"
      velocity="6" />
  </joint>
  <link
    name="fpv_pitch">
    <inertial>
      <origin
        xyz="-0.017448 -0.055509 -4.0542E-05"
        rpy="0 0 0" />
      <mass
        value="0.79082" />
      <inertia
        ixx="0.00090446"
        ixy="-1.0482E-06"
        ixz="3.6499E-07"
        iyy="0.0011756"
        iyz="8.4354E-08"
        izz="0.0009281" />
    </inertial>
    <visual>
      <origin
        xyz="0 0 0"
        rpy="0 0 0" />
      <geometry>
        <mesh
          filename="package://sp_description/meshes/fpv_module/fpv_pitch.STL" />
      </geometry>
      <material
        name="">
        <color
          rgba="0.49804 0.49804 0.49804 1" />
      </material>
    </visual>
    <collision>
      <origin xyz="-0.007 -0.028 0.4513" rpy="0 0 0" />
      <geometry>
        <box size="0.11 0.07 0.05"/>
      </geometry>
    </collision>
  </link>
  <joint
    name="fpv_pitch_joint"
    type="revolute">
    <origin
      xyz="0 0.0007 0.0275"
      rpy="-1.5708 0 -3.1416" />
    <parent
      link="fpv_yaw" />
    <child
      link="fpv_pitch" />
    <axis
      xyz="0 0 1" />
    <limit
      lower="-1.5708"
      upper="1.5708"
      effort="1.3"
      velocity="6" />
  </joint>

  <!--Transmission-->
  <transmission name="trans_mast_joint">
    <type>transmission_interface/SimpleTransmission</type>
    <actuator name="mast_joint_motor">
      <mechanicalReduction>1</mechanicalReduction>
    </actuator>
    <joint name="mast_joint">
      <hardwareInterface>hardware_interface/PositionJointInterface</hardwareInterface>
    </joint>
  </transmission>

  <transmission name="trans_fpv_yaw_joint">
    <type>transmission_interface/SimpleTransmission</type>
    <actuator name="fpv_yaw_joint_motor">
      <mechanicalReduction>1</mechanicalReduction>
    </actuator>
    <joint name="fpv_yaw_joint">
      <hardwareInterface>hardware_interface/PositionJointInterface</hardwareInterface>
    </joint>
  </transmission>

  <transmission name="trans_fpv_pitch_joint">
    <type>transmission_interface/SimpleTransmission</type>
    <actuator name="fpv_pitch_joint_motor">
      <mechanicalReduction>1</mechanicalReduction>
    </actuator>
    <joint name="fpv_pitch_joint">
      <hardwareInterface>hardware_interface/PositionJointInterface</hardwareInterface>
    </joint>
  </transmission>

  
  </xacro:macro>
</robot>