<?xml version="1.0" encoding="utf-8"?>
<!-- This URDF was automatically created by SolidWorks to URDF Exporter! Originally created by Stephen Brawner (brawner@gmail.com) 
     Commit Version: 1.6.0-4-g7f85cfe  Build Version: 1.6.7995.38578
     For more information, please see http://wiki.ros.org/sw_urdf_exporter -->
<robot
  name="engineer_rotating_ore"
  xmlns:xacro="http://wiki.ros.org/xacro">

  <xacro:macro name="engineer_rotating_ore">
    <link name="ore_left_link">
      <inertial>
        <origin xyz="0 0 0" rpy="0 0 0"/>
        <mass value="0.013"/>
        <inertia ixx="0.001" ixy="0.0" ixz="0.0" iyy="0.001" iyz="0.0" izz="0.001"/>
      </inertial>
    </link>

    <link name="ore_right_link">
      <inertial>
        <origin xyz="0 0 0" rpy="0 0 0"/>
        <mass value="0.013"/>
        <inertia ixx="0.001" ixy="0.0" ixz="0.0" iyy="0.001" iyz="0.0" izz="0.001"/>
      </inertial>
    </link>
    
    <joint name="ore_left_joint" type="revolute">
      <origin xyz="0 0 0" rpy="0 0 0" />
      <parent link="z_base_link" />
      <child link="ore_left_link" />
      <axis xyz="0 0 1" />
      <limit lower="0" upper="11" effort="10" velocity="1" />
    </joint>

    <joint name="ore_right_joint" type="revolute">
      <origin xyz="0 0 0" rpy="0 0 0" />
      <parent link="z_base_link" />
      <child link="ore_right_link" />
      <axis xyz="0 0 1" />
      <limit lower="0" upper="11" effort="10" velocity="1" />
    </joint>

    <transmission name="trans_ore_left_joint" >
      <type>transmission_interface/SimpleTransmission</type>
      <actuator name="ore_left_joint_motor">
        <mechanicalReduction>-1</mechanicalReduction>
        <hardwareInterface>hardware_interface/EffortJointInterface</hardwareInterface>
      </actuator>
			<joint name="ore_left_joint">
				<hardwareInterface>hardware_interface/EffortJointInterface</hardwareInterface>
			</joint>
    </transmission>

    <transmission name="trans_ore_right_joint" >
      <type>transmission_interface/SimpleTransmission</type>
      <actuator name="ore_right_joint_motor">
        <mechanicalReduction>1</mechanicalReduction>
        <hardwareInterface>hardware_interface/EffortJointInterface</hardwareInterface>
      </actuator>
			<joint name="ore_right_joint">
				<hardwareInterface>hardware_interface/EffortJointInterface</hardwareInterface>
			</joint>
    </transmission>
  
  </xacro:macro>
</robot>