<?xml version="1.0" ?>
<!-- =================================================================================== -->
<!-- |    This document was autogenerated by xacro from /home/cherrynova/catkin_ws/src/sp_control/sp_description/urdf/engineer_manipulator/engineer.xacro | -->
<!-- |    EDITING THIS FILE BY HAND IS NOT RECOMMENDED                                 | -->
<!-- =================================================================================== -->
<robot name="engineer">
    `
    <transmission name="trans_joint1">
        <type>transmission_interface/SimpleTransmission</type>
        <actuator name="joint1_motor">
            <mechanicalReduction>1.5</mechanicalReduction>
            <hardwareInterface>hardware_interface/PositionJointInterface</hardwareInterface>
        </actuator>
        <joint name="joint1">
            <hardwareInterface>hardware_interface/PositionJointInterface</hardwareInterface>
        </joint>
    </transmission>
    <transmission name="trans_joint2">
        <type>transmission_interface/SimpleTransmission</type>
        <actuator name="joint2_motor">
            <mechanicalReduction>6</mechanicalReduction>
            <hardwareInterface>hardware_interface/PositionJointInterface</hardwareInterface>
        </actuator>
        <joint name="joint2">
            <hardwareInterface>hardware_interface/PositionJointInterface</hardwareInterface>
        </joint>
    </transmission>
    <transmission name="trans_joint3">
        <type>transmission_interface/SimpleTransmission</type>
        <actuator name="joint3_motor">
            <mechanicalReduction>6</mechanicalReduction>
            <hardwareInterface>hardware_interface/PositionJointInterface</hardwareInterface>
        </actuator>
        <joint name="joint3">
            <hardwareInterface>hardware_interface/PositionJointInterface</hardwareInterface>
        </joint>
    </transmission>
    <transmission name="trans_joint4">
        <type>transmission_interface/SimpleTransmission</type>
        <actuator name="joint4_motor">
            <mechanicalReduction>1</mechanicalReduction>
            <hardwareInterface>hardware_interface/PositionJointInterface</hardwareInterface>
        </actuator>
        <joint name="joint4">
            <hardwareInterface>hardware_interface/PositionJointInterface</hardwareInterface>
        </joint>
    </transmission>
    <transmission name="trans_joint5">
        <type>transmission_interface/SimpleTransmission</type>
        <actuator name="joint5_motor">
            <mechanicalReduction>1</mechanicalReduction>
            <hardwareInterface>hardware_interface/PositionJointInterface</hardwareInterface>
        </actuator>
        <joint name="joint5">
            <hardwareInterface>hardware_interface/PositionJointInterface</hardwareInterface>
        </joint>
    </transmission>
    <transmission name="trans_joint6">
        <type>transmission_interface/SimpleTransmission</type>
        <actuator name="joint6_motor">
            <mechanicalReduction>1</mechanicalReduction>
            <hardwareInterface>hardware_interface/PositionJointInterface</hardwareInterface>
        </actuator>
        <joint name="joint6">
            <hardwareInterface>hardware_interface/PositionJointInterface</hardwareInterface>
        </joint>
    </transmission>
    <transmission name="trans_joint7">
        <type>transmission_interface/SimpleTransmission</type>
        <actuator name="joint7_motor">
            <mechanicalReduction>599.99</mechanicalReduction>
            <hardwareInterface>hardware_interface/PositionJointInterface</hardwareInterface>
        </actuator>
        <joint name="joint7">
            <hardwareInterface>hardware_interface/PositionJointInterface</hardwareInterface>
        </joint>
    </transmission>
    <gazebo>
        <plugin filename="libgazebo_ros_vacuum_gripper.so" name="gazebo_ros_vacuum_gripper">
            <robotNamespace>/vacuum_gripper</robotNamespace>
            <bodyName>vacuum_gripper</bodyName>
            <topicName>grasping</topicName>
            <maxForce>100</maxForce>
            <maxDistance>0.05</maxDistance>
            <minDistance>0.01</minDistance>
        </plugin>
        <plugin name="gazebo_ros_control">
            <robotNamespace>/</robotNamespace>
        </plugin>
    </gazebo>
    <gazebo reference="vacuum_gripper">
        <mu1>50</mu1>
        <mu2>50</mu2>
        <minDepth>0.003</minDepth>
        <maxVel>0</maxVel>
        <kp>10000000000000.0</kp>
        <kd>1.0</kd>
        <ki>2.0</ki>
        <material>Gazebo/Grey</material>
    </gazebo>
    <!--base link-->
    <link name="base_link">
        <inertial>
            <origin rpy="0 0 0" xyz="0.0147695790883097 -0.0277071473448106 0.0578144581314767" />
            <mass value="10.0515226503987" />
            <inertia ixx="0.0193511082538768" ixy="-3.41760973575497E-05" ixz="5.54217286706699E-06" iyy="0.0356235596590244" iyz="-8.92016001448171E-06" izz="0.046454065978897" />
        </inertial>
        <visual>
            <origin rpy="0 0 0" xyz="0 0 0" />
            <geometry>
                <mesh filename="package://sp_description/meshes/engineer_manipulator/engineer_chassis/base_link.STL" />
            </geometry>
            <material name="">
                <color rgba="0.792156862745098 0.819607843137255 0.933333333333333 1" />
            </material>
        </visual>
        <collision>
            <origin rpy="0 0 0" xyz="0 0 0" />
            <geometry>
                <box size="0.6 0.6 0.150" />
            </geometry>
        </collision>
        <collision>
            <origin rpy="0 0 0" xyz="0.228 0.0 0.118" />
            <geometry>
                <box size="0.144 0.3 0.14" />
            </geometry>
        </collision>
        <collision>
            <origin rpy="0 0 0" xyz="-0.205 0.0 0.10" />
            <geometry>
                <box size="0.19 0.3 0.09" />
            </geometry>
        </collision>
        <collision>
            <origin rpy="0 0 0" xyz="-0.01 0.193 0.13" />
            <geometry>
                <box size="0.220 0.214 0.148" />
            </geometry>
        </collision>
        <collision>
            <origin rpy="0 0 0" xyz="0.0 0.22 0.09" />
            <geometry>
                <box size="0.6 0.16 0.07" />
            </geometry>
        </collision>
        <collision>
            <origin rpy="0 0 0" xyz="0.0 -0.24 0.13" />
            <geometry>
                <box size="0.5 0.12 0.28" />
            </geometry>
        </collision>
        <collision>
            <origin rpy="0 0 0" xyz="0.0 0.054 0.10" />
            <geometry>
                <box rpy="0 0 0" size="0.19 0.008 0.10" />
            </geometry>
        </collision>
        <collision>
            <origin rpy="0 0 0" xyz="0.0 -0.172 0.10" />
            <geometry>
                <box size="0.19 0.01 0.10" />
            </geometry>
        </collision>
    </link>
    <!--  link  -->
    <link name="left_front_wheel">
        <visual>
            <geometry>
                <mesh filename="package://sp_description/meshes/common/mecanum_wheel/right_mecanum_wheel.STL" />
            </geometry>
        </visual>
        <inertial>
            <mass value="0.4235" />
            <inertia ixx="4.122e-4" ixy="0.0" ixz="0.0" iyy="7.398e-4" iyz="0.0" izz="4.122e-4" />
        </inertial>
    </link>
    <!--  joint  -->
    <joint name="left_front_wheel_joint" type="revolute">
        <axis xyz="0 1 0" />
        <origin rpy="0 0 0" xyz="0.19727 0.223 0.000889" />
        <!--      limit not work while type="continuous"-->
        <limit effort="10" lower="-1e9" upper="1e9" velocity="70" />
        <dynamics damping="0.0" friction="0.05" />
        <parent link="base_link" />
        <child link="left_front_wheel" />
    </joint>
    <!--  link  -->
    <link name="left_front_roller_0">
        <collision>
            <geometry>
                <sphere radius="0.009" />
            </geometry>
        </collision>
        <inertial>
            <mass value="0.036" />
            <inertia ixx="3128e-9" ixy="0.0" ixz="0.0" iyy="3128e-9" iyz="0.0" izz="3128e-9" />
            <origin xyz="0 0 0" rpy="0 0 0" />
        </inertial>
    </link>
    <joint name="left_front_roller_0_joint" type="continuous">
        <origin rpy="0 0 0" xyz="4.163799117101001e-18 0 -0.068" />
        <axis xyz="0.7071067811865476 -0.7071067811865476 0.0" />
        <dynamics damping="0.0" friction="0.001" />
        <parent link="left_front_wheel" />
        <child link="left_front_roller_0" />
    </joint>
    <gazebo reference="left_front_roller_0">
        <mu1 value="2000.0" />
        <mu2 value="2000.0" />
        <kp value="1000000.0" />
        <kd value="100.0" />
        <material>Gazebo/Black</material>
    </gazebo>
    <!--  link  -->
    <link name="left_front_roller_1">
        <collision>
            <geometry>
                <sphere radius="0.009" />
            </geometry>
        </collision>
        <inertial>
            <mass value="0.036" />
            <inertia ixx="3128e-9" ixy="0.0" ixz="0.0" iyy="3128e-9" iyz="0.0" izz="3128e-9" />
            <origin xyz="0 0 0" rpy="0 0 0" />
        </inertial>
    </link>
    <joint name="left_front_roller_1_joint" type="continuous">
        <origin rpy="0 0 0" xyz="0.026041377055996056 0 -0.06281597472798972" />
        <axis xyz="0.653200024955946 -0.7071067811865476 0.27079462217250855" />
        <dynamics damping="0.0" friction="0.001" />
        <parent link="left_front_wheel" />
        <child link="left_front_roller_1" />
    </joint>
    <gazebo reference="left_front_roller_1">
        <mu1 value="2000.0" />
        <mu2 value="2000.0" />
        <kp value="1000000.0" />
        <kd value="100.0" />
        <material>Gazebo/Black</material>
    </gazebo>
    <!--  link  -->
    <link name="left_front_roller_2">
        <collision>
            <geometry>
                <sphere radius="0.009" />
            </geometry>
        </collision>
        <inertial>
            <mass value="0.036" />
            <inertia ixx="3128e-9" ixy="0.0" ixz="0.0" iyy="3128e-9" iyz="0.0" izz="3128e-9" />
            <origin xyz="0 0 0" rpy="0 0 0" />
        </inertial>
    </link>
    <joint name="left_front_roller_2_joint" type="continuous">
        <origin rpy="0 0 0" xyz="0.04811219067739703 0 -0.048054314147865956" />
        <axis xyz="0.49969899116506866 -0.7071067811865476 0.5003008277312888" />
        <dynamics damping="0.0" friction="0.001" />
        <parent link="left_front_wheel" />
        <child link="left_front_roller_2" />
    </joint>
    <gazebo reference="left_front_roller_2">
        <mu1 value="2000.0" />
        <mu2 value="2000.0" />
        <kp value="1000000.0" />
        <kd value="100.0" />
        <material>Gazebo/Black</material>
    </gazebo>
    <!--  link  -->
    <link name="left_front_roller_3">
        <collision>
            <geometry>
                <sphere radius="0.009" />
            </geometry>
        </collision>
        <inertial>
            <mass value="0.036" />
            <inertia ixx="3128e-9" ixy="0.0" ixz="0.0" iyy="3128e-9" iyz="0.0" izz="3128e-9" />
            <origin xyz="0 0 0" rpy="0 0 0" />
        </inertial>
    </link>
    <joint name="left_front_roller_3_joint" type="continuous">
        <origin rpy="0 0 0" xyz="0.06284727452340379 0 -0.025965748303869884" />
        <axis xyz="0.2700081868271984 -0.7071067811865476 0.6535254999204613" />
        <dynamics damping="0.0" friction="0.001" />
        <parent link="left_front_wheel" />
        <child link="left_front_roller_3" />
    </joint>
    <gazebo reference="left_front_roller_3">
        <mu1 value="2000.0" />
        <mu2 value="2000.0" />
        <kp value="1000000.0" />
        <kd value="100.0" />
        <material>Gazebo/Black</material>
    </gazebo>
    <!--  link  -->
    <link name="left_front_roller_4">
        <collision>
            <geometry>
                <sphere radius="0.009" />
            </geometry>
        </collision>
        <inertial>
            <mass value="0.036" />
            <inertia ixx="3128e-9" ixy="0.0" ixz="0.0" iyy="3128e-9" iyz="0.0" izz="3128e-9" />
            <origin xyz="0 0 0" rpy="0 0 0" />
        </inertial>
    </link>
    <joint name="left_front_roller_4_joint" type="continuous">
        <origin rpy="0 0 0" xyz="0.06799995073981367 0 8.184975818264867e-05" />
        <axis xyz="-0.0008511252801386329 -0.7071067811865476 0.7071062689481388" />
        <dynamics damping="0.0" friction="0.001" />
        <parent link="left_front_wheel" />
        <child link="left_front_roller_4" />
    </joint>
    <gazebo reference="left_front_roller_4">
        <mu1 value="2000.0" />
        <mu2 value="2000.0" />
        <kp value="1000000.0" />
        <kd value="100.0" />
        <material>Gazebo/Black</material>
    </gazebo>
    <!--  link  -->
    <link name="left_front_roller_5">
        <collision>
            <geometry>
                <sphere radius="0.009" />
            </geometry>
        </collision>
        <inertial>
            <mass value="0.036" />
            <inertia ixx="3128e-9" ixy="0.0" ixz="0.0" iyy="3128e-9" iyz="0.0" izz="3128e-9" />
            <origin xyz="0 0 0" rpy="0 0 0" />
        </inertial>
    </link>
    <joint name="left_front_roller_5_joint" type="continuous">
        <origin rpy="0 0 0" xyz="0.06278458392296919 0 0.026116968078619688" />
        <axis xyz="-0.27158066518271434 -0.7071067811865476 0.6528736036162853" />
        <dynamics damping="0.0" friction="0.001" />
        <parent link="left_front_wheel" />
        <child link="left_front_roller_5" />
    </joint>
    <gazebo reference="left_front_roller_5">
        <mu1 value="2000.0" />
        <mu2 value="2000.0" />
        <kp value="1000000.0" />
        <kd value="100.0" />
        <material>Gazebo/Black</material>
    </gazebo>
    <!--  link  -->
    <link name="left_front_roller_6">
        <collision>
            <geometry>
                <sphere radius="0.009" />
            </geometry>
        </collision>
        <inertial>
            <mass value="0.036" />
            <inertia ixx="3128e-9" ixy="0.0" ixz="0.0" iyy="3128e-9" iyz="0.0" izz="3128e-9" />
            <origin xyz="0 0 0" rpy="0 0 0" />
        </inertial>
    </link>
    <joint name="left_front_roller_6_joint" type="continuous">
        <origin rpy="0 0 0" xyz="0.0479963679958505 0 0.04816999750059053" />
        <axis xyz="-0.5009019394471561 -0.7071067811865476 0.499096430620454" />
        <dynamics damping="0.0" friction="0.001" />
        <parent link="left_front_wheel" />
        <child link="left_front_roller_6" />
    </joint>
    <gazebo reference="left_front_roller_6">
        <mu1 value="2000.0" />
        <mu2 value="2000.0" />
        <kp value="1000000.0" />
        <kd value="100.0" />
        <material>Gazebo/Black</material>
    </gazebo>
    <!--  link  -->
    <link name="left_front_roller_7">
        <collision>
            <geometry>
                <sphere radius="0.009" />
            </geometry>
        </collision>
        <inertial>
            <mass value="0.036" />
            <inertia ixx="3128e-9" ixy="0.0" ixz="0.0" iyy="3128e-9" iyz="0.0" izz="3128e-9" />
            <origin xyz="0 0 0" rpy="0 0 0" />
        </inertial>
    </link>
    <joint name="left_front_roller_7_joint" type="continuous">
        <origin rpy="0 0 0" xyz="0.0258900819318143 0 0.06287848326386335" />
        <axis xyz="-0.6538500280382736 -0.7071067811865476 0.2692213602861942" />
        <dynamics damping="0.0" friction="0.001" />
        <parent link="left_front_wheel" />
        <child link="left_front_roller_7" />
    </joint>
    <gazebo reference="left_front_roller_7">
        <mu1 value="2000.0" />
        <mu2 value="2000.0" />
        <kp value="1000000.0" />
        <kd value="100.0" />
        <material>Gazebo/Black</material>
    </gazebo>
    <!--  link  -->
    <link name="left_front_roller_8">
        <collision>
            <geometry>
                <sphere radius="0.009" />
            </geometry>
        </collision>
        <inertial>
            <mass value="0.036" />
            <inertia ixx="3128e-9" ixy="0.0" ixz="0.0" iyy="3128e-9" iyz="0.0" izz="3128e-9" />
            <origin xyz="0 0 0" rpy="0 0 0" />
        </inertial>
    </link>
    <joint name="left_front_roller_8_joint" type="continuous">
        <origin rpy="0 0 0" xyz="-0.00016369939777898906 0 0.06799980295932605" />
        <axis xyz="-0.7071047322336546 -0.7071067811865476 -0.0017022493271422689" />
        <dynamics damping="0.0" friction="0.001" />
        <parent link="left_front_wheel" />
        <child link="left_front_roller_8" />
    </joint>
    <gazebo reference="left_front_roller_8">
        <mu1 value="2000.0" />
        <mu2 value="2000.0" />
        <kp value="1000000.0" />
        <kd value="100.0" />
        <material>Gazebo/Black</material>
    </gazebo>
    <!--  link  -->
    <link name="left_front_roller_9">
        <collision>
            <geometry>
                <sphere radius="0.009" />
            </geometry>
        </collision>
        <inertial>
            <mass value="0.036" />
            <inertia ixx="3128e-9" ixy="0.0" ixz="0.0" iyy="3128e-9" iyz="0.0" izz="3128e-9" />
            <origin xyz="0 0 0" rpy="0 0 0" />
        </inertial>
    </link>
    <joint name="left_front_roller_9_joint" type="continuous">
        <origin rpy="0 0 0" xyz="-0.026192521262222306 0 0.06275310215382211" />
        <axis xyz="-0.6525462363744081 -0.7071067811865476 -0.2723663147189738" />
        <dynamics damping="0.0" friction="0.001" />
        <parent link="left_front_wheel" />
        <child link="left_front_roller_9" />
    </joint>
    <gazebo reference="left_front_roller_9">
        <mu1 value="2000.0" />
        <mu2 value="2000.0" />
        <kp value="1000000.0" />
        <kd value="100.0" />
        <material>Gazebo/Black</material>
    </gazebo>
    <!--  link  -->
    <link name="left_front_roller_10">
        <collision>
            <geometry>
                <sphere radius="0.009" />
            </geometry>
        </collision>
        <inertial>
            <mass value="0.036" />
            <inertia ixx="3128e-9" ixy="0.0" ixz="0.0" iyy="3128e-9" iyz="0.0" izz="3128e-9" />
            <origin xyz="0 0 0" rpy="0 0 0" />
        </inertial>
    </link>
    <joint name="left_front_roller_10_joint" type="continuous">
        <origin rpy="0 0 0" xyz="-0.048227734533694264 0 0.04793835230530472" />
        <axis xyz="-0.49849314697045194 -0.7071067811865476 -0.5015023254417625" />
        <dynamics damping="0.0" friction="0.001" />
        <parent link="left_front_wheel" />
        <child link="left_front_roller_10" />
    </joint>
    <gazebo reference="left_front_roller_10">
        <mu1 value="2000.0" />
        <mu2 value="2000.0" />
        <kp value="1000000.0" />
        <kd value="100.0" />
        <material>Gazebo/Black</material>
    </gazebo>
    <!--  link  -->
    <link name="left_front_roller_11">
        <collision>
            <geometry>
                <sphere radius="0.009" />
            </geometry>
        </collision>
        <inertial>
            <mass value="0.036" />
            <inertia ixx="3128e-9" ixy="0.0" ixz="0.0" iyy="3128e-9" iyz="0.0" izz="3128e-9" />
            <origin xyz="0 0 0" rpy="0 0 0" />
        </inertial>
    </link>
    <joint name="left_front_roller_11_joint" type="continuous">
        <origin rpy="0 0 0" xyz="-0.06290960090415226 0 0.02581437804945697" />
        <axis xyz="-0.2684341436894733 -0.7071067811865476 -0.6541736088391974" />
        <dynamics damping="0.0" friction="0.001" />
        <parent link="left_front_wheel" />
        <child link="left_front_roller_11" />
    </joint>
    <gazebo reference="left_front_roller_11">
        <mu1 value="2000.0" />
        <mu2 value="2000.0" />
        <kp value="1000000.0" />
        <kd value="100.0" />
        <material>Gazebo/Black</material>
    </gazebo>
    <!--  link  -->
    <link name="left_front_roller_12">
        <collision>
            <geometry>
                <sphere radius="0.009" />
            </geometry>
        </collision>
        <inertial>
            <mass value="0.036" />
            <inertia ixx="3128e-9" ixy="0.0" ixz="0.0" iyy="3128e-9" iyz="0.0" izz="3128e-9" />
            <origin xyz="0 0 0" rpy="0 0 0" />
        </inertial>
    </link>
    <joint name="left_front_roller_12_joint" type="continuous">
        <origin rpy="0 0 0" xyz="-0.06799955665875124 0 -0.0002455488002028931" />
        <axis xyz="0.002553370907877698 -0.7071067811865476 -0.7071021710453214" />
        <dynamics damping="0.0" friction="0.001" />
        <parent link="left_front_wheel" />
        <child link="left_front_roller_12" />
    </joint>
    <gazebo reference="left_front_roller_12">
        <mu1 value="2000.0" />
        <mu2 value="2000.0" />
        <kp value="1000000.0" />
        <kd value="100.0" />
        <material>Gazebo/Black</material>
    </gazebo>
    <!--  link  -->
    <link name="left_front_roller_13">
        <collision>
            <geometry>
                <sphere radius="0.009" />
            </geometry>
        </collision>
        <inertial>
            <mass value="0.036" />
            <inertia ixx="3128e-9" ixy="0.0" ixz="0.0" iyy="3128e-9" iyz="0.0" izz="3128e-9" />
            <origin xyz="0 0 0" rpy="0 0 0" />
        </inertial>
    </link>
    <joint name="left_front_roller_13_joint" type="continuous">
        <origin rpy="0 0 0" xyz="-0.06272152946616016 0 -0.026268036497340295" />
        <axis xyz="0.2731515696430154 -0.7071067811865476 -0.6522179237046135" />
        <dynamics damping="0.0" friction="0.001" />
        <parent link="left_front_wheel" />
        <child link="left_front_roller_13" />
    </joint>
    <gazebo reference="left_front_roller_13">
        <mu1 value="2000.0" />
        <mu2 value="2000.0" />
        <kp value="1000000.0" />
        <kd value="100.0" />
        <material>Gazebo/Black</material>
    </gazebo>
    <!--  link  -->
    <link name="left_front_roller_14">
        <collision>
            <geometry>
                <sphere radius="0.009" />
            </geometry>
        </collision>
        <inertial>
            <mass value="0.036" />
            <inertia ixx="3128e-9" ixy="0.0" ixz="0.0" iyy="3128e-9" iyz="0.0" izz="3128e-9" />
            <origin xyz="0 0 0" rpy="0 0 0" />
        </inertial>
    </link>
    <joint name="left_front_roller_14_joint" type="continuous">
        <origin rpy="0 0 0" xyz="-0.04788026716028342 0 -0.04828540169305713" />
        <axis xyz="0.5021019848452515 -0.7071067811865476 -0.49788914108911725" />
        <dynamics damping="0.0" friction="0.001" />
        <parent link="left_front_wheel" />
        <child link="left_front_roller_14" />
    </joint>
    <gazebo reference="left_front_roller_14">
        <mu1 value="2000.0" />
        <mu2 value="2000.0" />
        <kp value="1000000.0" />
        <kd value="100.0" />
        <material>Gazebo/Black</material>
    </gazebo>
    <!--  link  -->
    <link name="left_front_roller_15">
        <collision>
            <geometry>
                <sphere radius="0.009" />
            </geometry>
        </collision>
        <inertial>
            <mass value="0.036" />
            <inertia ixx="3128e-9" ixy="0.0" ixz="0.0" iyy="3128e-9" iyz="0.0" izz="3128e-9" />
            <origin xyz="0 0 0" rpy="0 0 0" />
        </inertial>
    </link>
    <joint name="left_front_roller_15_joint" type="continuous">
        <origin rpy="0 0 0" xyz="-0.025738636766479847 0 -0.06294062739918639" />
        <axis xyz="0.6544962418544192 -0.7071067811865476 -0.2676465381775779" />
        <dynamics damping="0.0" friction="0.001" />
        <parent link="left_front_wheel" />
        <child link="left_front_roller_15" />
    </joint>
    <gazebo reference="left_front_roller_15">
        <mu1 value="2000.0" />
        <mu2 value="2000.0" />
        <kp value="1000000.0" />
        <kd value="100.0" />
        <material>Gazebo/Black</material>
    </gazebo>
    <!--  link  -->
    <link name="right_front_wheel">
        <visual>
            <geometry>
                <mesh filename="package://sp_description/meshes/common/mecanum_wheel/left_mecanum_wheel.STL" />
            </geometry>
        </visual>
        <inertial>
            <mass value="0.4235" />
            <inertia ixx="4.122e-4" ixy="0.0" ixz="0.0" iyy="7.398e-4" iyz="0.0" izz="4.122e-4" />
        </inertial>
    </link>
    <!--  joint  -->
    <joint name="right_front_wheel_joint" type="revolute">
        <axis xyz="0 1 0" />
        <origin rpy="0 0 0" xyz="0.19727 -0.223 0.000889" />
        <!--      limit not work while type="continuous"-->
        <limit effort="10" lower="-1e9" upper="1e9" velocity="70" />
        <dynamics damping="0.0" friction="0.05" />
        <parent link="base_link" />
        <child link="right_front_wheel" />
    </joint>
    <!--  link  -->
    <link name="right_front_roller_0">
        <collision>
            <geometry>
                <sphere radius="0.009" />
            </geometry>
        </collision>
        <inertial>
            <mass value="0.036" />
            <inertia ixx="3128e-9" ixy="0.0" ixz="0.0" iyy="3128e-9" iyz="0.0" izz="3128e-9" />
            <origin xyz="0 0 0" rpy="0 0 0" />
        </inertial>
    </link>
    <joint name="right_front_roller_0_joint" type="continuous">
        <origin rpy="0 0 0" xyz="4.163799117101001e-18 0 -0.068" />
        <axis xyz="0.7071067811865476 0.7071067811865476 0.0" />
        <dynamics damping="0.0" friction="0.001" />
        <parent link="right_front_wheel" />
        <child link="right_front_roller_0" />
    </joint>
    <gazebo reference="right_front_roller_0">
        <mu1 value="2000.0" />
        <mu2 value="2000.0" />
        <kp value="1000000.0" />
        <kd value="100.0" />
        <material>Gazebo/Black</material>
    </gazebo>
    <!--  link  -->
    <link name="right_front_roller_1">
        <collision>
            <geometry>
                <sphere radius="0.009" />
            </geometry>
        </collision>
        <inertial>
            <mass value="0.036" />
            <inertia ixx="3128e-9" ixy="0.0" ixz="0.0" iyy="3128e-9" iyz="0.0" izz="3128e-9" />
            <origin xyz="0 0 0" rpy="0 0 0" />
        </inertial>
    </link>
    <joint name="right_front_roller_1_joint" type="continuous">
        <origin rpy="0 0 0" xyz="0.026041377055996056 0 -0.06281597472798972" />
        <axis xyz="0.653200024955946 0.7071067811865476 0.27079462217250855" />
        <dynamics damping="0.0" friction="0.001" />
        <parent link="right_front_wheel" />
        <child link="right_front_roller_1" />
    </joint>
    <gazebo reference="right_front_roller_1">
        <mu1 value="2000.0" />
        <mu2 value="2000.0" />
        <kp value="1000000.0" />
        <kd value="100.0" />
        <material>Gazebo/Black</material>
    </gazebo>
    <!--  link  -->
    <link name="right_front_roller_2">
        <collision>
            <geometry>
                <sphere radius="0.009" />
            </geometry>
        </collision>
        <inertial>
            <mass value="0.036" />
            <inertia ixx="3128e-9" ixy="0.0" ixz="0.0" iyy="3128e-9" iyz="0.0" izz="3128e-9" />
            <origin xyz="0 0 0" rpy="0 0 0" />
        </inertial>
    </link>
    <joint name="right_front_roller_2_joint" type="continuous">
        <origin rpy="0 0 0" xyz="0.04811219067739703 0 -0.048054314147865956" />
        <axis xyz="0.49969899116506866 0.7071067811865476 0.5003008277312888" />
        <dynamics damping="0.0" friction="0.001" />
        <parent link="right_front_wheel" />
        <child link="right_front_roller_2" />
    </joint>
    <gazebo reference="right_front_roller_2">
        <mu1 value="2000.0" />
        <mu2 value="2000.0" />
        <kp value="1000000.0" />
        <kd value="100.0" />
        <material>Gazebo/Black</material>
    </gazebo>
    <!--  link  -->
    <link name="right_front_roller_3">
        <collision>
            <geometry>
                <sphere radius="0.009" />
            </geometry>
        </collision>
        <inertial>
            <mass value="0.036" />
            <inertia ixx="3128e-9" ixy="0.0" ixz="0.0" iyy="3128e-9" iyz="0.0" izz="3128e-9" />
            <origin xyz="0 0 0" rpy="0 0 0" />
        </inertial>
    </link>
    <joint name="right_front_roller_3_joint" type="continuous">
        <origin rpy="0 0 0" xyz="0.06284727452340379 0 -0.025965748303869884" />
        <axis xyz="0.2700081868271984 0.7071067811865476 0.6535254999204613" />
        <dynamics damping="0.0" friction="0.001" />
        <parent link="right_front_wheel" />
        <child link="right_front_roller_3" />
    </joint>
    <gazebo reference="right_front_roller_3">
        <mu1 value="2000.0" />
        <mu2 value="2000.0" />
        <kp value="1000000.0" />
        <kd value="100.0" />
        <material>Gazebo/Black</material>
    </gazebo>
    <!--  link  -->
    <link name="right_front_roller_4">
        <collision>
            <geometry>
                <sphere radius="0.009" />
            </geometry>
        </collision>
        <inertial>
            <mass value="0.036" />
            <inertia ixx="3128e-9" ixy="0.0" ixz="0.0" iyy="3128e-9" iyz="0.0" izz="3128e-9" />
            <origin xyz="0 0 0" rpy="0 0 0" />
        </inertial>
    </link>
    <joint name="right_front_roller_4_joint" type="continuous">
        <origin rpy="0 0 0" xyz="0.06799995073981367 0 8.184975818264867e-05" />
        <axis xyz="-0.0008511252801386329 0.7071067811865476 0.7071062689481388" />
        <dynamics damping="0.0" friction="0.001" />
        <parent link="right_front_wheel" />
        <child link="right_front_roller_4" />
    </joint>
    <gazebo reference="right_front_roller_4">
        <mu1 value="2000.0" />
        <mu2 value="2000.0" />
        <kp value="1000000.0" />
        <kd value="100.0" />
        <material>Gazebo/Black</material>
    </gazebo>
    <!--  link  -->
    <link name="right_front_roller_5">
        <collision>
            <geometry>
                <sphere radius="0.009" />
            </geometry>
        </collision>
        <inertial>
            <mass value="0.036" />
            <inertia ixx="3128e-9" ixy="0.0" ixz="0.0" iyy="3128e-9" iyz="0.0" izz="3128e-9" />
            <origin xyz="0 0 0" rpy="0 0 0" />
        </inertial>
    </link>
    <joint name="right_front_roller_5_joint" type="continuous">
        <origin rpy="0 0 0" xyz="0.06278458392296919 0 0.026116968078619688" />
        <axis xyz="-0.27158066518271434 0.7071067811865476 0.6528736036162853" />
        <dynamics damping="0.0" friction="0.001" />
        <parent link="right_front_wheel" />
        <child link="right_front_roller_5" />
    </joint>
    <gazebo reference="right_front_roller_5">
        <mu1 value="2000.0" />
        <mu2 value="2000.0" />
        <kp value="1000000.0" />
        <kd value="100.0" />
        <material>Gazebo/Black</material>
    </gazebo>
    <!--  link  -->
    <link name="right_front_roller_6">
        <collision>
            <geometry>
                <sphere radius="0.009" />
            </geometry>
        </collision>
        <inertial>
            <mass value="0.036" />
            <inertia ixx="3128e-9" ixy="0.0" ixz="0.0" iyy="3128e-9" iyz="0.0" izz="3128e-9" />
            <origin xyz="0 0 0" rpy="0 0 0" />
        </inertial>
    </link>
    <joint name="right_front_roller_6_joint" type="continuous">
        <origin rpy="0 0 0" xyz="0.0479963679958505 0 0.04816999750059053" />
        <axis xyz="-0.5009019394471561 0.7071067811865476 0.499096430620454" />
        <dynamics damping="0.0" friction="0.001" />
        <parent link="right_front_wheel" />
        <child link="right_front_roller_6" />
    </joint>
    <gazebo reference="right_front_roller_6">
        <mu1 value="2000.0" />
        <mu2 value="2000.0" />
        <kp value="1000000.0" />
        <kd value="100.0" />
        <material>Gazebo/Black</material>
    </gazebo>
    <!--  link  -->
    <link name="right_front_roller_7">
        <collision>
            <geometry>
                <sphere radius="0.009" />
            </geometry>
        </collision>
        <inertial>
            <mass value="0.036" />
            <inertia ixx="3128e-9" ixy="0.0" ixz="0.0" iyy="3128e-9" iyz="0.0" izz="3128e-9" />
            <origin xyz="0 0 0" rpy="0 0 0" />
        </inertial>
    </link>
    <joint name="right_front_roller_7_joint" type="continuous">
        <origin rpy="0 0 0" xyz="0.0258900819318143 0 0.06287848326386335" />
        <axis xyz="-0.6538500280382736 0.7071067811865476 0.2692213602861942" />
        <dynamics damping="0.0" friction="0.001" />
        <parent link="right_front_wheel" />
        <child link="right_front_roller_7" />
    </joint>
    <gazebo reference="right_front_roller_7">
        <mu1 value="2000.0" />
        <mu2 value="2000.0" />
        <kp value="1000000.0" />
        <kd value="100.0" />
        <material>Gazebo/Black</material>
    </gazebo>
    <!--  link  -->
    <link name="right_front_roller_8">
        <collision>
            <geometry>
                <sphere radius="0.009" />
            </geometry>
        </collision>
        <inertial>
            <mass value="0.036" />
            <inertia ixx="3128e-9" ixy="0.0" ixz="0.0" iyy="3128e-9" iyz="0.0" izz="3128e-9" />
            <origin xyz="0 0 0" rpy="0 0 0" />
        </inertial>
    </link>
    <joint name="right_front_roller_8_joint" type="continuous">
        <origin rpy="0 0 0" xyz="-0.00016369939777898906 0 0.06799980295932605" />
        <axis xyz="-0.7071047322336546 0.7071067811865476 -0.0017022493271422689" />
        <dynamics damping="0.0" friction="0.001" />
        <parent link="right_front_wheel" />
        <child link="right_front_roller_8" />
    </joint>
    <gazebo reference="right_front_roller_8">
        <mu1 value="2000.0" />
        <mu2 value="2000.0" />
        <kp value="1000000.0" />
        <kd value="100.0" />
        <material>Gazebo/Black</material>
    </gazebo>
    <!--  link  -->
    <link name="right_front_roller_9">
        <collision>
            <geometry>
                <sphere radius="0.009" />
            </geometry>
        </collision>
        <inertial>
            <mass value="0.036" />
            <inertia ixx="3128e-9" ixy="0.0" ixz="0.0" iyy="3128e-9" iyz="0.0" izz="3128e-9" />
            <origin xyz="0 0 0" rpy="0 0 0" />
        </inertial>
    </link>
    <joint name="right_front_roller_9_joint" type="continuous">
        <origin rpy="0 0 0" xyz="-0.026192521262222306 0 0.06275310215382211" />
        <axis xyz="-0.6525462363744081 0.7071067811865476 -0.2723663147189738" />
        <dynamics damping="0.0" friction="0.001" />
        <parent link="right_front_wheel" />
        <child link="right_front_roller_9" />
    </joint>
    <gazebo reference="right_front_roller_9">
        <mu1 value="2000.0" />
        <mu2 value="2000.0" />
        <kp value="1000000.0" />
        <kd value="100.0" />
        <material>Gazebo/Black</material>
    </gazebo>
    <!--  link  -->
    <link name="right_front_roller_10">
        <collision>
            <geometry>
                <sphere radius="0.009" />
            </geometry>
        </collision>
        <inertial>
            <mass value="0.036" />
            <inertia ixx="3128e-9" ixy="0.0" ixz="0.0" iyy="3128e-9" iyz="0.0" izz="3128e-9" />
            <origin xyz="0 0 0" rpy="0 0 0" />
        </inertial>
    </link>
    <joint name="right_front_roller_10_joint" type="continuous">
        <origin rpy="0 0 0" xyz="-0.048227734533694264 0 0.04793835230530472" />
        <axis xyz="-0.49849314697045194 0.7071067811865476 -0.5015023254417625" />
        <dynamics damping="0.0" friction="0.001" />
        <parent link="right_front_wheel" />
        <child link="right_front_roller_10" />
    </joint>
    <gazebo reference="right_front_roller_10">
        <mu1 value="2000.0" />
        <mu2 value="2000.0" />
        <kp value="1000000.0" />
        <kd value="100.0" />
        <material>Gazebo/Black</material>
    </gazebo>
    <!--  link  -->
    <link name="right_front_roller_11">
        <collision>
            <geometry>
                <sphere radius="0.009" />
            </geometry>
        </collision>
        <inertial>
            <mass value="0.036" />
            <inertia ixx="3128e-9" ixy="0.0" ixz="0.0" iyy="3128e-9" iyz="0.0" izz="3128e-9" />
            <origin xyz="0 0 0" rpy="0 0 0" />
        </inertial>
    </link>
    <joint name="right_front_roller_11_joint" type="continuous">
        <origin rpy="0 0 0" xyz="-0.06290960090415226 0 0.02581437804945697" />
        <axis xyz="-0.2684341436894733 0.7071067811865476 -0.6541736088391974" />
        <dynamics damping="0.0" friction="0.001" />
        <parent link="right_front_wheel" />
        <child link="right_front_roller_11" />
    </joint>
    <gazebo reference="right_front_roller_11">
        <mu1 value="2000.0" />
        <mu2 value="2000.0" />
        <kp value="1000000.0" />
        <kd value="100.0" />
        <material>Gazebo/Black</material>
    </gazebo>
    <!--  link  -->
    <link name="right_front_roller_12">
        <collision>
            <geometry>
                <sphere radius="0.009" />
            </geometry>
        </collision>
        <inertial>
            <mass value="0.036" />
            <inertia ixx="3128e-9" ixy="0.0" ixz="0.0" iyy="3128e-9" iyz="0.0" izz="3128e-9" />
            <origin xyz="0 0 0" rpy="0 0 0" />
        </inertial>
    </link>
    <joint name="right_front_roller_12_joint" type="continuous">
        <origin rpy="0 0 0" xyz="-0.06799955665875124 0 -0.0002455488002028931" />
        <axis xyz="0.002553370907877698 0.7071067811865476 -0.7071021710453214" />
        <dynamics damping="0.0" friction="0.001" />
        <parent link="right_front_wheel" />
        <child link="right_front_roller_12" />
    </joint>
    <gazebo reference="right_front_roller_12">
        <mu1 value="2000.0" />
        <mu2 value="2000.0" />
        <kp value="1000000.0" />
        <kd value="100.0" />
        <material>Gazebo/Black</material>
    </gazebo>
    <!--  link  -->
    <link name="right_front_roller_13">
        <collision>
            <geometry>
                <sphere radius="0.009" />
            </geometry>
        </collision>
        <inertial>
            <mass value="0.036" />
            <inertia ixx="3128e-9" ixy="0.0" ixz="0.0" iyy="3128e-9" iyz="0.0" izz="3128e-9" />
            <origin xyz="0 0 0" rpy="0 0 0" />
        </inertial>
    </link>
    <joint name="right_front_roller_13_joint" type="continuous">
        <origin rpy="0 0 0" xyz="-0.06272152946616016 0 -0.026268036497340295" />
        <axis xyz="0.2731515696430154 0.7071067811865476 -0.6522179237046135" />
        <dynamics damping="0.0" friction="0.001" />
        <parent link="right_front_wheel" />
        <child link="right_front_roller_13" />
    </joint>
    <gazebo reference="right_front_roller_13">
        <mu1 value="2000.0" />
        <mu2 value="2000.0" />
        <kp value="1000000.0" />
        <kd value="100.0" />
        <material>Gazebo/Black</material>
    </gazebo>
    <!--  link  -->
    <link name="right_front_roller_14">
        <collision>
            <geometry>
                <sphere radius="0.009" />
            </geometry>
        </collision>
        <inertial>
            <mass value="0.036" />
            <inertia ixx="3128e-9" ixy="0.0" ixz="0.0" iyy="3128e-9" iyz="0.0" izz="3128e-9" />
            <origin xyz="0 0 0" rpy="0 0 0" />
        </inertial>
    </link>
    <joint name="right_front_roller_14_joint" type="continuous">
        <origin rpy="0 0 0" xyz="-0.04788026716028342 0 -0.04828540169305713" />
        <axis xyz="0.5021019848452515 0.7071067811865476 -0.49788914108911725" />
        <dynamics damping="0.0" friction="0.001" />
        <parent link="right_front_wheel" />
        <child link="right_front_roller_14" />
    </joint>
    <gazebo reference="right_front_roller_14">
        <mu1 value="2000.0" />
        <mu2 value="2000.0" />
        <kp value="1000000.0" />
        <kd value="100.0" />
        <material>Gazebo/Black</material>
    </gazebo>
    <!--  link  -->
    <link name="right_front_roller_15">
        <collision>
            <geometry>
                <sphere radius="0.009" />
            </geometry>
        </collision>
        <inertial>
            <mass value="0.036" />
            <inertia ixx="3128e-9" ixy="0.0" ixz="0.0" iyy="3128e-9" iyz="0.0" izz="3128e-9" />
            <origin xyz="0 0 0" rpy="0 0 0" />
        </inertial>
    </link>
    <joint name="right_front_roller_15_joint" type="continuous">
        <origin rpy="0 0 0" xyz="-0.025738636766479847 0 -0.06294062739918639" />
        <axis xyz="0.6544962418544192 0.7071067811865476 -0.2676465381775779" />
        <dynamics damping="0.0" friction="0.001" />
        <parent link="right_front_wheel" />
        <child link="right_front_roller_15" />
    </joint>
    <gazebo reference="right_front_roller_15">
        <mu1 value="2000.0" />
        <mu2 value="2000.0" />
        <kp value="1000000.0" />
        <kd value="100.0" />
        <material>Gazebo/Black</material>
    </gazebo>
    <!--  link  -->
    <link name="left_back_wheel">
        <visual>
            <geometry>
                <mesh filename="package://sp_description/meshes/common/mecanum_wheel/left_mecanum_wheel.STL" />
            </geometry>
        </visual>
        <inertial>
            <mass value="0.4235" />
            <inertia ixx="4.122e-4" ixy="0.0" ixz="0.0" iyy="7.398e-4" iyz="0.0" izz="4.122e-4" />
        </inertial>
    </link>
    <!--  joint  -->
    <joint name="left_back_wheel_joint" type="revolute">
        <axis xyz="0 1 0" />
        <origin rpy="0 0 0" xyz="-0.19727 0.223 0.000889" />
        <!--      limit not work while type="continuous"-->
        <limit effort="10" lower="-1e9" upper="1e9" velocity="70" />
        <dynamics damping="0.0" friction="0.05" />
        <parent link="base_link" />
        <child link="left_back_wheel" />
    </joint>
    <!--  link  -->
    <link name="left_back_roller_0">
        <collision>
            <geometry>
                <sphere radius="0.009" />
            </geometry>
        </collision>
        <inertial>
            <mass value="0.036" />
            <inertia ixx="3128e-9" ixy="0.0" ixz="0.0" iyy="3128e-9" iyz="0.0" izz="3128e-9" />
            <origin xyz="0 0 0" rpy="0 0 0" />
        </inertial>
    </link>
    <joint name="left_back_roller_0_joint" type="continuous">
        <origin rpy="0 0 0" xyz="4.163799117101001e-18 0 -0.068" />
        <axis xyz="0.7071067811865476 0.7071067811865476 0.0" />
        <dynamics damping="0.0" friction="0.001" />
        <parent link="left_back_wheel" />
        <child link="left_back_roller_0" />
    </joint>
    <gazebo reference="left_back_roller_0">
        <mu1 value="2000.0" />
        <mu2 value="2000.0" />
        <kp value="1000000.0" />
        <kd value="100.0" />
        <material>Gazebo/Black</material>
    </gazebo>
    <!--  link  -->
    <link name="left_back_roller_1">
        <collision>
            <geometry>
                <sphere radius="0.009" />
            </geometry>
        </collision>
        <inertial>
            <mass value="0.036" />
            <inertia ixx="3128e-9" ixy="0.0" ixz="0.0" iyy="3128e-9" iyz="0.0" izz="3128e-9" />
            <origin xyz="0 0 0" rpy="0 0 0" />
        </inertial>
    </link>
    <joint name="left_back_roller_1_joint" type="continuous">
        <origin rpy="0 0 0" xyz="0.026041377055996056 0 -0.06281597472798972" />
        <axis xyz="0.653200024955946 0.7071067811865476 0.27079462217250855" />
        <dynamics damping="0.0" friction="0.001" />
        <parent link="left_back_wheel" />
        <child link="left_back_roller_1" />
    </joint>
    <gazebo reference="left_back_roller_1">
        <mu1 value="2000.0" />
        <mu2 value="2000.0" />
        <kp value="1000000.0" />
        <kd value="100.0" />
        <material>Gazebo/Black</material>
    </gazebo>
    <!--  link  -->
    <link name="left_back_roller_2">
        <collision>
            <geometry>
                <sphere radius="0.009" />
            </geometry>
        </collision>
        <inertial>
            <mass value="0.036" />
            <inertia ixx="3128e-9" ixy="0.0" ixz="0.0" iyy="3128e-9" iyz="0.0" izz="3128e-9" />
            <origin xyz="0 0 0" rpy="0 0 0" />
        </inertial>
    </link>
    <joint name="left_back_roller_2_joint" type="continuous">
        <origin rpy="0 0 0" xyz="0.04811219067739703 0 -0.048054314147865956" />
        <axis xyz="0.49969899116506866 0.7071067811865476 0.5003008277312888" />
        <dynamics damping="0.0" friction="0.001" />
        <parent link="left_back_wheel" />
        <child link="left_back_roller_2" />
    </joint>
    <gazebo reference="left_back_roller_2">
        <mu1 value="2000.0" />
        <mu2 value="2000.0" />
        <kp value="1000000.0" />
        <kd value="100.0" />
        <material>Gazebo/Black</material>
    </gazebo>
    <!--  link  -->
    <link name="left_back_roller_3">
        <collision>
            <geometry>
                <sphere radius="0.009" />
            </geometry>
        </collision>
        <inertial>
            <mass value="0.036" />
            <inertia ixx="3128e-9" ixy="0.0" ixz="0.0" iyy="3128e-9" iyz="0.0" izz="3128e-9" />
            <origin xyz="0 0 0" rpy="0 0 0" />
        </inertial>
    </link>
    <joint name="left_back_roller_3_joint" type="continuous">
        <origin rpy="0 0 0" xyz="0.06284727452340379 0 -0.025965748303869884" />
        <axis xyz="0.2700081868271984 0.7071067811865476 0.6535254999204613" />
        <dynamics damping="0.0" friction="0.001" />
        <parent link="left_back_wheel" />
        <child link="left_back_roller_3" />
    </joint>
    <gazebo reference="left_back_roller_3">
        <mu1 value="2000.0" />
        <mu2 value="2000.0" />
        <kp value="1000000.0" />
        <kd value="100.0" />
        <material>Gazebo/Black</material>
    </gazebo>
    <!--  link  -->
    <link name="left_back_roller_4">
        <collision>
            <geometry>
                <sphere radius="0.009" />
            </geometry>
        </collision>
        <inertial>
            <mass value="0.036" />
            <inertia ixx="3128e-9" ixy="0.0" ixz="0.0" iyy="3128e-9" iyz="0.0" izz="3128e-9" />
            <origin xyz="0 0 0" rpy="0 0 0" />
        </inertial>
    </link>
    <joint name="left_back_roller_4_joint" type="continuous">
        <origin rpy="0 0 0" xyz="0.06799995073981367 0 8.184975818264867e-05" />
        <axis xyz="-0.0008511252801386329 0.7071067811865476 0.7071062689481388" />
        <dynamics damping="0.0" friction="0.001" />
        <parent link="left_back_wheel" />
        <child link="left_back_roller_4" />
    </joint>
    <gazebo reference="left_back_roller_4">
        <mu1 value="2000.0" />
        <mu2 value="2000.0" />
        <kp value="1000000.0" />
        <kd value="100.0" />
        <material>Gazebo/Black</material>
    </gazebo>
    <!--  link  -->
    <link name="left_back_roller_5">
        <collision>
            <geometry>
                <sphere radius="0.009" />
            </geometry>
        </collision>
        <inertial>
            <mass value="0.036" />
            <inertia ixx="3128e-9" ixy="0.0" ixz="0.0" iyy="3128e-9" iyz="0.0" izz="3128e-9" />
            <origin xyz="0 0 0" rpy="0 0 0" />
        </inertial>
    </link>
    <joint name="left_back_roller_5_joint" type="continuous">
        <origin rpy="0 0 0" xyz="0.06278458392296919 0 0.026116968078619688" />
        <axis xyz="-0.27158066518271434 0.7071067811865476 0.6528736036162853" />
        <dynamics damping="0.0" friction="0.001" />
        <parent link="left_back_wheel" />
        <child link="left_back_roller_5" />
    </joint>
    <gazebo reference="left_back_roller_5">
        <mu1 value="2000.0" />
        <mu2 value="2000.0" />
        <kp value="1000000.0" />
        <kd value="100.0" />
        <material>Gazebo/Black</material>
    </gazebo>
    <!--  link  -->
    <link name="left_back_roller_6">
        <collision>
            <geometry>
                <sphere radius="0.009" />
            </geometry>
        </collision>
        <inertial>
            <mass value="0.036" />
            <inertia ixx="3128e-9" ixy="0.0" ixz="0.0" iyy="3128e-9" iyz="0.0" izz="3128e-9" />
            <origin xyz="0 0 0" rpy="0 0 0" />
        </inertial>
    </link>
    <joint name="left_back_roller_6_joint" type="continuous">
        <origin rpy="0 0 0" xyz="0.0479963679958505 0 0.04816999750059053" />
        <axis xyz="-0.5009019394471561 0.7071067811865476 0.499096430620454" />
        <dynamics damping="0.0" friction="0.001" />
        <parent link="left_back_wheel" />
        <child link="left_back_roller_6" />
    </joint>
    <gazebo reference="left_back_roller_6">
        <mu1 value="2000.0" />
        <mu2 value="2000.0" />
        <kp value="1000000.0" />
        <kd value="100.0" />
        <material>Gazebo/Black</material>
    </gazebo>
    <!--  link  -->
    <link name="left_back_roller_7">
        <collision>
            <geometry>
                <sphere radius="0.009" />
            </geometry>
        </collision>
        <inertial>
            <mass value="0.036" />
            <inertia ixx="3128e-9" ixy="0.0" ixz="0.0" iyy="3128e-9" iyz="0.0" izz="3128e-9" />
            <origin xyz="0 0 0" rpy="0 0 0" />
        </inertial>
    </link>
    <joint name="left_back_roller_7_joint" type="continuous">
        <origin rpy="0 0 0" xyz="0.0258900819318143 0 0.06287848326386335" />
        <axis xyz="-0.6538500280382736 0.7071067811865476 0.2692213602861942" />
        <dynamics damping="0.0" friction="0.001" />
        <parent link="left_back_wheel" />
        <child link="left_back_roller_7" />
    </joint>
    <gazebo reference="left_back_roller_7">
        <mu1 value="2000.0" />
        <mu2 value="2000.0" />
        <kp value="1000000.0" />
        <kd value="100.0" />
        <material>Gazebo/Black</material>
    </gazebo>
    <!--  link  -->
    <link name="left_back_roller_8">
        <collision>
            <geometry>
                <sphere radius="0.009" />
            </geometry>
        </collision>
        <inertial>
            <mass value="0.036" />
            <inertia ixx="3128e-9" ixy="0.0" ixz="0.0" iyy="3128e-9" iyz="0.0" izz="3128e-9" />
            <origin xyz="0 0 0" rpy="0 0 0" />
        </inertial>
    </link>
    <joint name="left_back_roller_8_joint" type="continuous">
        <origin rpy="0 0 0" xyz="-0.00016369939777898906 0 0.06799980295932605" />
        <axis xyz="-0.7071047322336546 0.7071067811865476 -0.0017022493271422689" />
        <dynamics damping="0.0" friction="0.001" />
        <parent link="left_back_wheel" />
        <child link="left_back_roller_8" />
    </joint>
    <gazebo reference="left_back_roller_8">
        <mu1 value="2000.0" />
        <mu2 value="2000.0" />
        <kp value="1000000.0" />
        <kd value="100.0" />
        <material>Gazebo/Black</material>
    </gazebo>
    <!--  link  -->
    <link name="left_back_roller_9">
        <collision>
            <geometry>
                <sphere radius="0.009" />
            </geometry>
        </collision>
        <inertial>
            <mass value="0.036" />
            <inertia ixx="3128e-9" ixy="0.0" ixz="0.0" iyy="3128e-9" iyz="0.0" izz="3128e-9" />
            <origin xyz="0 0 0" rpy="0 0 0" />
        </inertial>
    </link>
    <joint name="left_back_roller_9_joint" type="continuous">
        <origin rpy="0 0 0" xyz="-0.026192521262222306 0 0.06275310215382211" />
        <axis xyz="-0.6525462363744081 0.7071067811865476 -0.2723663147189738" />
        <dynamics damping="0.0" friction="0.001" />
        <parent link="left_back_wheel" />
        <child link="left_back_roller_9" />
    </joint>
    <gazebo reference="left_back_roller_9">
        <mu1 value="2000.0" />
        <mu2 value="2000.0" />
        <kp value="1000000.0" />
        <kd value="100.0" />
        <material>Gazebo/Black</material>
    </gazebo>
    <!--  link  -->
    <link name="left_back_roller_10">
        <collision>
            <geometry>
                <sphere radius="0.009" />
            </geometry>
        </collision>
        <inertial>
            <mass value="0.036" />
            <inertia ixx="3128e-9" ixy="0.0" ixz="0.0" iyy="3128e-9" iyz="0.0" izz="3128e-9" />
            <origin xyz="0 0 0" rpy="0 0 0" />
        </inertial>
    </link>
    <joint name="left_back_roller_10_joint" type="continuous">
        <origin rpy="0 0 0" xyz="-0.048227734533694264 0 0.04793835230530472" />
        <axis xyz="-0.49849314697045194 0.7071067811865476 -0.5015023254417625" />
        <dynamics damping="0.0" friction="0.001" />
        <parent link="left_back_wheel" />
        <child link="left_back_roller_10" />
    </joint>
    <gazebo reference="left_back_roller_10">
        <mu1 value="2000.0" />
        <mu2 value="2000.0" />
        <kp value="1000000.0" />
        <kd value="100.0" />
        <material>Gazebo/Black</material>
    </gazebo>
    <!--  link  -->
    <link name="left_back_roller_11">
        <collision>
            <geometry>
                <sphere radius="0.009" />
            </geometry>
        </collision>
        <inertial>
            <mass value="0.036" />
            <inertia ixx="3128e-9" ixy="0.0" ixz="0.0" iyy="3128e-9" iyz="0.0" izz="3128e-9" />
            <origin xyz="0 0 0" rpy="0 0 0" />
        </inertial>
    </link>
    <joint name="left_back_roller_11_joint" type="continuous">
        <origin rpy="0 0 0" xyz="-0.06290960090415226 0 0.02581437804945697" />
        <axis xyz="-0.2684341436894733 0.7071067811865476 -0.6541736088391974" />
        <dynamics damping="0.0" friction="0.001" />
        <parent link="left_back_wheel" />
        <child link="left_back_roller_11" />
    </joint>
    <gazebo reference="left_back_roller_11">
        <mu1 value="2000.0" />
        <mu2 value="2000.0" />
        <kp value="1000000.0" />
        <kd value="100.0" />
        <material>Gazebo/Black</material>
    </gazebo>
    <!--  link  -->
    <link name="left_back_roller_12">
        <collision>
            <geometry>
                <sphere radius="0.009" />
            </geometry>
        </collision>
        <inertial>
            <mass value="0.036" />
            <inertia ixx="3128e-9" ixy="0.0" ixz="0.0" iyy="3128e-9" iyz="0.0" izz="3128e-9" />
            <origin xyz="0 0 0" rpy="0 0 0" />
        </inertial>
    </link>
    <joint name="left_back_roller_12_joint" type="continuous">
        <origin rpy="0 0 0" xyz="-0.06799955665875124 0 -0.0002455488002028931" />
        <axis xyz="0.002553370907877698 0.7071067811865476 -0.7071021710453214" />
        <dynamics damping="0.0" friction="0.001" />
        <parent link="left_back_wheel" />
        <child link="left_back_roller_12" />
    </joint>
    <gazebo reference="left_back_roller_12">
        <mu1 value="2000.0" />
        <mu2 value="2000.0" />
        <kp value="1000000.0" />
        <kd value="100.0" />
        <material>Gazebo/Black</material>
    </gazebo>
    <!--  link  -->
    <link name="left_back_roller_13">
        <collision>
            <geometry>
                <sphere radius="0.009" />
            </geometry>
        </collision>
        <inertial>
            <mass value="0.036" />
            <inertia ixx="3128e-9" ixy="0.0" ixz="0.0" iyy="3128e-9" iyz="0.0" izz="3128e-9" />
            <origin xyz="0 0 0" rpy="0 0 0" />
        </inertial>
    </link>
    <joint name="left_back_roller_13_joint" type="continuous">
        <origin rpy="0 0 0" xyz="-0.06272152946616016 0 -0.026268036497340295" />
        <axis xyz="0.2731515696430154 0.7071067811865476 -0.6522179237046135" />
        <dynamics damping="0.0" friction="0.001" />
        <parent link="left_back_wheel" />
        <child link="left_back_roller_13" />
    </joint>
    <gazebo reference="left_back_roller_13">
        <mu1 value="2000.0" />
        <mu2 value="2000.0" />
        <kp value="1000000.0" />
        <kd value="100.0" />
        <material>Gazebo/Black</material>
    </gazebo>
    <!--  link  -->
    <link name="left_back_roller_14">
        <collision>
            <geometry>
                <sphere radius="0.009" />
            </geometry>
        </collision>
        <inertial>
            <mass value="0.036" />
            <inertia ixx="3128e-9" ixy="0.0" ixz="0.0" iyy="3128e-9" iyz="0.0" izz="3128e-9" />
            <origin xyz="0 0 0" rpy="0 0 0" />
        </inertial>
    </link>
    <joint name="left_back_roller_14_joint" type="continuous">
        <origin rpy="0 0 0" xyz="-0.04788026716028342 0 -0.04828540169305713" />
        <axis xyz="0.5021019848452515 0.7071067811865476 -0.49788914108911725" />
        <dynamics damping="0.0" friction="0.001" />
        <parent link="left_back_wheel" />
        <child link="left_back_roller_14" />
    </joint>
    <gazebo reference="left_back_roller_14">
        <mu1 value="2000.0" />
        <mu2 value="2000.0" />
        <kp value="1000000.0" />
        <kd value="100.0" />
        <material>Gazebo/Black</material>
    </gazebo>
    <!--  link  -->
    <link name="left_back_roller_15">
        <collision>
            <geometry>
                <sphere radius="0.009" />
            </geometry>
        </collision>
        <inertial>
            <mass value="0.036" />
            <inertia ixx="3128e-9" ixy="0.0" ixz="0.0" iyy="3128e-9" iyz="0.0" izz="3128e-9" />
            <origin xyz="0 0 0" rpy="0 0 0" />
        </inertial>
    </link>
    <joint name="left_back_roller_15_joint" type="continuous">
        <origin rpy="0 0 0" xyz="-0.025738636766479847 0 -0.06294062739918639" />
        <axis xyz="0.6544962418544192 0.7071067811865476 -0.2676465381775779" />
        <dynamics damping="0.0" friction="0.001" />
        <parent link="left_back_wheel" />
        <child link="left_back_roller_15" />
    </joint>
    <gazebo reference="left_back_roller_15">
        <mu1 value="2000.0" />
        <mu2 value="2000.0" />
        <kp value="1000000.0" />
        <kd value="100.0" />
        <material>Gazebo/Black</material>
    </gazebo>
    <!--  link  -->
    <link name="right_back_wheel">
        <visual>
            <geometry>
                <mesh filename="package://sp_description/meshes/common/mecanum_wheel/right_mecanum_wheel.STL" />
            </geometry>
        </visual>
        <inertial>
            <mass value="0.4235" />
            <inertia ixx="4.122e-4" ixy="0.0" ixz="0.0" iyy="7.398e-4" iyz="0.0" izz="4.122e-4" />
        </inertial>
    </link>
    <!--  joint  -->
    <joint name="right_back_wheel_joint" type="revolute">
        <axis xyz="0 1 0" />
        <origin rpy="0 0 0" xyz="-0.19727 -0.223 0.000889" />
        <!--      limit not work while type="continuous"-->
        <limit effort="10" lower="-1e9" upper="1e9" velocity="70" />
        <dynamics damping="0.0" friction="0.05" />
        <parent link="base_link" />
        <child link="right_back_wheel" />
    </joint>
    <!--  link  -->
    <link name="right_back_roller_0">
        <collision>
            <geometry>
                <sphere radius="0.009" />
            </geometry>
        </collision>
        <inertial>
            <mass value="0.036" />
            <inertia ixx="3128e-9" ixy="0.0" ixz="0.0" iyy="3128e-9" iyz="0.0" izz="3128e-9" />
            <origin xyz="0 0 0" rpy="0 0 0" />
        </inertial>
    </link>
    <joint name="right_back_roller_0_joint" type="continuous">
        <origin rpy="0 0 0" xyz="4.163799117101001e-18 0 -0.068" />
        <axis xyz="0.7071067811865476 -0.7071067811865476 0.0" />
        <dynamics damping="0.0" friction="0.001" />
        <parent link="right_back_wheel" />
        <child link="right_back_roller_0" />
    </joint>
    <gazebo reference="right_back_roller_0">
        <mu1 value="2000.0" />
        <mu2 value="2000.0" />
        <kp value="1000000.0" />
        <kd value="100.0" />
        <material>Gazebo/Black</material>
    </gazebo>
    <!--  link  -->
    <link name="right_back_roller_1">
        <collision>
            <geometry>
                <sphere radius="0.009" />
            </geometry>
        </collision>
        <inertial>
            <mass value="0.036" />
            <inertia ixx="3128e-9" ixy="0.0" ixz="0.0" iyy="3128e-9" iyz="0.0" izz="3128e-9" />
            <origin xyz="0 0 0" rpy="0 0 0" />
        </inertial>
    </link>
    <joint name="right_back_roller_1_joint" type="continuous">
        <origin rpy="0 0 0" xyz="0.026041377055996056 0 -0.06281597472798972" />
        <axis xyz="0.653200024955946 -0.7071067811865476 0.27079462217250855" />
        <dynamics damping="0.0" friction="0.001" />
        <parent link="right_back_wheel" />
        <child link="right_back_roller_1" />
    </joint>
    <gazebo reference="right_back_roller_1">
        <mu1 value="2000.0" />
        <mu2 value="2000.0" />
        <kp value="1000000.0" />
        <kd value="100.0" />
        <material>Gazebo/Black</material>
    </gazebo>
    <!--  link  -->
    <link name="right_back_roller_2">
        <collision>
            <geometry>
                <sphere radius="0.009" />
            </geometry>
        </collision>
        <inertial>
            <mass value="0.036" />
            <inertia ixx="3128e-9" ixy="0.0" ixz="0.0" iyy="3128e-9" iyz="0.0" izz="3128e-9" />
            <origin xyz="0 0 0" rpy="0 0 0" />
        </inertial>
    </link>
    <joint name="right_back_roller_2_joint" type="continuous">
        <origin rpy="0 0 0" xyz="0.04811219067739703 0 -0.048054314147865956" />
        <axis xyz="0.49969899116506866 -0.7071067811865476 0.5003008277312888" />
        <dynamics damping="0.0" friction="0.001" />
        <parent link="right_back_wheel" />
        <child link="right_back_roller_2" />
    </joint>
    <gazebo reference="right_back_roller_2">
        <mu1 value="2000.0" />
        <mu2 value="2000.0" />
        <kp value="1000000.0" />
        <kd value="100.0" />
        <material>Gazebo/Black</material>
    </gazebo>
    <!--  link  -->
    <link name="right_back_roller_3">
        <collision>
            <geometry>
                <sphere radius="0.009" />
            </geometry>
        </collision>
        <inertial>
            <mass value="0.036" />
            <inertia ixx="3128e-9" ixy="0.0" ixz="0.0" iyy="3128e-9" iyz="0.0" izz="3128e-9" />
            <origin xyz="0 0 0" rpy="0 0 0" />
        </inertial>
    </link>
    <joint name="right_back_roller_3_joint" type="continuous">
        <origin rpy="0 0 0" xyz="0.06284727452340379 0 -0.025965748303869884" />
        <axis xyz="0.2700081868271984 -0.7071067811865476 0.6535254999204613" />
        <dynamics damping="0.0" friction="0.001" />
        <parent link="right_back_wheel" />
        <child link="right_back_roller_3" />
    </joint>
    <gazebo reference="right_back_roller_3">
        <mu1 value="2000.0" />
        <mu2 value="2000.0" />
        <kp value="1000000.0" />
        <kd value="100.0" />
        <material>Gazebo/Black</material>
    </gazebo>
    <!--  link  -->
    <link name="right_back_roller_4">
        <collision>
            <geometry>
                <sphere radius="0.009" />
            </geometry>
        </collision>
        <inertial>
            <mass value="0.036" />
            <inertia ixx="3128e-9" ixy="0.0" ixz="0.0" iyy="3128e-9" iyz="0.0" izz="3128e-9" />
            <origin xyz="0 0 0" rpy="0 0 0" />
        </inertial>
    </link>
    <joint name="right_back_roller_4_joint" type="continuous">
        <origin rpy="0 0 0" xyz="0.06799995073981367 0 8.184975818264867e-05" />
        <axis xyz="-0.0008511252801386329 -0.7071067811865476 0.7071062689481388" />
        <dynamics damping="0.0" friction="0.001" />
        <parent link="right_back_wheel" />
        <child link="right_back_roller_4" />
    </joint>
    <gazebo reference="right_back_roller_4">
        <mu1 value="2000.0" />
        <mu2 value="2000.0" />
        <kp value="1000000.0" />
        <kd value="100.0" />
        <material>Gazebo/Black</material>
    </gazebo>
    <!--  link  -->
    <link name="right_back_roller_5">
        <collision>
            <geometry>
                <sphere radius="0.009" />
            </geometry>
        </collision>
        <inertial>
            <mass value="0.036" />
            <inertia ixx="3128e-9" ixy="0.0" ixz="0.0" iyy="3128e-9" iyz="0.0" izz="3128e-9" />
            <origin xyz="0 0 0" rpy="0 0 0" />
        </inertial>
    </link>
    <joint name="right_back_roller_5_joint" type="continuous">
        <origin rpy="0 0 0" xyz="0.06278458392296919 0 0.026116968078619688" />
        <axis xyz="-0.27158066518271434 -0.7071067811865476 0.6528736036162853" />
        <dynamics damping="0.0" friction="0.001" />
        <parent link="right_back_wheel" />
        <child link="right_back_roller_5" />
    </joint>
    <gazebo reference="right_back_roller_5">
        <mu1 value="2000.0" />
        <mu2 value="2000.0" />
        <kp value="1000000.0" />
        <kd value="100.0" />
        <material>Gazebo/Black</material>
    </gazebo>
    <!--  link  -->
    <link name="right_back_roller_6">
        <collision>
            <geometry>
                <sphere radius="0.009" />
            </geometry>
        </collision>
        <inertial>
            <mass value="0.036" />
            <inertia ixx="3128e-9" ixy="0.0" ixz="0.0" iyy="3128e-9" iyz="0.0" izz="3128e-9" />
            <origin xyz="0 0 0" rpy="0 0 0" />
        </inertial>
    </link>
    <joint name="right_back_roller_6_joint" type="continuous">
        <origin rpy="0 0 0" xyz="0.0479963679958505 0 0.04816999750059053" />
        <axis xyz="-0.5009019394471561 -0.7071067811865476 0.499096430620454" />
        <dynamics damping="0.0" friction="0.001" />
        <parent link="right_back_wheel" />
        <child link="right_back_roller_6" />
    </joint>
    <gazebo reference="right_back_roller_6">
        <mu1 value="2000.0" />
        <mu2 value="2000.0" />
        <kp value="1000000.0" />
        <kd value="100.0" />
        <material>Gazebo/Black</material>
    </gazebo>
    <!--  link  -->
    <link name="right_back_roller_7">
        <collision>
            <geometry>
                <sphere radius="0.009" />
            </geometry>
        </collision>
        <inertial>
            <mass value="0.036" />
            <inertia ixx="3128e-9" ixy="0.0" ixz="0.0" iyy="3128e-9" iyz="0.0" izz="3128e-9" />
            <origin xyz="0 0 0" rpy="0 0 0" />
        </inertial>
    </link>
    <joint name="right_back_roller_7_joint" type="continuous">
        <origin rpy="0 0 0" xyz="0.0258900819318143 0 0.06287848326386335" />
        <axis xyz="-0.6538500280382736 -0.7071067811865476 0.2692213602861942" />
        <dynamics damping="0.0" friction="0.001" />
        <parent link="right_back_wheel" />
        <child link="right_back_roller_7" />
    </joint>
    <gazebo reference="right_back_roller_7">
        <mu1 value="2000.0" />
        <mu2 value="2000.0" />
        <kp value="1000000.0" />
        <kd value="100.0" />
        <material>Gazebo/Black</material>
    </gazebo>
    <!--  link  -->
    <link name="right_back_roller_8">
        <collision>
            <geometry>
                <sphere radius="0.009" />
            </geometry>
        </collision>
        <inertial>
            <mass value="0.036" />
            <inertia ixx="3128e-9" ixy="0.0" ixz="0.0" iyy="3128e-9" iyz="0.0" izz="3128e-9" />
            <origin xyz="0 0 0" rpy="0 0 0" />
        </inertial>
    </link>
    <joint name="right_back_roller_8_joint" type="continuous">
        <origin rpy="0 0 0" xyz="-0.00016369939777898906 0 0.06799980295932605" />
        <axis xyz="-0.7071047322336546 -0.7071067811865476 -0.0017022493271422689" />
        <dynamics damping="0.0" friction="0.001" />
        <parent link="right_back_wheel" />
        <child link="right_back_roller_8" />
    </joint>
    <gazebo reference="right_back_roller_8">
        <mu1 value="2000.0" />
        <mu2 value="2000.0" />
        <kp value="1000000.0" />
        <kd value="100.0" />
        <material>Gazebo/Black</material>
    </gazebo>
    <!--  link  -->
    <link name="right_back_roller_9">
        <collision>
            <geometry>
                <sphere radius="0.009" />
            </geometry>
        </collision>
        <inertial>
            <mass value="0.036" />
            <inertia ixx="3128e-9" ixy="0.0" ixz="0.0" iyy="3128e-9" iyz="0.0" izz="3128e-9" />
            <origin xyz="0 0 0" rpy="0 0 0" />
        </inertial>
    </link>
    <joint name="right_back_roller_9_joint" type="continuous">
        <origin rpy="0 0 0" xyz="-0.026192521262222306 0 0.06275310215382211" />
        <axis xyz="-0.6525462363744081 -0.7071067811865476 -0.2723663147189738" />
        <dynamics damping="0.0" friction="0.001" />
        <parent link="right_back_wheel" />
        <child link="right_back_roller_9" />
    </joint>
    <gazebo reference="right_back_roller_9">
        <mu1 value="2000.0" />
        <mu2 value="2000.0" />
        <kp value="1000000.0" />
        <kd value="100.0" />
        <material>Gazebo/Black</material>
    </gazebo>
    <!--  link  -->
    <link name="right_back_roller_10">
        <collision>
            <geometry>
                <sphere radius="0.009" />
            </geometry>
        </collision>
        <inertial>
            <mass value="0.036" />
            <inertia ixx="3128e-9" ixy="0.0" ixz="0.0" iyy="3128e-9" iyz="0.0" izz="3128e-9" />
            <origin xyz="0 0 0" rpy="0 0 0" />
        </inertial>
    </link>
    <joint name="right_back_roller_10_joint" type="continuous">
        <origin rpy="0 0 0" xyz="-0.048227734533694264 0 0.04793835230530472" />
        <axis xyz="-0.49849314697045194 -0.7071067811865476 -0.5015023254417625" />
        <dynamics damping="0.0" friction="0.001" />
        <parent link="right_back_wheel" />
        <child link="right_back_roller_10" />
    </joint>
    <gazebo reference="right_back_roller_10">
        <mu1 value="2000.0" />
        <mu2 value="2000.0" />
        <kp value="1000000.0" />
        <kd value="100.0" />
        <material>Gazebo/Black</material>
    </gazebo>
    <!--  link  -->
    <link name="right_back_roller_11">
        <collision>
            <geometry>
                <sphere radius="0.009" />
            </geometry>
        </collision>
        <inertial>
            <mass value="0.036" />
            <inertia ixx="3128e-9" ixy="0.0" ixz="0.0" iyy="3128e-9" iyz="0.0" izz="3128e-9" />
            <origin xyz="0 0 0" rpy="0 0 0" />
        </inertial>
    </link>
    <joint name="right_back_roller_11_joint" type="continuous">
        <origin rpy="0 0 0" xyz="-0.06290960090415226 0 0.02581437804945697" />
        <axis xyz="-0.2684341436894733 -0.7071067811865476 -0.6541736088391974" />
        <dynamics damping="0.0" friction="0.001" />
        <parent link="right_back_wheel" />
        <child link="right_back_roller_11" />
    </joint>
    <gazebo reference="right_back_roller_11">
        <mu1 value="2000.0" />
        <mu2 value="2000.0" />
        <kp value="1000000.0" />
        <kd value="100.0" />
        <material>Gazebo/Black</material>
    </gazebo>
    <!--  link  -->
    <link name="right_back_roller_12">
        <collision>
            <geometry>
                <sphere radius="0.009" />
            </geometry>
        </collision>
        <inertial>
            <mass value="0.036" />
            <inertia ixx="3128e-9" ixy="0.0" ixz="0.0" iyy="3128e-9" iyz="0.0" izz="3128e-9" />
            <origin xyz="0 0 0" rpy="0 0 0" />
        </inertial>
    </link>
    <joint name="right_back_roller_12_joint" type="continuous">
        <origin rpy="0 0 0" xyz="-0.06799955665875124 0 -0.0002455488002028931" />
        <axis xyz="0.002553370907877698 -0.7071067811865476 -0.7071021710453214" />
        <dynamics damping="0.0" friction="0.001" />
        <parent link="right_back_wheel" />
        <child link="right_back_roller_12" />
    </joint>
    <gazebo reference="right_back_roller_12">
        <mu1 value="2000.0" />
        <mu2 value="2000.0" />
        <kp value="1000000.0" />
        <kd value="100.0" />
        <material>Gazebo/Black</material>
    </gazebo>
    <!--  link  -->
    <link name="right_back_roller_13">
        <collision>
            <geometry>
                <sphere radius="0.009" />
            </geometry>
        </collision>
        <inertial>
            <mass value="0.036" />
            <inertia ixx="3128e-9" ixy="0.0" ixz="0.0" iyy="3128e-9" iyz="0.0" izz="3128e-9" />
            <origin xyz="0 0 0" rpy="0 0 0" />
        </inertial>
    </link>
    <joint name="right_back_roller_13_joint" type="continuous">
        <origin rpy="0 0 0" xyz="-0.06272152946616016 0 -0.026268036497340295" />
        <axis xyz="0.2731515696430154 -0.7071067811865476 -0.6522179237046135" />
        <dynamics damping="0.0" friction="0.001" />
        <parent link="right_back_wheel" />
        <child link="right_back_roller_13" />
    </joint>
    <gazebo reference="right_back_roller_13">
        <mu1 value="2000.0" />
        <mu2 value="2000.0" />
        <kp value="1000000.0" />
        <kd value="100.0" />
        <material>Gazebo/Black</material>
    </gazebo>
    <!--  link  -->
    <link name="right_back_roller_14">
        <collision>
            <geometry>
                <sphere radius="0.009" />
            </geometry>
        </collision>
        <inertial>
            <mass value="0.036" />
            <inertia ixx="3128e-9" ixy="0.0" ixz="0.0" iyy="3128e-9" iyz="0.0" izz="3128e-9" />
            <origin xyz="0 0 0" rpy="0 0 0" />
        </inertial>
    </link>
    <joint name="right_back_roller_14_joint" type="continuous">
        <origin rpy="0 0 0" xyz="-0.04788026716028342 0 -0.04828540169305713" />
        <axis xyz="0.5021019848452515 -0.7071067811865476 -0.49788914108911725" />
        <dynamics damping="0.0" friction="0.001" />
        <parent link="right_back_wheel" />
        <child link="right_back_roller_14" />
    </joint>
    <gazebo reference="right_back_roller_14">
        <mu1 value="2000.0" />
        <mu2 value="2000.0" />
        <kp value="1000000.0" />
        <kd value="100.0" />
        <material>Gazebo/Black</material>
    </gazebo>
    <!--  link  -->
    <link name="right_back_roller_15">
        <collision>
            <geometry>
                <sphere radius="0.009" />
            </geometry>
        </collision>
        <inertial>
            <mass value="0.036" />
            <inertia ixx="3128e-9" ixy="0.0" ixz="0.0" iyy="3128e-9" iyz="0.0" izz="3128e-9" />
            <origin xyz="0 0 0" rpy="0 0 0" />
        </inertial>
    </link>
    <joint name="right_back_roller_15_joint" type="continuous">
        <origin rpy="0 0 0" xyz="-0.025738636766479847 0 -0.06294062739918639" />
        <axis xyz="0.6544962418544192 -0.7071067811865476 -0.2676465381775779" />
        <dynamics damping="0.0" friction="0.001" />
        <parent link="right_back_wheel" />
        <child link="right_back_roller_15" />
    </joint>
    <gazebo reference="right_back_roller_15">
        <mu1 value="2000.0" />
        <mu2 value="2000.0" />
        <kp value="1000000.0" />
        <kd value="100.0" />
        <material>Gazebo/Black</material>
    </gazebo>
    <transmission name="left_front_wheel_trans">
        <type>transmission_interface/SimpleTransmission</type>
        <actuator name="left_front_wheel_motor">
            <hardwareInterface>hardware_interface/EffortJointInterface</hardwareInterface>
            <mechanicalReduction>1</mechanicalReduction>
        </actuator>
        <joint name="left_front_wheel_joint">
            <hardwareInterface>hardware_interface/EffortJointInterface</hardwareInterface>
        </joint>
    </transmission>
    <transmission name="right_front_wheel_trans">
        <type>transmission_interface/SimpleTransmission</type>
        <actuator name="right_front_wheel_motor">
            <hardwareInterface>hardware_interface/EffortJointInterface</hardwareInterface>
            <mechanicalReduction>-1</mechanicalReduction>
        </actuator>
        <joint name="right_front_wheel_joint">
            <hardwareInterface>hardware_interface/EffortJointInterface</hardwareInterface>
        </joint>
    </transmission>
    <transmission name="left_back_wheel_trans">
        <type>transmission_interface/SimpleTransmission</type>
        <actuator name="left_back_wheel_motor">
            <hardwareInterface>hardware_interface/EffortJointInterface</hardwareInterface>
            <mechanicalReduction>1</mechanicalReduction>
        </actuator>
        <joint name="left_back_wheel_joint">
            <hardwareInterface>hardware_interface/EffortJointInterface</hardwareInterface>
        </joint>
    </transmission>
    <transmission name="right_back_wheel_trans">
        <type>transmission_interface/SimpleTransmission</type>
        <actuator name="right_back_wheel_motor">
            <hardwareInterface>hardware_interface/EffortJointInterface</hardwareInterface>
            <mechanicalReduction>-1</mechanicalReduction>
        </actuator>
        <joint name="right_back_wheel_joint">
            <hardwareInterface>hardware_interface/EffortJointInterface</hardwareInterface>
        </joint>
    </transmission>
    <link name="fpv_base_link">
        <inertial>
            <origin rpy="0 0 0" xyz="-0.00792936871652137 0.000141142989662449 0.260766462339412" />
            <mass value="0.317542464634811" />
            <inertia ixx="0.000965471374037066" ixy="9.93131375188562E-08" ixz="-4.59210283751836E-07" iyy="0.000974644385413349" iyz="-2.29555782023746E-07" izz="3.90092448204564E-05" />
        </inertial>
        <visual>
            <origin rpy="0 0 0" xyz="0 0 0" />
            <geometry>
                <mesh filename="package://sp_description/meshes/engineer_manipulator/fpv_module/fpv_base_link.STL" />
            </geometry>
            <material name="">
                <color rgba="0.898039215686275 0.917647058823529 0.929411764705882 1" />
            </material>
        </visual>
        <collision>
            <origin rpy="0 0 0" xyz="0 0 0" />
            <geometry>
                <mesh filename="package://sp_description/meshes/engineer_manipulator/fpv_module/fpv_base_link.STL" />
            </geometry>
        </collision>
    </link>
    <link name="mast">
        <inertial>
            <origin rpy="0 0 0" xyz="-0.0584010828086417 -0.00159000441041939 0.273527091290577" />
            <mass value="0.596769834435929" />
            <inertia ixx="0.00358416489838144" ixy="8.93424511469642E-06" ixz="-8.40259560018718E-08" iyy="0.00396184957629145" iyz="-5.81196895554224E-09" izz="0.00062348701535612" />
        </inertial>
        <visual>
            <origin rpy="0 0 0" xyz="0 0 0" />
            <geometry>
                <mesh filename="package://sp_description/meshes/engineer_manipulator/fpv_module/mast.STL" />
            </geometry>
            <material name="">
                <color rgba="0.823529411764706 0.870588235294118 0.980392156862745 1" />
            </material>
        </visual>
        <collision>
            <origin rpy="0 0 0" xyz="0 0 0" />
            <geometry>
                <mesh filename="package://sp_description/meshes/engineer_manipulator/fpv_module/mast.STL" />
            </geometry>
        </collision>
    </link>
    <joint name="mast_joint" type="prismatic">
        <origin rpy="0 0 0" xyz="0 0 0" />
        <parent link="fpv_base_link" />
        <child link="mast" />
        <axis xyz="0 0 -1" />
        <limit effort="50" lower="-0.235" upper="0" velocity="0.4" />
    </joint>
    <link name="fpv_yaw">
        <inertial>
            <origin rpy="0 0 0" xyz="-0.0092103 0.044084 0.018323" />
            <mass value="0.060612" />
            <inertia ixx="9.0201E-03" ixy="1.0141E-04" ixz="5.7277E-05" iyy="1.4587E-02" iyz="3.2725E-04" izz="1.9433E-02" />
        </inertial>
        <visual>
            <origin rpy="0 0 0" xyz="0 0 0" />
            <geometry>
                <mesh filename="package://sp_description/meshes/engineer_manipulator/fpv_module/fpv_yaw.STL" />
            </geometry>
            <material name="">
                <color rgba="0.49804 0.49804 0.49804 1" />
            </material>
        </visual>
        <collision>
            <origin rpy="0 0 0" xyz="0 0 0" />
            <geometry>
                <mesh filename="package://sp_description/meshes/engineer_manipulator/fpv_module/fpv_yaw.STL" />
            </geometry>
        </collision>
    </link>
    <joint name="fpv_yaw_joint" type="revolute">
        <origin rpy="0 0 -1.5707963267949" xyz="0 -0.0285 0.3853" />
        <parent link="mast" />
        <child link="fpv_yaw" />
        <axis xyz="0 0 1" />
        <limit effort="1.3" lower="-1.80" upper="1.50" velocity="6" />
    </joint>
    <link name="fpv_pitch">
        <inertial>
            <origin rpy="0 0 0" xyz="-0.017448 -0.055509 -4.0539E-05" />
            <mass value="0.79082" />
            <inertia ixx="0.00090446" ixy="-1.0482E-03" ixz="3.6509E-04" iyy="0.0011756" iyz="8.4354E-05" izz="0.0009281" />
        </inertial>
        <visual>
            <origin rpy="0 0 0" xyz="0 0 0" />
            <geometry>
                <mesh filename="package://sp_description/meshes/engineer_manipulator/fpv_module/fpv_pitch.STL" />
            </geometry>
            <material name="">
                <color rgba="1 1 1 1" />
            </material>
        </visual>
        <collision>
            <origin rpy="0 0 0" xyz="0 0 0" />
            <geometry>
                <mesh filename="package://sp_description/meshes/engineer_manipulator/fpv_module/fpv_pitch.STL" />
            </geometry>
        </collision>
    </link>
    <joint name="fpv_pitch_joint" type="revolute">
        <origin rpy="-1.5707963267949 0 3.14159265358979" xyz="0 0.000700000000000704 0.0275" />
        <parent link="fpv_yaw" />
        <child link="fpv_pitch" />
        <axis xyz="0 0 1" />
        <limit effort="1.3" lower="-1.5708" upper="1.5708" velocity="6" />
    </joint>
    <!--Transmission-->
    <transmission name="trans_mast_joint">
        <type>transmission_interface/SimpleTransmission</type>
        <actuator name="mast_joint_motor">
            <mechanicalReduction>50</mechanicalReduction>
            <hardwareInterface>hardware_interface/EffortJointInterface</hardwareInterface>
        </actuator>
        <joint name="mast_joint">
            <hardwareInterface>hardware_interface/EffortJointInterface</hardwareInterface>
        </joint>
    </transmission>
    <transmission name="trans_fpv_yaw_joint">
        <type>transmission_interface/SimpleTransmission</type>
        <actuator name="fpv_yaw_joint_motor">
            <mechanicalReduction>1</mechanicalReduction>
            <hardwareInterface>hardware_interface/EffortJointInterface</hardwareInterface>
        </actuator>
        <joint name="fpv_yaw_joint">
            <hardwareInterface>hardware_interface/PositionJointInterface</hardwareInterface>
        </joint>
    </transmission>
    <transmission name="trans_fpv_pitch_joint">
        <type>transmission_interface/SimpleTransmission</type>
        <actuator name="fpv_pitch_joint_motor">
            <mechanicalReduction>1</mechanicalReduction>
            <hardwareInterface>hardware_interface/EffortJointInterface</hardwareInterface>
        </actuator>
        <joint name="fpv_pitch_joint">
            <hardwareInterface>hardware_interface/PositionJointInterface</hardwareInterface>
        </joint>
    </transmission>
    <gazebo reference="fpv_pitch">
        <material>Gazebo/Black</material>
    </gazebo>
    <link name="arm_base_link">
        <inertial>
            <origin rpy="0 0 0" xyz="0.000191990525551576 -0.0379959432267828 -0.0188711762736671" />
            <mass value="0.395354400864979" />
            <inertia ixx="0.000467726564216232" ixy="-8.67714690501313E-09" ixz="4.31198411045603E-09" iyy="0.000307127917627802" iyz="-2.40360210665882E-08" izz="0.000768655424904835" />
        </inertial>
        <visual>
            <origin rpy="0 0 0" xyz="0 0 0" />
            <geometry>
                <mesh filename="package://sp_description/meshes/engineer_manipulator/engineer_manipulator/arm_base_link.STL" />
            </geometry>
            <material name="">
                <color rgba="1 1 1 1" />
            </material>
        </visual>
        <collision>
            <origin rpy="0 0 0" xyz="0 0 0" />
            <geometry>
                <mesh filename="package://sp_description/meshes/engineer_manipulator/engineer_manipulator/arm_base_link.STL" />
            </geometry>
        </collision>
    </link>
    <link name="link1">
        <inertial>
            <origin rpy="0 0 0" xyz="-0.00519778790831543 -0.000376162564114741 0.051547696306667" />
            <mass value="0.376683384729688" />
            <inertia ixx="0.000845918540984844" ixy="1.12279959742112E-07" ixz="9.01688301312492E-07" iyy="0.000489021055809623" iyz="7.41749753688042E-07" izz="0.000437357298424943" />
        </inertial>
        <visual>
            <origin rpy="0 0 0" xyz="0 0 0" />
            <geometry>
                <mesh filename="package://sp_description/meshes/engineer_manipulator/engineer_manipulator/link1.STL" />
            </geometry>
            <material name="">
                <color rgba="1 1 1 1" />
            </material>
        </visual>
        <collision>
            <origin rpy="0 0 0" xyz="0 0 0" />
            <geometry>
                <mesh filename="package://sp_description/meshes/engineer_manipulator/engineer_manipulator/link1.STL" />
            </geometry>
        </collision>
    </link>
    <joint name="joint1" type="revolute">
        <origin rpy="0 0 0" xyz="0 0 0" />
        <parent link="arm_base_link" />
        <child link="link1" />
        <axis xyz="0 0 1" />
        <limit effort="20" lower="-3.14" upper="3.14" velocity="6" />
    </joint>
    <link name="link2">
        <inertial>
            <origin rpy="0 0 0" xyz="0.050580281880749 1.15493250689451E-05 -0.0210030003469162" />
            <mass value="0.759246586931641" />
            <inertia ixx="0.000476310073091113" ixy="7.29764960891789E-07" ixz="1.10638206714342E-07" iyy="0.000991153032504733" iyz="1.21515857857987E-06" izz="0.00140495471373823" />
        </inertial>
        <visual>
            <origin rpy="0 0 0" xyz="0 0 0" />
            <geometry>
                <mesh filename="package://sp_description/meshes/engineer_manipulator/engineer_manipulator/link2.STL" />
            </geometry>
            <material name="">
                <color rgba="1 1 1 1" />
            </material>
        </visual>
        <collision>
            <origin rpy="0 0 0" xyz="0 0 0" />
            <geometry>
                <mesh filename="package://sp_description/meshes/engineer_manipulator/engineer_manipulator/link2.STL" />
            </geometry>
        </collision>
    </link>
    <joint name="joint2" type="revolute">
        <origin rpy="0 -1.5708 0" xyz="-0.022 0 0.065" />
        <parent link="link1" />
        <child link="link2" />
        <axis xyz="0 0 1" />
        <limit effort="20" lower="-1.70" upper="1.70" velocity="8" />
    </joint>
    <link name="link3">
        <inertial>
            <origin rpy="0 0 0" xyz="0.0245084498465696 0.00738609929531111 0.00192882422441409" />
            <mass value="0.728531979995667" />
            <inertia ixx="0.000532458424182733" ixy="4.53824196718106E-06" ixz="2.04205314034E-06" iyy="0.000532510298817301" iyz="-1.81917766175563E-06" izz="0.000337461792942105" />
        </inertial>
        <visual>
            <origin rpy="0 0 0" xyz="0 0 0" />
            <geometry>
                <mesh filename="package://sp_description/meshes/engineer_manipulator/engineer_manipulator/link3.STL" />
            </geometry>
            <material name="">
                <color rgba="1 1 1 1" />
            </material>
        </visual>
        <collision>
            <origin rpy="0 0 0" xyz="0 0 0" />
            <geometry>
                <mesh filename="package://sp_description/meshes/engineer_manipulator/engineer_manipulator/link3.STL" />
            </geometry>
        </collision>
    </link>
    <joint name="joint3" type="revolute">
        <origin rpy="0 0 0" xyz="0.2 0 0" />
        <parent link="link2" />
        <child link="link3" />
        <axis xyz="0 0 -1" />
        <limit effort="20" lower="-2.80" upper="2.80" velocity="8" />
    </joint>
    <link name="link4">
        <inertial>
            <origin rpy="0 0 0" xyz="-4.15720177258799E-05 0.00320298874916644 0.00671219827123581" />
            <mass value="0.227354423602744" />
            <inertia ixx="0.00017836251229402" ixy="-4.3119850715308E-09" ixz="5.53767841869846E-10" iyy="0.000191169545672061" iyz="2.40360190145244E-08" izz="0.000327594643478463" />
        </inertial>
        <visual>
            <origin rpy="0 0 0" xyz="0 0 0" />
            <geometry>
                <mesh filename="package://sp_description/meshes/engineer_manipulator/engineer_manipulator/link4.STL" />
            </geometry>
            <material name="">
                <color rgba="1 1 1 1" />
            </material>
        </visual>
        <collision>
            <origin rpy="0 0 0" xyz="0 0 0" />
            <geometry>
                <mesh filename="package://sp_description/meshes/engineer_manipulator/engineer_manipulator/link4.STL" />
            </geometry>
        </collision>
    </link>
    <joint name="joint4" type="revolute">
        <origin rpy="0 1.5708 0" xyz="0.13435 0 0" />
        <parent link="link3" />
        <child link="link4" />
        <axis xyz="0 0 1" />
        <limit effort="20" lower="-3.14" upper="3.14" velocity="7" />
    </joint>
    <link name="link5">
        <inertial>
            <origin rpy="0 0 0" xyz="0.0448570389290742 7.50749423052491E-05 -0.0145612470233759" />
            <mass value="0.0807348568456161" />
            <inertia ixx="3.32465515141751E-05" ixy="-2.40360210662102E-08" ixz="-4.31198411042277E-09" iyy="2.26337327690657E-05" iyz="5.39577655542099E-10" izz="2.31477934401328E-05" />
        </inertial>
        <visual>
            <origin rpy="0 0 0" xyz="0 0 0" />
            <geometry>
                <mesh filename="package://sp_description/meshes/engineer_manipulator/engineer_manipulator/link5.STL" />
            </geometry>
            <material name="">
                <color rgba="1 1 1 1" />
            </material>
        </visual>
        <collision>
            <origin rpy="0 0 0" xyz="0 0 0" />
            <geometry>
                <mesh filename="package://sp_description/meshes/engineer_manipulator/engineer_manipulator/link5.STL" />
            </geometry>
        </collision>
    </link>
    <joint name="joint5" type="revolute">
        <origin rpy="1.5708 -1.5708 0" xyz="0 -0.025 0.05" />
        <parent link="link4" />
        <child link="link5" />
        <axis xyz="0 0 1" />
        <limit effort="20" lower="-2.10" upper="2.10" velocity="7" />
    </joint>
    <link name="link6">
        <inertial>
            <origin rpy="0 0 0" xyz="-4.3008E-05 -0.0079055 -0.013813" />
            <mass value="0.25692" />
            <inertia ixx="0.00021993" ixy="-4.1694E-10" ixz="9.6881E-12" iyy="0.0002338" iyz="-4.2941E-10" izz="6.2378E-05" />
        </inertial>
        <visual>
            <origin rpy="0 0 0" xyz="0 0 0" />
            <geometry>
                <mesh filename="package://sp_description/meshes/engineer_manipulator/engineer_manipulator/link6.STL" />
            </geometry>
            <material name="">
                <color rgba="1 1 1 1" />
            </material>
        </visual>
        <collision>
            <origin rpy="0 0 0" xyz="0 0 0" />
            <geometry>
                <mesh filename="package://sp_description/meshes/engineer_manipulator/engineer_manipulator/link6.STL" />
            </geometry>
        </collision>
    </link>
    <joint name="joint6" type="revolute">
        <origin rpy="-1.5708 0.05753 -1.5708" xyz="0.096 0 -0.03" />
        <parent link="link5" />
        <child link="link6" />
        <axis xyz="0 0 1" />
        <limit effort="20" lower="-3.14" upper="3.14" velocity="7" />
    </joint>
    <link name="link7">
        <inertial>
            <origin rpy="0 0 0" xyz="1.578E-05 -0.032317 -0.028954" />
            <mass value="0.20296" />
            <inertia ixx="9.9818E-05" ixy="-7.9536E-08" ixz="-4.5421E-10" iyy="0.00015416" iyz="-4.0049E-09" izz="0.00019962" />
        </inertial>
        <visual>
            <origin rpy="0 0 0" xyz="0 0 0" />
            <geometry>
                <mesh filename="package://sp_description/meshes/engineer_manipulator/engineer_manipulator/link7.STL" />
            </geometry>
            <material name="">
                <color rgba="1 1 1 1" />
            </material>
        </visual>
        <collision>
            <origin rpy="0 0 0" xyz="0 0 0" />
            <geometry>
                <mesh filename="package://sp_description/meshes/engineer_manipulator/engineer_manipulator/link7.STL" />
            </geometry>
        </collision>
    </link>
    <joint name="joint7" type="prismatic">
        <origin rpy="0 0 0" xyz="0 0 0.025373" />
        <parent link="link6" />
        <child link="link7" />
        <axis xyz="0 0 -1" />
        <limit effort="20" lower="-0.075" upper="0" velocity="0.075" />
    </joint>
    <link name="vacuum_gripper" />
    <joint name="vacuum_gripper_joint" type="fixed">
        <origin rpy="0 0 0" xyz="0 0 0.055" />
        <parent link="link7" />
        <child link="vacuum_gripper" />
        <axis xyz="0 0 1" />
    </joint>
    <joint name="joint_arm2body" type="fixed">
        <axis xyz="0 0 1" />
        <origin rpy="0 0 -1.5708" xyz="0.022 0.166 0.228" />
        <parent link="base_link" />
        <child link="arm_base_link" />
    </joint>
    <joint name="joint_mast2body" type="fixed">
        <axis xyz="0 0 1" />
        <origin rpy="0 0 1.5708" xyz="-0.2295 -0.0825 0.0177" />
        <parent link="base_link" />
        <child link="fpv_base_link" />
    </joint>
    <gazebo>
        <plugin filename="libgazebo_ros_control.so" name="gazebo_ros_control">
            <robotNamespace>/</robotNamespace>
        </plugin>
        <plugin filename="libchassis_controller.so" name="chassis_controller">
            <robotNamespace>/</robotNamespace>
        </plugin>
        <plugin filename="libgimbal_controller.so" name="gimbal_controller">
            <robotNamespace>/</robotNamespace>
        </plugin>
    </gazebo>
    <transmission name="trans_left_front_roller_0_joint">
        <type>transmission_interface/SimpleTransmission</type>
        <joint name="left_front_roller_0_joint">
            <hardwareInterface>hardware_interface/EffortJointInterface</hardwareInterface>
        </joint>
        <actuator name="left_front_roller_0_joint_motor">
            <hardwareInterface>hardware_interface/EffortJointInterface</hardwareInterface>
            <mechanicalReduction>1</mechanicalReduction>
        </actuator>
    </transmission>
    <transmission name="trans_left_front_roller_1_joint">
        <type>transmission_interface/SimpleTransmission</type>
        <joint name="left_front_roller_1_joint">
            <hardwareInterface>hardware_interface/EffortJointInterface</hardwareInterface>
        </joint>
        <actuator name="left_front_roller_1_joint_motor">
            <hardwareInterface>hardware_interface/EffortJointInterface</hardwareInterface>
            <mechanicalReduction>1</mechanicalReduction>
        </actuator>
    </transmission>
    <transmission name="trans_left_front_roller_2_joint">
        <type>transmission_interface/SimpleTransmission</type>
        <joint name="left_front_roller_2_joint">
            <hardwareInterface>hardware_interface/EffortJointInterface</hardwareInterface>
        </joint>
        <actuator name="left_front_roller_2_joint_motor">
            <hardwareInterface>hardware_interface/EffortJointInterface</hardwareInterface>
            <mechanicalReduction>1</mechanicalReduction>
        </actuator>
    </transmission>
    <transmission name="trans_left_front_roller_3_joint">
        <type>transmission_interface/SimpleTransmission</type>
        <joint name="left_front_roller_3_joint">
            <hardwareInterface>hardware_interface/EffortJointInterface</hardwareInterface>
        </joint>
        <actuator name="left_front_roller_3_joint_motor">
            <hardwareInterface>hardware_interface/EffortJointInterface</hardwareInterface>
            <mechanicalReduction>1</mechanicalReduction>
        </actuator>
    </transmission>
    <transmission name="trans_left_front_roller_4_joint">
        <type>transmission_interface/SimpleTransmission</type>
        <joint name="left_front_roller_4_joint">
            <hardwareInterface>hardware_interface/EffortJointInterface</hardwareInterface>
        </joint>
        <actuator name="left_front_roller_4_joint_motor">
            <hardwareInterface>hardware_interface/EffortJointInterface</hardwareInterface>
            <mechanicalReduction>1</mechanicalReduction>
        </actuator>
    </transmission>
    <transmission name="trans_left_front_roller_5_joint">
        <type>transmission_interface/SimpleTransmission</type>
        <joint name="left_front_roller_5_joint">
            <hardwareInterface>hardware_interface/EffortJointInterface</hardwareInterface>
        </joint>
        <actuator name="left_front_roller_5_joint_motor">
            <hardwareInterface>hardware_interface/EffortJointInterface</hardwareInterface>
            <mechanicalReduction>1</mechanicalReduction>
        </actuator>
    </transmission>
    <transmission name="trans_left_front_roller_6_joint">
        <type>transmission_interface/SimpleTransmission</type>
        <joint name="left_front_roller_6_joint">
            <hardwareInterface>hardware_interface/EffortJointInterface</hardwareInterface>
        </joint>
        <actuator name="left_front_roller_6_joint_motor">
            <hardwareInterface>hardware_interface/EffortJointInterface</hardwareInterface>
            <mechanicalReduction>1</mechanicalReduction>
        </actuator>
    </transmission>
    <transmission name="trans_left_front_roller_7_joint">
        <type>transmission_interface/SimpleTransmission</type>
        <joint name="left_front_roller_7_joint">
            <hardwareInterface>hardware_interface/EffortJointInterface</hardwareInterface>
        </joint>
        <actuator name="left_front_roller_7_joint_motor">
            <hardwareInterface>hardware_interface/EffortJointInterface</hardwareInterface>
            <mechanicalReduction>1</mechanicalReduction>
        </actuator>
    </transmission>
    <transmission name="trans_left_front_roller_8_joint">
        <type>transmission_interface/SimpleTransmission</type>
        <joint name="left_front_roller_8_joint">
            <hardwareInterface>hardware_interface/EffortJointInterface</hardwareInterface>
        </joint>
        <actuator name="left_front_roller_8_joint_motor">
            <hardwareInterface>hardware_interface/EffortJointInterface</hardwareInterface>
            <mechanicalReduction>1</mechanicalReduction>
        </actuator>
    </transmission>
    <transmission name="trans_left_front_roller_9_joint">
        <type>transmission_interface/SimpleTransmission</type>
        <joint name="left_front_roller_9_joint">
            <hardwareInterface>hardware_interface/EffortJointInterface</hardwareInterface>
        </joint>
        <actuator name="left_front_roller_9_joint_motor">
            <hardwareInterface>hardware_interface/EffortJointInterface</hardwareInterface>
            <mechanicalReduction>1</mechanicalReduction>
        </actuator>
    </transmission>
    <transmission name="trans_left_front_roller_10_joint">
        <type>transmission_interface/SimpleTransmission</type>
        <joint name="left_front_roller_10_joint">
            <hardwareInterface>hardware_interface/EffortJointInterface</hardwareInterface>
        </joint>
        <actuator name="left_front_roller_10_joint_motor">
            <hardwareInterface>hardware_interface/EffortJointInterface</hardwareInterface>
            <mechanicalReduction>1</mechanicalReduction>
        </actuator>
    </transmission>
    <transmission name="trans_left_front_roller_11_joint">
        <type>transmission_interface/SimpleTransmission</type>
        <joint name="left_front_roller_11_joint">
            <hardwareInterface>hardware_interface/EffortJointInterface</hardwareInterface>
        </joint>
        <actuator name="left_front_roller_11_joint_motor">
            <hardwareInterface>hardware_interface/EffortJointInterface</hardwareInterface>
            <mechanicalReduction>1</mechanicalReduction>
        </actuator>
    </transmission>
    <transmission name="trans_left_front_roller_12_joint">
        <type>transmission_interface/SimpleTransmission</type>
        <joint name="left_front_roller_12_joint">
            <hardwareInterface>hardware_interface/EffortJointInterface</hardwareInterface>
        </joint>
        <actuator name="left_front_roller_12_joint_motor">
            <hardwareInterface>hardware_interface/EffortJointInterface</hardwareInterface>
            <mechanicalReduction>1</mechanicalReduction>
        </actuator>
    </transmission>
    <transmission name="trans_left_front_roller_13_joint">
        <type>transmission_interface/SimpleTransmission</type>
        <joint name="left_front_roller_13_joint">
            <hardwareInterface>hardware_interface/EffortJointInterface</hardwareInterface>
        </joint>
        <actuator name="left_front_roller_13_joint_motor">
            <hardwareInterface>hardware_interface/EffortJointInterface</hardwareInterface>
            <mechanicalReduction>1</mechanicalReduction>
        </actuator>
    </transmission>
    <transmission name="trans_left_front_roller_14_joint">
        <type>transmission_interface/SimpleTransmission</type>
        <joint name="left_front_roller_14_joint">
            <hardwareInterface>hardware_interface/EffortJointInterface</hardwareInterface>
        </joint>
        <actuator name="left_front_roller_14_joint_motor">
            <hardwareInterface>hardware_interface/EffortJointInterface</hardwareInterface>
            <mechanicalReduction>1</mechanicalReduction>
        </actuator>
    </transmission>
    <transmission name="trans_left_front_roller_15_joint">
        <type>transmission_interface/SimpleTransmission</type>
        <joint name="left_front_roller_15_joint">
            <hardwareInterface>hardware_interface/EffortJointInterface</hardwareInterface>
        </joint>
        <actuator name="left_front_roller_15_joint_motor">
            <hardwareInterface>hardware_interface/EffortJointInterface</hardwareInterface>
            <mechanicalReduction>1</mechanicalReduction>
        </actuator>
    </transmission>
    <transmission name="trans_right_front_roller_0_joint">
        <type>transmission_interface/SimpleTransmission</type>
        <joint name="right_front_roller_0_joint">
            <hardwareInterface>hardware_interface/EffortJointInterface</hardwareInterface>
        </joint>
        <actuator name="right_front_roller_0_joint_motor">
            <hardwareInterface>hardware_interface/EffortJointInterface</hardwareInterface>
            <mechanicalReduction>1</mechanicalReduction>
        </actuator>
    </transmission>
    <transmission name="trans_right_front_roller_1_joint">
        <type>transmission_interface/SimpleTransmission</type>
        <joint name="right_front_roller_1_joint">
            <hardwareInterface>hardware_interface/EffortJointInterface</hardwareInterface>
        </joint>
        <actuator name="right_front_roller_1_joint_motor">
            <hardwareInterface>hardware_interface/EffortJointInterface</hardwareInterface>
            <mechanicalReduction>1</mechanicalReduction>
        </actuator>
    </transmission>
    <transmission name="trans_right_front_roller_2_joint">
        <type>transmission_interface/SimpleTransmission</type>
        <joint name="right_front_roller_2_joint">
            <hardwareInterface>hardware_interface/EffortJointInterface</hardwareInterface>
        </joint>
        <actuator name="right_front_roller_2_joint_motor">
            <hardwareInterface>hardware_interface/EffortJointInterface</hardwareInterface>
            <mechanicalReduction>1</mechanicalReduction>
        </actuator>
    </transmission>
    <transmission name="trans_right_front_roller_3_joint">
        <type>transmission_interface/SimpleTransmission</type>
        <joint name="right_front_roller_3_joint">
            <hardwareInterface>hardware_interface/EffortJointInterface</hardwareInterface>
        </joint>
        <actuator name="right_front_roller_3_joint_motor">
            <hardwareInterface>hardware_interface/EffortJointInterface</hardwareInterface>
            <mechanicalReduction>1</mechanicalReduction>
        </actuator>
    </transmission>
    <transmission name="trans_right_front_roller_4_joint">
        <type>transmission_interface/SimpleTransmission</type>
        <joint name="right_front_roller_4_joint">
            <hardwareInterface>hardware_interface/EffortJointInterface</hardwareInterface>
        </joint>
        <actuator name="right_front_roller_4_joint_motor">
            <hardwareInterface>hardware_interface/EffortJointInterface</hardwareInterface>
            <mechanicalReduction>1</mechanicalReduction>
        </actuator>
    </transmission>
    <transmission name="trans_right_front_roller_5_joint">
        <type>transmission_interface/SimpleTransmission</type>
        <joint name="right_front_roller_5_joint">
            <hardwareInterface>hardware_interface/EffortJointInterface</hardwareInterface>
        </joint>
        <actuator name="right_front_roller_5_joint_motor">
            <hardwareInterface>hardware_interface/EffortJointInterface</hardwareInterface>
            <mechanicalReduction>1</mechanicalReduction>
        </actuator>
    </transmission>
    <transmission name="trans_right_front_roller_6_joint">
        <type>transmission_interface/SimpleTransmission</type>
        <joint name="right_front_roller_6_joint">
            <hardwareInterface>hardware_interface/EffortJointInterface</hardwareInterface>
        </joint>
        <actuator name="right_front_roller_6_joint_motor">
            <hardwareInterface>hardware_interface/EffortJointInterface</hardwareInterface>
            <mechanicalReduction>1</mechanicalReduction>
        </actuator>
    </transmission>
    <transmission name="trans_right_front_roller_7_joint">
        <type>transmission_interface/SimpleTransmission</type>
        <joint name="right_front_roller_7_joint">
            <hardwareInterface>hardware_interface/EffortJointInterface</hardwareInterface>
        </joint>
        <actuator name="right_front_roller_7_joint_motor">
            <hardwareInterface>hardware_interface/EffortJointInterface</hardwareInterface>
            <mechanicalReduction>1</mechanicalReduction>
        </actuator>
    </transmission>
    <transmission name="trans_right_front_roller_8_joint">
        <type>transmission_interface/SimpleTransmission</type>
        <joint name="right_front_roller_8_joint">
            <hardwareInterface>hardware_interface/EffortJointInterface</hardwareInterface>
        </joint>
        <actuator name="right_front_roller_8_joint_motor">
            <hardwareInterface>hardware_interface/EffortJointInterface</hardwareInterface>
            <mechanicalReduction>1</mechanicalReduction>
        </actuator>
    </transmission>
    <transmission name="trans_right_front_roller_9_joint">
        <type>transmission_interface/SimpleTransmission</type>
        <joint name="right_front_roller_9_joint">
            <hardwareInterface>hardware_interface/EffortJointInterface</hardwareInterface>
        </joint>
        <actuator name="right_front_roller_9_joint_motor">
            <hardwareInterface>hardware_interface/EffortJointInterface</hardwareInterface>
            <mechanicalReduction>1</mechanicalReduction>
        </actuator>
    </transmission>
    <transmission name="trans_right_front_roller_10_joint">
        <type>transmission_interface/SimpleTransmission</type>
        <joint name="right_front_roller_10_joint">
            <hardwareInterface>hardware_interface/EffortJointInterface</hardwareInterface>
        </joint>
        <actuator name="right_front_roller_10_joint_motor">
            <hardwareInterface>hardware_interface/EffortJointInterface</hardwareInterface>
            <mechanicalReduction>1</mechanicalReduction>
        </actuator>
    </transmission>
    <transmission name="trans_right_front_roller_11_joint">
        <type>transmission_interface/SimpleTransmission</type>
        <joint name="right_front_roller_11_joint">
            <hardwareInterface>hardware_interface/EffortJointInterface</hardwareInterface>
        </joint>
        <actuator name="right_front_roller_11_joint_motor">
            <hardwareInterface>hardware_interface/EffortJointInterface</hardwareInterface>
            <mechanicalReduction>1</mechanicalReduction>
        </actuator>
    </transmission>
    <transmission name="trans_right_front_roller_12_joint">
        <type>transmission_interface/SimpleTransmission</type>
        <joint name="right_front_roller_12_joint">
            <hardwareInterface>hardware_interface/EffortJointInterface</hardwareInterface>
        </joint>
        <actuator name="right_front_roller_12_joint_motor">
            <hardwareInterface>hardware_interface/EffortJointInterface</hardwareInterface>
            <mechanicalReduction>1</mechanicalReduction>
        </actuator>
    </transmission>
    <transmission name="trans_right_front_roller_13_joint">
        <type>transmission_interface/SimpleTransmission</type>
        <joint name="right_front_roller_13_joint">
            <hardwareInterface>hardware_interface/EffortJointInterface</hardwareInterface>
        </joint>
        <actuator name="right_front_roller_13_joint_motor">
            <hardwareInterface>hardware_interface/EffortJointInterface</hardwareInterface>
            <mechanicalReduction>1</mechanicalReduction>
        </actuator>
    </transmission>
    <transmission name="trans_right_front_roller_14_joint">
        <type>transmission_interface/SimpleTransmission</type>
        <joint name="right_front_roller_14_joint">
            <hardwareInterface>hardware_interface/EffortJointInterface</hardwareInterface>
        </joint>
        <actuator name="right_front_roller_14_joint_motor">
            <hardwareInterface>hardware_interface/EffortJointInterface</hardwareInterface>
            <mechanicalReduction>1</mechanicalReduction>
        </actuator>
    </transmission>
    <transmission name="trans_right_front_roller_15_joint">
        <type>transmission_interface/SimpleTransmission</type>
        <joint name="right_front_roller_15_joint">
            <hardwareInterface>hardware_interface/EffortJointInterface</hardwareInterface>
        </joint>
        <actuator name="right_front_roller_15_joint_motor">
            <hardwareInterface>hardware_interface/EffortJointInterface</hardwareInterface>
            <mechanicalReduction>1</mechanicalReduction>
        </actuator>
    </transmission>
    <transmission name="trans_left_back_roller_0_joint">
        <type>transmission_interface/SimpleTransmission</type>
        <joint name="left_back_roller_0_joint">
            <hardwareInterface>hardware_interface/EffortJointInterface</hardwareInterface>
        </joint>
        <actuator name="left_back_roller_0_joint_motor">
            <hardwareInterface>hardware_interface/EffortJointInterface</hardwareInterface>
            <mechanicalReduction>1</mechanicalReduction>
        </actuator>
    </transmission>
    <transmission name="trans_left_back_roller_1_joint">
        <type>transmission_interface/SimpleTransmission</type>
        <joint name="left_back_roller_1_joint">
            <hardwareInterface>hardware_interface/EffortJointInterface</hardwareInterface>
        </joint>
        <actuator name="left_back_roller_1_joint_motor">
            <hardwareInterface>hardware_interface/EffortJointInterface</hardwareInterface>
            <mechanicalReduction>1</mechanicalReduction>
        </actuator>
    </transmission>
    <transmission name="trans_left_back_roller_2_joint">
        <type>transmission_interface/SimpleTransmission</type>
        <joint name="left_back_roller_2_joint">
            <hardwareInterface>hardware_interface/EffortJointInterface</hardwareInterface>
        </joint>
        <actuator name="left_back_roller_2_joint_motor">
            <hardwareInterface>hardware_interface/EffortJointInterface</hardwareInterface>
            <mechanicalReduction>1</mechanicalReduction>
        </actuator>
    </transmission>
    <transmission name="trans_left_back_roller_3_joint">
        <type>transmission_interface/SimpleTransmission</type>
        <joint name="left_back_roller_3_joint">
            <hardwareInterface>hardware_interface/EffortJointInterface</hardwareInterface>
        </joint>
        <actuator name="left_back_roller_3_joint_motor">
            <hardwareInterface>hardware_interface/EffortJointInterface</hardwareInterface>
            <mechanicalReduction>1</mechanicalReduction>
        </actuator>
    </transmission>
    <transmission name="trans_left_back_roller_4_joint">
        <type>transmission_interface/SimpleTransmission</type>
        <joint name="left_back_roller_4_joint">
            <hardwareInterface>hardware_interface/EffortJointInterface</hardwareInterface>
        </joint>
        <actuator name="left_back_roller_4_joint_motor">
            <hardwareInterface>hardware_interface/EffortJointInterface</hardwareInterface>
            <mechanicalReduction>1</mechanicalReduction>
        </actuator>
    </transmission>
    <transmission name="trans_left_back_roller_5_joint">
        <type>transmission_interface/SimpleTransmission</type>
        <joint name="left_back_roller_5_joint">
            <hardwareInterface>hardware_interface/EffortJointInterface</hardwareInterface>
        </joint>
        <actuator name="left_back_roller_5_joint_motor">
            <hardwareInterface>hardware_interface/EffortJointInterface</hardwareInterface>
            <mechanicalReduction>1</mechanicalReduction>
        </actuator>
    </transmission>
    <transmission name="trans_left_back_roller_6_joint">
        <type>transmission_interface/SimpleTransmission</type>
        <joint name="left_back_roller_6_joint">
            <hardwareInterface>hardware_interface/EffortJointInterface</hardwareInterface>
        </joint>
        <actuator name="left_back_roller_6_joint_motor">
            <hardwareInterface>hardware_interface/EffortJointInterface</hardwareInterface>
            <mechanicalReduction>1</mechanicalReduction>
        </actuator>
    </transmission>
    <transmission name="trans_left_back_roller_7_joint">
        <type>transmission_interface/SimpleTransmission</type>
        <joint name="left_back_roller_7_joint">
            <hardwareInterface>hardware_interface/EffortJointInterface</hardwareInterface>
        </joint>
        <actuator name="left_back_roller_7_joint_motor">
            <hardwareInterface>hardware_interface/EffortJointInterface</hardwareInterface>
            <mechanicalReduction>1</mechanicalReduction>
        </actuator>
    </transmission>
    <transmission name="trans_left_back_roller_8_joint">
        <type>transmission_interface/SimpleTransmission</type>
        <joint name="left_back_roller_8_joint">
            <hardwareInterface>hardware_interface/EffortJointInterface</hardwareInterface>
        </joint>
        <actuator name="left_back_roller_8_joint_motor">
            <hardwareInterface>hardware_interface/EffortJointInterface</hardwareInterface>
            <mechanicalReduction>1</mechanicalReduction>
        </actuator>
    </transmission>
    <transmission name="trans_left_back_roller_9_joint">
        <type>transmission_interface/SimpleTransmission</type>
        <joint name="left_back_roller_9_joint">
            <hardwareInterface>hardware_interface/EffortJointInterface</hardwareInterface>
        </joint>
        <actuator name="left_back_roller_9_joint_motor">
            <hardwareInterface>hardware_interface/EffortJointInterface</hardwareInterface>
            <mechanicalReduction>1</mechanicalReduction>
        </actuator>
    </transmission>
    <transmission name="trans_left_back_roller_10_joint">
        <type>transmission_interface/SimpleTransmission</type>
        <joint name="left_back_roller_10_joint">
            <hardwareInterface>hardware_interface/EffortJointInterface</hardwareInterface>
        </joint>
        <actuator name="left_back_roller_10_joint_motor">
            <hardwareInterface>hardware_interface/EffortJointInterface</hardwareInterface>
            <mechanicalReduction>1</mechanicalReduction>
        </actuator>
    </transmission>
    <transmission name="trans_left_back_roller_11_joint">
        <type>transmission_interface/SimpleTransmission</type>
        <joint name="left_back_roller_11_joint">
            <hardwareInterface>hardware_interface/EffortJointInterface</hardwareInterface>
        </joint>
        <actuator name="left_back_roller_11_joint_motor">
            <hardwareInterface>hardware_interface/EffortJointInterface</hardwareInterface>
            <mechanicalReduction>1</mechanicalReduction>
        </actuator>
    </transmission>
    <transmission name="trans_left_back_roller_12_joint">
        <type>transmission_interface/SimpleTransmission</type>
        <joint name="left_back_roller_12_joint">
            <hardwareInterface>hardware_interface/EffortJointInterface</hardwareInterface>
        </joint>
        <actuator name="left_back_roller_12_joint_motor">
            <hardwareInterface>hardware_interface/EffortJointInterface</hardwareInterface>
            <mechanicalReduction>1</mechanicalReduction>
        </actuator>
    </transmission>
    <transmission name="trans_left_back_roller_13_joint">
        <type>transmission_interface/SimpleTransmission</type>
        <joint name="left_back_roller_13_joint">
            <hardwareInterface>hardware_interface/EffortJointInterface</hardwareInterface>
        </joint>
        <actuator name="left_back_roller_13_joint_motor">
            <hardwareInterface>hardware_interface/EffortJointInterface</hardwareInterface>
            <mechanicalReduction>1</mechanicalReduction>
        </actuator>
    </transmission>
    <transmission name="trans_left_back_roller_14_joint">
        <type>transmission_interface/SimpleTransmission</type>
        <joint name="left_back_roller_14_joint">
            <hardwareInterface>hardware_interface/EffortJointInterface</hardwareInterface>
        </joint>
        <actuator name="left_back_roller_14_joint_motor">
            <hardwareInterface>hardware_interface/EffortJointInterface</hardwareInterface>
            <mechanicalReduction>1</mechanicalReduction>
        </actuator>
    </transmission>
    <transmission name="trans_left_back_roller_15_joint">
        <type>transmission_interface/SimpleTransmission</type>
        <joint name="left_back_roller_15_joint">
            <hardwareInterface>hardware_interface/EffortJointInterface</hardwareInterface>
        </joint>
        <actuator name="left_back_roller_15_joint_motor">
            <hardwareInterface>hardware_interface/EffortJointInterface</hardwareInterface>
            <mechanicalReduction>1</mechanicalReduction>
        </actuator>
    </transmission>
    <transmission name="trans_right_back_roller_0_joint">
        <type>transmission_interface/SimpleTransmission</type>
        <joint name="right_back_roller_0_joint">
            <hardwareInterface>hardware_interface/EffortJointInterface</hardwareInterface>
        </joint>
        <actuator name="right_back_roller_0_joint_motor">
            <hardwareInterface>hardware_interface/EffortJointInterface</hardwareInterface>
            <mechanicalReduction>1</mechanicalReduction>
        </actuator>
    </transmission>
    <transmission name="trans_right_back_roller_1_joint">
        <type>transmission_interface/SimpleTransmission</type>
        <joint name="right_back_roller_1_joint">
            <hardwareInterface>hardware_interface/EffortJointInterface</hardwareInterface>
        </joint>
        <actuator name="right_back_roller_1_joint_motor">
            <hardwareInterface>hardware_interface/EffortJointInterface</hardwareInterface>
            <mechanicalReduction>1</mechanicalReduction>
        </actuator>
    </transmission>
    <transmission name="trans_right_back_roller_2_joint">
        <type>transmission_interface/SimpleTransmission</type>
        <joint name="right_back_roller_2_joint">
            <hardwareInterface>hardware_interface/EffortJointInterface</hardwareInterface>
        </joint>
        <actuator name="right_back_roller_2_joint_motor">
            <hardwareInterface>hardware_interface/EffortJointInterface</hardwareInterface>
            <mechanicalReduction>1</mechanicalReduction>
        </actuator>
    </transmission>
    <transmission name="trans_right_back_roller_3_joint">
        <type>transmission_interface/SimpleTransmission</type>
        <joint name="right_back_roller_3_joint">
            <hardwareInterface>hardware_interface/EffortJointInterface</hardwareInterface>
        </joint>
        <actuator name="right_back_roller_3_joint_motor">
            <hardwareInterface>hardware_interface/EffortJointInterface</hardwareInterface>
            <mechanicalReduction>1</mechanicalReduction>
        </actuator>
    </transmission>
    <transmission name="trans_right_back_roller_4_joint">
        <type>transmission_interface/SimpleTransmission</type>
        <joint name="right_back_roller_4_joint">
            <hardwareInterface>hardware_interface/EffortJointInterface</hardwareInterface>
        </joint>
        <actuator name="right_back_roller_4_joint_motor">
            <hardwareInterface>hardware_interface/EffortJointInterface</hardwareInterface>
            <mechanicalReduction>1</mechanicalReduction>
        </actuator>
    </transmission>
    <transmission name="trans_right_back_roller_5_joint">
        <type>transmission_interface/SimpleTransmission</type>
        <joint name="right_back_roller_5_joint">
            <hardwareInterface>hardware_interface/EffortJointInterface</hardwareInterface>
        </joint>
        <actuator name="right_back_roller_5_joint_motor">
            <hardwareInterface>hardware_interface/EffortJointInterface</hardwareInterface>
            <mechanicalReduction>1</mechanicalReduction>
        </actuator>
    </transmission>
    <transmission name="trans_right_back_roller_6_joint">
        <type>transmission_interface/SimpleTransmission</type>
        <joint name="right_back_roller_6_joint">
            <hardwareInterface>hardware_interface/EffortJointInterface</hardwareInterface>
        </joint>
        <actuator name="right_back_roller_6_joint_motor">
            <hardwareInterface>hardware_interface/EffortJointInterface</hardwareInterface>
            <mechanicalReduction>1</mechanicalReduction>
        </actuator>
    </transmission>
    <transmission name="trans_right_back_roller_7_joint">
        <type>transmission_interface/SimpleTransmission</type>
        <joint name="right_back_roller_7_joint">
            <hardwareInterface>hardware_interface/EffortJointInterface</hardwareInterface>
        </joint>
        <actuator name="right_back_roller_7_joint_motor">
            <hardwareInterface>hardware_interface/EffortJointInterface</hardwareInterface>
            <mechanicalReduction>1</mechanicalReduction>
        </actuator>
    </transmission>
    <transmission name="trans_right_back_roller_8_joint">
        <type>transmission_interface/SimpleTransmission</type>
        <joint name="right_back_roller_8_joint">
            <hardwareInterface>hardware_interface/EffortJointInterface</hardwareInterface>
        </joint>
        <actuator name="right_back_roller_8_joint_motor">
            <hardwareInterface>hardware_interface/EffortJointInterface</hardwareInterface>
            <mechanicalReduction>1</mechanicalReduction>
        </actuator>
    </transmission>
    <transmission name="trans_right_back_roller_9_joint">
        <type>transmission_interface/SimpleTransmission</type>
        <joint name="right_back_roller_9_joint">
            <hardwareInterface>hardware_interface/EffortJointInterface</hardwareInterface>
        </joint>
        <actuator name="right_back_roller_9_joint_motor">
            <hardwareInterface>hardware_interface/EffortJointInterface</hardwareInterface>
            <mechanicalReduction>1</mechanicalReduction>
        </actuator>
    </transmission>
    <transmission name="trans_right_back_roller_10_joint">
        <type>transmission_interface/SimpleTransmission</type>
        <joint name="right_back_roller_10_joint">
            <hardwareInterface>hardware_interface/EffortJointInterface</hardwareInterface>
        </joint>
        <actuator name="right_back_roller_10_joint_motor">
            <hardwareInterface>hardware_interface/EffortJointInterface</hardwareInterface>
            <mechanicalReduction>1</mechanicalReduction>
        </actuator>
    </transmission>
    <transmission name="trans_right_back_roller_11_joint">
        <type>transmission_interface/SimpleTransmission</type>
        <joint name="right_back_roller_11_joint">
            <hardwareInterface>hardware_interface/EffortJointInterface</hardwareInterface>
        </joint>
        <actuator name="right_back_roller_11_joint_motor">
            <hardwareInterface>hardware_interface/EffortJointInterface</hardwareInterface>
            <mechanicalReduction>1</mechanicalReduction>
        </actuator>
    </transmission>
    <transmission name="trans_right_back_roller_12_joint">
        <type>transmission_interface/SimpleTransmission</type>
        <joint name="right_back_roller_12_joint">
            <hardwareInterface>hardware_interface/EffortJointInterface</hardwareInterface>
        </joint>
        <actuator name="right_back_roller_12_joint_motor">
            <hardwareInterface>hardware_interface/EffortJointInterface</hardwareInterface>
            <mechanicalReduction>1</mechanicalReduction>
        </actuator>
    </transmission>
    <transmission name="trans_right_back_roller_13_joint">
        <type>transmission_interface/SimpleTransmission</type>
        <joint name="right_back_roller_13_joint">
            <hardwareInterface>hardware_interface/EffortJointInterface</hardwareInterface>
        </joint>
        <actuator name="right_back_roller_13_joint_motor">
            <hardwareInterface>hardware_interface/EffortJointInterface</hardwareInterface>
            <mechanicalReduction>1</mechanicalReduction>
        </actuator>
    </transmission>
    <transmission name="trans_right_back_roller_14_joint">
        <type>transmission_interface/SimpleTransmission</type>
        <joint name="right_back_roller_14_joint">
            <hardwareInterface>hardware_interface/EffortJointInterface</hardwareInterface>
        </joint>
        <actuator name="right_back_roller_14_joint_motor">
            <hardwareInterface>hardware_interface/EffortJointInterface</hardwareInterface>
            <mechanicalReduction>1</mechanicalReduction>
        </actuator>
    </transmission>
    <transmission name="trans_right_back_roller_15_joint">
        <type>transmission_interface/SimpleTransmission</type>
        <joint name="right_back_roller_15_joint">
            <hardwareInterface>hardware_interface/EffortJointInterface</hardwareInterface>
        </joint>
        <actuator name="right_back_roller_15_joint_motor">
            <hardwareInterface>hardware_interface/EffortJointInterface</hardwareInterface>
            <mechanicalReduction>1</mechanicalReduction>
        </actuator>
    </transmission>
</robot>

